Workbook

Sheet Summary
A1: # | B1: trade | C1: date initiated | D1: Col | E1: live pnl
A2: 41b | B2: SUBFIN S45 vs SX5E | C2: {=INDIRECT("'" & A2 & "'!A14")} -> 46176 | D2: I | E2: {=_xlfn.LET(_xlpm.r,INDIRECT("'" & A2 & "'!" & D2 & ":" & D2),LOOKUP(2,1/(ISNUMBER(_xlpm.r)),_xlpm.r))} -> 523297.57
A3: 41c | B3: SNRFIN S45 vs SX7E | C3: {=INDIRECT("'" & A3 & "'!A14")} -> 46181 | D3: I | E3: {=_xlfn.LET(_xlpm.r,INDIRECT("'" & A3 & "'!" & D3 & ":" & D3),LOOKUP(2,1/(ISNUMBER(_xlpm.r)),_xlpm.r))} -> 509645.88
A4: 44a | B4: HSBC vs Main | C4: {=INDIRECT("'" & A4 & "'!A14")} -> 46176.625 | D4: H | E4: {=_xlfn.LET(_xlpm.r,INDIRECT("'" & A4 & "'!" & D4 & ":" & D4),LOOKUP(2,1/(ISNUMBER(_xlpm.r)),_xlpm.r))} -> -50756.01
A5: 44b | B5: HSBC Basis | C5: {=INDIRECT("'" & A5 & "'!A14")} -> 46176.625 | D5: H | E5: {=_xlfn.LET(_xlpm.r,INDIRECT("'" & A5 & "'!" & D5 & ":" & D5),LOOKUP(2,1/(ISNUMBER(_xlpm.r)),_xlpm.r))} -> -142630.32
A6: 50 | B6: GOOGL Curve | C6: {=INDIRECT("'" & A6 & "'!A14")} -> 46174.625 | D6: H | E6: {=_xlfn.LET(_xlpm.r,INDIRECT("'" & A6 & "'!" & D6 & ":" & D6),LOOKUP(2,1/(ISNUMBER(_xlpm.r)),_xlpm.r))} -> -37117.274
A7: 51 | B7: Brazil Steepener | C7: {=INDIRECT("'" & A7 & "'!A14")} -> 46174.625 | D7: H | E7: {=_xlfn.LET(_xlpm.r,INDIRECT("'" & A7 & "'!" & D7 & ":" & D7),LOOKUP(2,1/(ISNUMBER(_xlpm.r)),_xlpm.r))} -> -49242.999
A8: 52 | B8: SUBFIN vs EUR GS | C8: {=INDIRECT("'" & A8 & "'!A14")} -> 46176.625 | D8: H | E8: {=_xlfn.LET(_xlpm.r,INDIRECT("'" & A8 & "'!" & D8 & ":" & D8),LOOKUP(2,1/(ISNUMBER(_xlpm.r)),_xlpm.r))} -> 8731.064
A9: 54 | B9: IEAC Sprd vs SX5E Puts | C9: {=INDIRECT("'" & A9 & "'!A14")} -> 46189 | D9: L | E9: {=_xlfn.LET(_xlpm.r,INDIRECT("'" & A9 & "'!" & D9 & ":" & D9),LOOKUP(2,1/(ISNUMBER(_xlpm.r)),_xlpm.r))} -> -98055.291
A10: 55 | B10: EUR HY Basis | C10: {=INDIRECT("'" & A10 & "'!A14")} -> 46190 | D10: L | E10: {=_xlfn.LET(_xlpm.r,INDIRECT("'" & A10 & "'!" & D10 & ":" & D10),LOOKUP(2,1/(ISNUMBER(_xlpm.r)),_xlpm.r))} -> 42592.482

Sheet Dividends
A1: DIVIDEND HISTORY (live BDS — Bloomberg, Ex-Date + Amount)
A3: EMB | D3: VCIT | G3: IHYG | J3: IEAC | M3: HYG | P3: LQD | S3: BKLN
A4: EMB US EQUITY | D4: VCIT US EQUITY | G4: IHYG LN EQUITY | J4: IEAC LN EQUITY | M4: HYG US EQUITY | P4: LQD US EQUITY | S4: BKLN US EQUITY
A5: Ex-Date | B5: Amount | D5: Ex-Date | E5: Amount | G5: Ex-Date | H5: Amount | J5: Ex-Date | K5: Amount | M5: Ex-Date | N5: Amount | P5: Ex-Date | Q5: Amount | S5: Ex-Date | T5: Amount
A6: {=_xlfn.CHOOSECOLS(_xll.BDS($A$4,"DVD_HIST_ALL","DVD_START_DT=20240101","DVD_END_DT=20351231","HEADERS=N"),2,5)} -> 46174 | B6: 0.407041 | D6: {=_xlfn.CHOOSECOLS(_xll.BDS($D$4,"DVD_HIST_ALL","DVD_START_DT=20240101","DVD_END_DT=20351231","HEADERS=N"),2,5)} -> 46174 | E6: 0.3412 | G6: {=_xlfn.CHOOSECOLS(_xll.BDS($G$4,"DVD_HIST_ALL","DVD_START_DT=20240101","DVD_END_DT=20351231","HEADERS=N"),2,5)} -> 46191 | H6: 1.1646 | J6: {=_xlfn.CHOOSECOLS(_xll.BDS($J$4,"DVD_HIST_ALL","DVD_START_DT=20240101","DVD_END_DT=20351231","HEADERS=N"),2,5)} -> 46037 | K6: 2.0449 | M6: {=_xlfn.CHOOSECOLS(_xll.BDS($M$4,"DVD_HIST_ALL","DVD_START_DT=20240101","DVD_END_DT=20351231","HEADERS=N"),2,5)} -> 46174 | N6: 0.408967 | P6: {=_xlfn.CHOOSECOLS(_xll.BDS($P$4,"DVD_HIST_ALL","DVD_START_DT=20240101","DVD_END_DT=20351231","HEADERS=N"),2,5)} -> 46174 | Q6: 0.413251 | S6: {=_xlfn.CHOOSECOLS(_xll.BDS($S$4,"DVD_HIST_ALL","DVD_START_DT=20240101","DVD_END_DT=20351231","HEADERS=N"),2,5)} -> 46160 | T6: 0.10111
A7: 46143 | B7: 0.410076 | D7: 46143 | E7: 0.3262 | G7: 46100 | H7: 2.3303 | J7: 45855 | K7: 1.9446 | M7: 46143 | N7: 0.418714 | P7: 46143 | Q7: 0.424551 | S7: 46132 | T7: 0.10497
A8: 46113 | B8: 0.455397 | D8: 46113 | E8: 0.3438 | G8: 45911 | H8: 2.4173 | J8: 45673 | K8: 2.0396 | M8: 46113 | N8: 0.383731 | P8: 46113 | Q8: 0.446478 | S8: 46104 | T8: 0.11551
A9: 46083 | B9: 0.402963 | D9: 46083 | E9: 0.3026 | G9: 45729 | H9: 2.6722 | J9: 45491 | K9: 2.0996 | M9: 46083 | N9: 0.393736 | P9: 46083 | Q9: 0.382834 | S9: 46076 | T9: 0.10055
A10: 46055 | B10: 0.41458 | D10: 46055 | E10: 0.33 | G10: 45547 | H10: 2.8229 | J10: 45302 | K10: 2.0209 | M10: 46055 | N10: 0.398688 | P10: 46055 | Q10: 0.407845 | S10: 46042 | T10: 0.10777
A11: 46010 | B11: 0.382893 | D11: 46009 | E11: 0.3358 | G11: 45365 | H11: 2.9 | M11: 46010 | N11: 0.380624 | P11: 46010 | Q11: 0.436458 | S11: 46013 | T11: 0.10282
A12: 45992 | B12: 0.372202 | D12: 45992 | E12: 0.3223 | M12: 45992 | N12: 0.374767 | P12: 45992 | Q12: 0.413481 | S12: 45985 | T12: 0.11955
A13: 45964 | B13: 0.417558 | D13: 45964 | E13: 0.334 | M13: 45964 | N13: 0.409763 | P13: 45964 | Q13: 0.402445 | S13: 45950 | T13: 0.12011
A14: 45931 | B14: 0.392529 | D14: 45931 | E14: 0.326 | M14: 45931 | N14: 0.381299 | P14: 45931 | Q14: 0.406036 | S14: 45922 | T14: 0.12484
A15: 45902 | B15: 0.401921 | D15: 45902 | E15: 0.3279 | M15: 45902 | N15: 0.383321 | P15: 45902 | Q15: 0.384434 | S15: 45887 | T15: 0.12347
A16: 45870 | B16: 0.411035 | D16: 45870 | E16: 0.3408 | M16: 45870 | N16: 0.404487 | P16: 45870 | Q16: 0.444155 | S16: 45859 | T16: 0.11933
A17: 45839 | B17: 0.379909 | D17: 45839 | E17: 0.3207 | M17: 45839 | N17: 0.379436 | P17: 45839 | Q17: 0.401927 | S17: 45831 | T17: 0.11617
A18: 45810 | B18: 0.405383 | D18: 45810 | E18: 0.328 | M18: 45810 | N18: 0.375571 | P18: 45810 | Q18: 0.396319 | S18: 45796 | T18: 0.1648
A19: 45778 | B19: 0.402288 | D19: 45778 | E19: 0.3151 | M19: 45778 | N19: 0.401345 | P19: 45778 | Q19: 0.431941 | S19: 45768 | T19: 0.12493
A20: 45748 | B20: 0.399904 | D20: 45748 | E20: 0.3189 | M20: 45748 | N20: 0.382397 | P20: 45748 | Q20: 0.416781 | S20: 45740 | T20: 0.10781
A21: 45719 | B21: 0.385564 | D21: 45719 | E21: 0.2865 | M21: 45719 | N21: 0.374339 | P21: 45719 | Q21: 0.414742 | S21: 45712 | T21: 0.11158
A22: 45691 | B22: 0.440929 | D22: 45691 | E22: 0.3129 | M22: 45691 | N22: 0.360138 | P22: 45691 | Q22: 0.388977 | S22: 45678 | T22: 0.1237
A23: 45656 | B23: 0.254515 | D23: 45650 | E23: 0.3119 | M23: 45644 | N23: 0.409324 | P23: 45644 | Q23: 0.385499 | S23: 45649 | T23: 0.11976
... A34: 45352 | B34: 0.385713 | D34: 45323 | E34: 0.281 | M34: 45323 | N34: 0.383831 | P34: 45323 | Q34: 0.3886 | S34: 45313 | T34: 0.13742
A35: 45323 | B35: 0.367262

Sheet 41b
B1: ERIXITSU Index | L1: =TODAY()-150 -> 46041 | R1: {=LOOKUP(2,1/(R:R<>""),R:R)} -> 46190 | AC1: Last ER Date = | AD1: {=LOOKUP(2,1/(AB:AB<>""),AB:AB)} -> 46190
B2: Short Risk | C2: Long Risk | L2: Short Risk | N2: Long Risk | R2: {=_xlfn.UNIQUE(Q:Q)} -> 0 | AC2: Last CDX = | AD2: =VLOOKUP(AD1,Z:AA,2) -> 88.237
A3: Name= | B3: SUBFIN S45 | C3: SX7E | L3: {=_xll.BDH($B$4, "PX_LAST, ", TODAY()-300, TODAY()-1)} -> 46101 | M3: 133.299 | N3: {=_xll.BDH($C$4, "PX_LAST, ", TODAY()-300, TODAY()-1)} -> 45922 | O3: 225.7 | P3: =IF(COUNTIF(N:N,L3),L3,"") -> 46101 | Q3: =IF(P3>$A$14,P3,"") | X3: {=_xll.BDH(B1, "LAST_PRICE", "05/01/2026","")} -> 46143 | Y3: 164.6034 | Z3: {=_xll.BDH(B4, "LAST_PRICE", "05/01/2026", "")} -> 46143 | AA3: 99.15 | AB3: =IF(COUNTIF(Z:Z,X3),X3,"") -> 46143 | AC3: Last ER = | AD3: =VLOOKUP(AD1,X:Y,2) -> 165.6306
A4: BBG Ticker= | B4: SUBFIN CDSI S45 5Y CORP | C4: CAM6 INDEX | E4: Contract Size = | F4: 50 | L4: 46104 | M4: 129.787 | N4: 45923 | O4: 226.65 | P4: =IF(COUNTIF(N:N,L4),L4,"") -> 46104 | Q4: =IF(P4>$A$14,P4,"") | R4: 46177 | X4: 46147 | Y4: 164.5176 | Z4: 46147 | AA4: 100.452 | AB4: =IF(COUNTIF(Z:Z,X4),X4,"") -> 46147 | AC4: Carry Days = | AD4: =INT(NOW())-INT(AD1) -> 1
A5: Not'l= | B5: =75*10^6 -> 75000000 | C5: 525 | L5: 46105 | M5: 131.094 | N5: 45924 | O5: 227.4 | P5: =IF(COUNTIF(N:N,L5),L5,"") -> 46105 | Q5: =IF(P5>$A$14,P5,"") | R5: 46178 | X5: 46148 | Y5: 164.8755 | Z5: 46148 | AA5: 95.917 | AB5: =IF(COUNTIF(Z:Z,X5),X5,"") -> 46148
A6: Carry= | B6: 0.01 | C6: 0 | L6: 46106 | M6: 126.128 | N6: 45925 | O6: 225.8 | P6: =IF(COUNTIF(N:N,L6),L6,"") -> 46106 | Q6: =IF(P6>$A$14,P6,"") | R6: 46181 | X6: 46149 | Y6: 164.7939 | Z6: 46149 | AA6: 97.303 | AB6: =IF(COUNTIF(Z:Z,X6),X6,"") -> 46149
A7: Financing Rate= | B7: 0 | C7: 0 | L7: 46107 | M7: 133.728 | N7: 45926 | O7: 230.25 | P7: =IF(COUNTIF(N:N,L7),L7,"") -> 46107 | Q7: =IF(P7>$A$14,P7,"") | R7: 46182 | X7: 46150 | Y7: 164.7687 | Z7: 46150 | AA7: 97.287 | AB7: =IF(COUNTIF(Z:Z,X7),X7,"") -> 46150
A8: Initial Duration= | B8: 4.69 | L8: 46108 | M8: 138.6 | N8: 45929 | O8: 228.4 | P8: =IF(COUNTIF(N:N,L8),L8,"") -> 46108 | Q8: =IF(P8>$A$14,P8,"") | R8: 46183 | X8: 46153 | Y8: 164.834 | Z8: 46153 | AA8: 96.719 | AB8: =IF(COUNTIF(Z:Z,X8),X8,"") -> 46153
A9: Live BBG PX= | B9: {=_xll.BDP(B4,"PX_LAST")} -> 88.30506 | C9: {=_xll.BDP(C4,"PX_LAST")} -> 295.2 | L9: 46111 | M9: 137.76 | N9: 45930 | O9: 228.85 | P9: =IF(COUNTIF(N:N,L9),L9,"") -> 46111 | Q9: =IF(P9>$A$14,P9,"") | R9: 46184 | X9: 46154 | Y9: 164.583 | Z9: 46154 | AA9: 100.017 | AB9: =IF(COUNTIF(Z:Z,X9),X9,"") -> 46154
A10: Live ER = | B10: =AD3*(1-(B9-AD2)*B8*10^-4+B6*AD4/360) -> 165.62991 | L10: 46112 | M10: 133.543 | N10: 45931 | O10: 230.4 | P10: =IF(COUNTIF(N:N,L10),L10,"") -> 46112 | Q10: =IF(P10>$A$14,P10,"") | R10: 46185 | X10: 46155 | Y10: 164.7606 | Z10: 46155 | AA10: 97.277 | AB10: =IF(COUNTIF(Z:Z,X10),X10,"") -> 46155
L11: 46113 | M11: 121.008 | N11: 45932 | O11: 228.5 | P11: =IF(COUNTIF(N:N,L11),L11,"") -> 46113 | Q11: =IF(P11>$A$14,P11,"") | R11: 46188 | X11: 46156 | Y11: 164.914 | Z11: 46156 | AA11: 95.843 | AB11: =IF(COUNTIF(Z:Z,X11),X11,"") -> 46156
A12: Date | B12: Short Risk | E12: Long Risk | H12: Div | I12: Net P/L | L12: 46114 | M12: 118.791 | N12: 45933 | O12: 229.3 | P12: =IF(COUNTIF(N:N,L12),L12,"") -> 46114 | Q12: =IF(P12>$A$14,P12,"") | R12: 46189 | X12: 46157 | Y12: 164.5833 | Z12: 46157 | AA12: 100.188 | AB12: =IF(COUNTIF(Z:Z,X12),X12,"") -> 46157
B13: Sprd | C13: Price P/L | D13: Carry P/L | E13: Price | F13: Price P/L | G13: Carry P/L | L13: 46119 | M13: 121.522 | N13: 45936 | O13: 226.55 | P13: =IF(COUNTIF(N:N,L13),L13,"") -> 46119 | Q13: =IF(P13>$A$14,P13,"") | R13: 46190 | X13: 46160 | Y13: 164.6849 | Z13: 46160 | AA13: 98.826 | AB13: =IF(COUNTIF(Z:Z,X13),X13,"") -> 46160
A14: 46176 | B14: =165.3818/(1-(D14-C14)*B8*10^-4) -> 165.25887 | C14: 92.4 | D14: 90.814 | E14: 268.85 | I14: 0 | L14: 46120 | M14: 107.431 | N14: 45937 | O14: 226 | P14: =IF(COUNTIF(N:N,L14),L14,"") -> 46120 | Q14: =IF(P14>$A$14,P14,"") | X14: 46161 | Y14: 164.5903 | Z14: 46161 | AA14: 100.245 | AB14: =IF(COUNTIF(Z:Z,X14),X14,"") -> 46161
A15: =IF(AND(ISBLANK(R4), A14 = $R$1),NOW(),IF(ISBLANK(R4),IF(ISBLANK(#REF!),NOW(),""),R4)) -> 46177 | B15: =IF(COUNTIF($R$2:R1000,A15)=1,VLOOKUP(A15,X:Y,2), IF(COUNTIF($R$2:R1000,A15)=0,$B$10,"")) -> 165.3818 | C15: =IF(ISERROR(B15-2),"",1*(B15/$B$14-1)*$B$5) -> 55787.55 | E15: =IF(COUNTIF(L:L,A15)=1,VLOOKUP(A15,N:O,2), IF(COUNTIF(L:L,A15)=0,$C$9,"")) -> 270.85 | F15: =IF(ISERROR(B15-2),"",(E15-$E$14)*$C$5*$F$4) -> 52500 | G15: =IF(ISERROR(B15-2),"",-$C$7*$C$5*(A15-$A$14)/360) -> 0 | I15: =IF(ISERROR(B15-2),"",-1*(C15+D15-F15)) -> -3287.55 | L15: 46121 | M15: 104.477 | N15: 45938 | O15: 226.95 | P15: =IF(COUNTIF(N:N,L15),L15,"") -> 46121 | Q15: =IF(P15>$A$14,P15,"") | X15: 46162 | Y15: 164.9511 | Z15: 46162 | AA15: 95.457 | AB15: =IF(COUNTIF(Z:Z,X15),X15,"") -> 46162
A16: =IF(AND(ISBLANK(R5), A15 = $R$1),NOW(),IF(ISBLANK(R5),IF(ISBLANK(C15),NOW(),""),R5)) -> 46178 | B16: =IF(COUNTIF($R$2:R1001,A16)=1,VLOOKUP(A16,X:Y,2), IF(COUNTIF($R$2:R1001,A16)=0,$B$10,"")) -> 165.2787 | C16: =IF(ISERROR(B16-2),"",1*(B16/$B$14-1)*$B$5) -> 8997.3246 | E16: =IF(COUNTIF(L:L,A16)=1,VLOOKUP(A16,N:O,2), IF(COUNTIF(L:L,A16)=0,$C$9,"")) -> 269.65 | F16: =IF(ISERROR(B16-2),"",(E16-$E$14)*$C$5*$F$4) -> 21000 | G16: =IF(ISERROR(B16-2),"",-$C$7*$C$5*(A16-$A$14)/360) -> 0 | I16: =IF(ISERROR(B16-2),"",-1*(C16+D16-F16)) -> 12002.675 | L16: 46122 | M16: 106.512 | N16: 45939 | O16: 225.35 | P16: =IF(COUNTIF(N:N,L16),L16,"") -> 46122 | Q16: =IF(P16>$A$14,P16,"") | X16: 46163 | Y16: 164.8717 | Z16: 46163 | AA16: 96.618 | AB16: =IF(COUNTIF(Z:Z,X16),X16,"") -> 46163
A17: =IF(AND(ISBLANK(R6), A16 = $R$1),NOW(),IF(ISBLANK(R6),IF(ISBLANK(C16),NOW(),""),R6)) -> 46181 | B17: =IF(COUNTIF($R$2:R1002,A17)=1,VLOOKUP(A17,X:Y,2), IF(COUNTIF($R$2:R1002,A17)=0,$B$10,"")) -> 165.2598 | C17: =IF(ISERROR(B17-2),"",1*(B17/$B$14-1)*$B$5) -> 419.87302 | E17: =IF(COUNTIF(L:L,A17)=1,VLOOKUP(A17,N:O,2), IF(COUNTIF(L:L,A17)=0,$C$9,"")) -> 268.45 | F17: =IF(ISERROR(B17-2),"",(E17-$E$14)*$C$5*$F$4) -> -10500 | G17: =IF(ISERROR(B17-2),"",-$C$7*$C$5*(A17-$A$14)/360) -> 0 | I17: =IF(ISERROR(B17-2),"",-1*(C17+D17-F17)) -> -10919.873 | L17: 46125 | M17: 106.686 | N17: 45940 | O17: 222.5 | P17: =IF(COUNTIF(N:N,L17),L17,"") -> 46125 | Q17: =IF(P17>$A$14,P17,"") | X17: 46164 | Y17: 165.0279 | Z17: 46164 | AA17: 94.872 | AB17: =IF(COUNTIF(Z:Z,X17),X17,"") -> 46164
A18: =IF(AND(ISBLANK(R7), A17 = $R$1),NOW(),IF(ISBLANK(R7),IF(ISBLANK(C17),NOW(),""),R7)) -> 46182 | B18: =IF(COUNTIF($R$2:R1003,A18)=1,VLOOKUP(A18,X:Y,2), IF(COUNTIF($R$2:R1003,A18)=0,$B$10,"")) -> 165.26 | C18: =IF(ISERROR(B18-2),"",1*(B18/$B$14-1)*$B$5) -> 510.6397 | E18: =IF(COUNTIF(L:L,A18)=1,VLOOKUP(A18,N:O,2), IF(COUNTIF(L:L,A18)=0,$C$9,"")) -> 268.2 | F18: =IF(ISERROR(B18-2),"",(E18-$E$14)*$C$5*$F$4) -> -17062.5 | G18: =IF(ISERROR(B18-2),"",-$C$7*$C$5*(A18-$A$14)/360) -> 0 | I18: =IF(ISERROR(B18-2),"",-1*(C18+D18-F18)) -> -17573.14 | L18: 46126 | M18: 101.413 | N18: 45943 | O18: 223.45 | P18: =IF(COUNTIF(N:N,L18),L18,"") -> 46126 | Q18: =IF(P18>$A$14,P18,"") | X18: 46168 | Y18: 165.161 | Z18: 46168 | AA18: 93.215 | AB18: =IF(COUNTIF(Z:Z,X18),X18,"") -> 46168
A19: =IF(AND(ISBLANK(R8), A18 = $R$1),NOW(),IF(ISBLANK(R8),IF(ISBLANK(C18),NOW(),""),R8)) -> 46183 | B19: =IF(COUNTIF($R$2:R1004,A19)=1,VLOOKUP(A19,X:Y,2), IF(COUNTIF($R$2:R1004,A19)=0,$B$10,"")) -> 165.1884 | C19: =IF(ISERROR(B19-2),"",1*(B19/$B$14-1)*$B$5) -> -31983.833 | E19: =IF(COUNTIF(L:L,A19)=1,VLOOKUP(A19,N:O,2), IF(COUNTIF(L:L,A19)=0,$C$9,"")) -> 266.35 | F19: =IF(ISERROR(B19-2),"",(E19-$E$14)*$C$5*$F$4) -> -65625 | G19: =IF(ISERROR(B19-2),"",-$C$7*$C$5*(A19-$A$14)/360) -> 0 | I19: =IF(ISERROR(B19-2),"",-1*(C19+D19-F19)) -> -33641.167 | L19: 46127 | M19: 101.941 | N19: 45944 | O19: 224 | P19: =IF(COUNTIF(N:N,L19),L19,"") -> 46127 | Q19: =IF(P19>$A$14,P19,"") | X19: 46169 | Y19: 165.1833 | Z19: 46169 | AA19: 93.236 | AB19: =IF(COUNTIF(Z:Z,X19),X19,"") -> 46169
A20: =IF(AND(ISBLANK(R9), A19 = $R$1),NOW(),IF(ISBLANK(R9),IF(ISBLANK(C19),NOW(),""),R9)) -> 46184 | B20: =IF(COUNTIF($R$2:R1005,A20)=1,VLOOKUP(A20,X:Y,2), IF(COUNTIF($R$2:R1005,A20)=0,$B$10,"")) -> 165.2487 | C20: =IF(ISERROR(B20-2),"",1*(B20/$B$14-1)*$B$5) -> -4617.6779 | E20: =IF(COUNTIF(L:L,A20)=1,VLOOKUP(A20,N:O,2), IF(COUNTIF(L:L,A20)=0,$C$9,"")) -> 267.05 | F20: =IF(ISERROR(B20-2),"",(E20-$E$14)*$C$5*$F$4) -> -47250 | G20: =IF(ISERROR(B20-2),"",-$C$7*$C$5*(A20-$A$14)/360) -> 0 | I20: =IF(ISERROR(B20-2),"",-1*(C20+D20-F20)) -> -42632.322 | L20: 46128 | M20: 103.227 | N20: 45945 | O20: 223.6 | P20: =IF(COUNTIF(N:N,L20),L20,"") -> 46128 | Q20: =IF(P20>$A$14,P20,"") | X20: 46170 | Y20: 165.2879 | Z20: 46170 | AA20: 91.685 | AB20: =IF(COUNTIF(Z:Z,X20),X20,"") -> 46170
A21: =IF(AND(ISBLANK(R10), A20 = $R$1),NOW(),IF(ISBLANK(R10),IF(ISBLANK(C20),NOW(),""),R10)) -> 46185 | B21: =IF(COUNTIF($R$2:R1006,A21)=1,VLOOKUP(A21,X:Y,2), IF(COUNTIF($R$2:R1006,A21)=0,$B$10,"")) -> 165.5484 | C21: =IF(ISERROR(B21-2),"",1*(B21/$B$14-1)*$B$5) -> 131396.2 | E21: =IF(COUNTIF(L:L,A21)=1,VLOOKUP(A21,N:O,2), IF(COUNTIF(L:L,A21)=0,$C$9,"")) -> 277.55 | F21: =IF(ISERROR(B21-2),"",(E21-$E$14)*$C$5*$F$4) -> 228375 | G21: =IF(ISERROR(B21-2),"",-$C$7*$C$5*(A21-$A$14)/360) -> 0 | I21: =IF(ISERROR(B21-2),"",-1*(C21+D21-F21)) -> 96978.803 | L21: 46129 | M21: 98.823 | N21: 45946 | O21: 224.8 | P21: =IF(COUNTIF(N:N,L21),L21,"") -> 46129 | Q21: =IF(P21>$A$14,P21,"") | X21: 46171 | Y21: 165.3875 | Z21: 46171 | AA21: 90.555 | AB21: =IF(COUNTIF(Z:Z,X21),X21,"") -> 46171
A22: =IF(AND(ISBLANK(R11), A21 = $R$1),NOW(),IF(ISBLANK(R11),IF(ISBLANK(C21),NOW(),""),R11)) -> 46188 | B22: =IF(COUNTIF($R$2:R1007,A22)=1,VLOOKUP(A22,X:Y,2), IF(COUNTIF($R$2:R1007,A22)=0,$B$10,"")) -> 165.6978 | C22: =IF(ISERROR(B22-2),"",1*(B22/$B$14-1)*$B$5) -> 199198.91 | E22: =IF(COUNTIF(L:L,A22)=1,VLOOKUP(A22,N:O,2), IF(COUNTIF(L:L,A22)=0,$C$9,"")) -> 284.15 | F22: =IF(ISERROR(B22-2),"",(E22-$E$14)*$C$5*$F$4) -> 401625 | G22: =IF(ISERROR(B22-2),"",-$C$7*$C$5*(A22-$A$14)/360) -> 0 | I22: =IF(ISERROR(B22-2),"",-1*(C22+D22-F22)) -> 202426.09 | L22: 46132 | M22: 100.01 | N22: 45947 | O22: 219.65 | P22: =IF(COUNTIF(N:N,L22),L22,"") -> 46132 | Q22: =IF(P22>$A$14,P22,"") | X22: 46174 | Y22: 165.238 | Z22: 46174 | AA22: 92.426 | AB22: =IF(COUNTIF(Z:Z,X22),X22,"") -> 46174
A23: =IF(AND(ISBLANK(R12), A22 = $R$1),NOW(),IF(ISBLANK(R12),IF(ISBLANK(C22),NOW(),""),R12)) -> 46189 | B23: =IF(COUNTIF($R$2:R1008,A23)=1,VLOOKUP(A23,X:Y,2), IF(COUNTIF($R$2:R1008,A23)=0,$B$10,"")) -> 165.6726 | C23: =IF(ISERROR(B23-2),"",1*(B23/$B$14-1)*$B$5) -> 187762.31 | E23: =IF(COUNTIF(L:L,A23)=1,VLOOKUP(A23,N:O,2), IF(COUNTIF(L:L,A23)=0,$C$9,"")) -> 289.15 | F23: =IF(ISERROR(B23-2),"",(E23-$E$14)*$C$5*$F$4) -> 532875 | G23: =IF(ISERROR(B23-2),"",-$C$7*$C$5*(A23-$A$14)/360) -> 0 | I23: =IF(ISERROR(B23-2),"",-1*(C23+D23-F23)) -> 345112.69 | L23: 46133 | M23: 102.241 | N23: 45950 | O23: 222.05 | P23: =IF(COUNTIF(N:N,L23),L23,"") -> 46133 | Q23: =IF(P23>$A$14,P23,"") | X23: 46175 | Y23: 165.381 | Z23: 46175 | AA23: 90.719 | AB23: =IF(COUNTIF(Z:Z,X23),X23,"") -> 46175
A24: =IF(AND(ISBLANK(R13), A23 = $R$1),NOW(),IF(ISBLANK(R13),IF(ISBLANK(C23),NOW(),""),R13)) -> 46190 | B24: =IF(COUNTIF($R$2:R1009,A24)=1,VLOOKUP(A24,X:Y,2), IF(COUNTIF($R$2:R1009,A24)=0,$B$10,"")) -> 165.6306 | C24: =IF(ISERROR(B24-2),"",1*(B24/$B$14-1)*$B$5) -> 168701.3 | E24: =IF(COUNTIF(L:L,A24)=1,VLOOKUP(A24,N:O,2), IF(COUNTIF(L:L,A24)=0,$C$9,"")) -> 294.4 | F24: =IF(ISERROR(B24-2),"",(E24-$E$14)*$C$5*$F$4) -> 670687.5 | G24: =IF(ISERROR(B24-2),"",-$C$7*$C$5*(A24-$A$14)/360) -> 0 | I24: =IF(ISERROR(B24-2),"",-1*(C24+D24-F24)) -> 501986.2 | L24: 46134 | M24: 102.872 | N24: 45951 | O24: 220.85 | P24: =IF(COUNTIF(N:N,L24),L24,"") -> 46134 | Q24: =IF(P24>$A$14,P24,"") | X24: 46176 | Y24: 165.2545 | Z24: 46176 | AA24: 92.716 | AB24: =IF(COUNTIF(Z:Z,X24),X24,"") -> 46176
A25: =IF(AND(ISBLANK(R14), A24 = $R$1),NOW(),IF(ISBLANK(R14),IF(ISBLANK(C24),NOW(),""),R14)) -> 46191.471 | B25: =IF(COUNTIF($R$2:R1010,A25)=1,VLOOKUP(A25,X:Y,2), IF(COUNTIF($R$2:R1010,A25)=0,$B$10,"")) -> 165.62991 | C25: =IF(ISERROR(B25-2),"",1*(B25/$B$14-1)*$B$5) -> 168389.93 | E25: =IF(COUNTIF(L:L,A25)=1,VLOOKUP(A25,N:O,2), IF(COUNTIF(L:L,A25)=0,$C$9,"")) -> 295.2 | F25: =IF(ISERROR(B25-2),"",(E25-$E$14)*$C$5*$F$4) -> 691687.5 | G25: =IF(ISERROR(B25-2),"",-$C$7*$C$5*(A25-$A$14)/360) -> 0 | I25: =IF(ISERROR(B25-2),"",-1*(C25+D25-F25)) -> 523297.57 | L25: 46135 | M25: 103.328 | N25: 45952 | O25: 220.15 | P25: =IF(COUNTIF(N:N,L25),L25,"") -> 46135 | Q25: =IF(P25>$A$14,P25,"") | X25: 46177 | Y25: 165.3818 | Z25: 46177 | AA25: 90.814 | AB25: =IF(COUNTIF(Z:Z,X25),X25,"") -> 46177
A26: =IF(AND(ISBLANK(R15), A25 = $R$1),NOW(),IF(ISBLANK(R15),IF(ISBLANK(C25),NOW(),""),R15)) | B26: =IF(COUNTIF($R$2:R1011,A26)=1,VLOOKUP(A26,X:Y,2), IF(COUNTIF($R$2:R1011,A26)=0,$B$10,"")) | C26: =IF(ISERROR(B26-2),"",1*(B26/$B$14-1)*$B$5) | E26: =IF(COUNTIF(L:L,A26)=1,VLOOKUP(A26,N:O,2), IF(COUNTIF(L:L,A26)=0,$C$9,"")) | F26: =IF(ISERROR(B26-2),"",(E26-$E$14)*$C$5*$F$4) | G26: =IF(ISERROR(B26-2),"",-$C$7*$C$5*(A26-$A$14)/360) | I26: =IF(ISERROR(B26-2),"",-1*(C26+D26-F26)) | L26: 46136 | M26: 102.834 | N26: 45953 | O26: 220.45 | P26: =IF(COUNTIF(N:N,L26),L26,"") -> 46136 | Q26: =IF(P26>$A$14,P26,"") | X26: 46178 | Y26: 165.2787 | Z26: 46178 | AA26: 92.252 | AB26: =IF(COUNTIF(Z:Z,X26),X26,"") -> 46178
A27: =IF(AND(ISBLANK(R16), A26 = $R$1),NOW(),IF(ISBLANK(R16),IF(ISBLANK(C26),NOW(),""),R16)) | B27: =IF(COUNTIF($R$2:R1012,A27)=1,VLOOKUP(A27,X:Y,2), IF(COUNTIF($R$2:R1012,A27)=0,$B$10,"")) | C27: =IF(ISERROR(B27-2),"",1*(B27/$B$14-1)*$B$5) | E27: =IF(COUNTIF(L:L,A27)=1,VLOOKUP(A27,N:O,2), IF(COUNTIF(L:L,A27)=0,$C$9,"")) | F27: =IF(ISERROR(B27-2),"",(E27-$E$14)*$C$5*$F$4) | G27: =IF(ISERROR(B27-2),"",-$C$7*$C$5*(A27-$A$14)/360) | I27: =IF(ISERROR(B27-2),"",-1*(C27+D27-F27)) | L27: 46139 | M27: 103.662 | N27: 45954 | O27: 220 | P27: =IF(COUNTIF(N:N,L27),L27,"") -> 46139 | Q27: =IF(P27>$A$14,P27,"") | X27: 46181 | Y27: 165.2598 | Z27: 46181 | AA27: 92.679 | AB27: =IF(COUNTIF(Z:Z,X27),X27,"") -> 46181
... A29: =IF(AND(ISBLANK(R18), A28 = $R$1),NOW(),IF(ISBLANK(R18),IF(ISBLANK(C28),NOW(),""),R18)) | B29: =IF(COUNTIF($R$2:R1014,A29)=1,VLOOKUP(A29,X:Y,2), IF(COUNTIF($R$2:R1014,A29)=0,$B$10,"")) | C29: =IF(ISERROR(B29-2),"",1*(B29/$B$14-1)*$B$5) | E29: =IF(COUNTIF(L:L,A29)=1,VLOOKUP(A29,N:O,2), IF(COUNTIF(L:L,A29)=0,$C$9,"")) | F29: =IF(ISERROR(B29-2),"",(E29-$E$14)*$C$5*$F$4) | G29: =IF(ISERROR(B29-2),"",-$C$7*$C$5*(A29-$A$14)/360) | I29: =IF(ISERROR(B29-2),"",-1*(C29+D29-F29)) | L29: 46141 | M29: 106.142 | N29: 45958 | O29: 223.5 | P29: =IF(COUNTIF(N:N,L29),L29,"") -> 46141 | Q29: =IF(P29>$A$14,P29,"") | X29: 46183 | Y29: 165.1884 | Z29: 46183 | AA29: 93.603 | AB29: =IF(COUNTIF(Z:Z,X29),X29,"") -> 46183
A30: =IF(AND(ISBLANK(R19), A29 = $R$1),NOW(),IF(ISBLANK(R19),IF(ISBLANK(C29),NOW(),""),R19)) | B30: =IF(COUNTIF($R$2:R1015,A30)=1,VLOOKUP(A30,X:Y,2), IF(COUNTIF($R$2:R1015,A30)=0,$B$10,"")) | C30: =IF(ISERROR(B30-2),"",1*(B30/$B$14-1)*$B$5) | E30: =IF(COUNTIF(L:L,A30)=1,VLOOKUP(A30,N:O,2), IF(COUNTIF(L:L,A30)=0,$C$9,"")) | F30: =IF(ISERROR(B30-2),"",(E30-$E$14)*$C$5*$F$4) | G30: =IF(ISERROR(B30-2),"",-$C$7*$C$5*(A30-$A$14)/360) | H30: =$F$7*$F$4 -> 0 | I30: =IF(ISERROR(B30-2),"",-1*(C30+D30-F30)) | L30: 46142 | M30: 102.985 | N30: 45959 | O30: 228.1 | P30: =IF(COUNTIF(N:N,L30),L30,"") -> 46142 | Q30: =IF(P30>$A$14,P30,"") | X30: 46184 | Y30: 165.2487 | Z30: 46184 | AA30: 93.01 | AB30: =IF(COUNTIF(Z:Z,X30),X30,"") -> 46184
A31: =IF(AND(ISBLANK(R20), A30 = $R$1),NOW(),IF(ISBLANK(R20),IF(ISBLANK(C30),NOW(),""),R20)) | B31: =IF(COUNTIF($R$2:R1016,A31)=1,VLOOKUP(A31,X:Y,2), IF(COUNTIF($R$2:R1016,A31)=0,$B$10,"")) | C31: =IF(ISERROR(B31-2),"",1*(B31/$B$14-1)*$B$5) | E31: =IF(COUNTIF(L:L,A31)=1,VLOOKUP(A31,N:O,2), IF(COUNTIF(L:L,A31)=0,$C$9,"")) | F31: =IF(ISERROR(B31-2),"",(E31-$E$14)*$C$5*$F$4) | G31: =IF(ISERROR(B31-2),"",-$C$7*$C$5*(A31-$A$14)/360) | I31: =IF(ISERROR(B31-2),"",-1*(C31+D31-F31)) | L31: 46143 | M31: 99.15 | N31: 45960 | O31: 227.3 | P31: =IF(COUNTIF(N:N,L31),L31,"") | Q31: =IF(P31>$A$14,P31,"") | X31: 46185 | Y31: 165.5484 | Z31: 46185 | AA31: 89.265 | AB31: =IF(COUNTIF(Z:Z,X31),X31,"") -> 46185
A32: =IF(AND(ISBLANK(R21), A31 = $R$1),NOW(),IF(ISBLANK(R21),IF(ISBLANK(C31),NOW(),""),R21)) | B32: =IF(COUNTIF($R$2:R1017,A32)=1,VLOOKUP(A32,X:Y,2), IF(COUNTIF($R$2:R1017,A32)=0,$B$10,"")) | C32: =IF(ISERROR(B32-2),"",1*(B32/$B$14-1)*$B$5) | E32: =IF(COUNTIF(L:L,A32)=1,VLOOKUP(A32,N:O,2), IF(COUNTIF(L:L,A32)=0,$C$9,"")) | F32: =IF(ISERROR(B32-2),"",(E32-$E$14)*$C$5*$F$4) | G32: =IF(ISERROR(B32-2),"",-$C$7*$C$5*(A32-$A$14)/360) | I32: =IF(ISERROR(B32-2),"",-1*(C32+D32-F32)) | L32: 46147 | M32: 100.452 | N32: 45961 | O32: 228.35 | P32: =IF(COUNTIF(N:N,L32),L32,"") -> 46147 | Q32: =IF(P32>$A$14,P32,"") | X32: 46188 | Y32: 165.6978 | Z32: 46188 | AA32: 87.133 | AB32: =IF(COUNTIF(Z:Z,X32),X32,"") -> 46188
A33: =IF(AND(ISBLANK(R22), A32 = $R$1),NOW(),IF(ISBLANK(R22),IF(ISBLANK(C32),NOW(),""),R22)) | B33: =IF(COUNTIF($R$2:R1018,A33)=1,VLOOKUP(A33,X:Y,2), IF(COUNTIF($R$2:R1018,A33)=0,$B$10,"")) | C33: =IF(ISERROR(B33-2),"",1*(B33/$B$14-1)*$B$5) | E33: =IF(COUNTIF(L:L,A33)=1,VLOOKUP(A33,N:O,2), IF(COUNTIF(L:L,A33)=0,$C$9,"")) | F33: =IF(ISERROR(B33-2),"",(E33-$E$14)*$C$5*$F$4) | G33: =IF(ISERROR(B33-2),"",-$C$7*$C$5*(A33-$A$14)/360) | I33: =IF(ISERROR(B33-2),"",-1*(C33+D33-F33)) | L33: 46148 | M33: 95.917 | N33: 45964 | O33: 228.9 | P33: =IF(COUNTIF(N:N,L33),L33,"") -> 46148 | Q33: =IF(P33>$A$14,P33,"") | X33: 46189 | Y33: 165.6726 | Z33: 46189 | AA33: 87.676 | AB33: =IF(COUNTIF(Z:Z,X33),X33,"") -> 46189
A34: =IF(AND(ISBLANK(R23), A33 = $R$1),NOW(),IF(ISBLANK(R23),IF(ISBLANK(C33),NOW(),""),R23)) | B34: =IF(COUNTIF($R$2:R1019,A34)=1,VLOOKUP(A34,X:Y,2), IF(COUNTIF($R$2:R1019,A34)=0,$B$10,"")) | C34: =IF(ISERROR(B34-2),"",1*(B34/$B$14-1)*$B$5) | E34: =IF(COUNTIF(L:L,A34)=1,VLOOKUP(A34,N:O,2), IF(COUNTIF(L:L,A34)=0,$C$9,"")) | F34: =IF(ISERROR(B34-2),"",(E34-$E$14)*$C$5*$F$4) | G34: =IF(ISERROR(B34-2),"",-$C$7*$C$5*(A34-$A$14)/360) | I34: =IF(ISERROR(B34-2),"",-1*(C34+D34-F34)) | L34: 46149 | M34: 97.303 | N34: 45965 | O34: 229.25 | P34: =IF(COUNTIF(N:N,L34),L34,"") -> 46149 | Q34: =IF(P34>$A$14,P34,"") | X34: 46190 | Y34: 165.6306 | Z34: 46190 | AA34: 88.237 | AB34: =IF(COUNTIF(Z:Z,X34),X34,"") -> 46190
A35: =IF(AND(ISBLANK(R24), A34 = $R$1),NOW(),IF(ISBLANK(R24),IF(ISBLANK(C34),NOW(),""),R24)) | B35: =IF(COUNTIF($R$2:R1020,A35)=1,VLOOKUP(A35,X:Y,2), IF(COUNTIF($R$2:R1020,A35)=0,$B$10,"")) | C35: =IF(ISERROR(B35-2),"",1*(B35/$B$14-1)*$B$5) | E35: =IF(COUNTIF(L:L,A35)=1,VLOOKUP(A35,N:O,2), IF(COUNTIF(L:L,A35)=0,$C$9,"")) | F35: =IF(ISERROR(B35-2),"",(E35-$E$14)*$C$5*$F$4) | G35: =IF(ISERROR(B35-2),"",-$C$7*$C$5*(A35-$A$14)/360) | I35: =IF(ISERROR(B35-2),"",-1*(C35+D35-F35)) | L35: 46150 | M35: 97.287 | N35: 45966 | O35: 230.35 | P35: =IF(COUNTIF(N:N,L35),L35,"") -> 46150 | Q35: =IF(P35>$A$14,P35,"") | Z35: 46191 | AA35: 88.282 | AB35: =IF(COUNTIF(Z:Z,X35),X35,"")
A36: =IF(AND(ISBLANK(R25), A35 = $R$1),NOW(),IF(ISBLANK(R25),IF(ISBLANK(C35),NOW(),""),R25)) | B36: =IF(COUNTIF($R$2:R1021,A36)=1,VLOOKUP(A36,X:Y,2), IF(COUNTIF($R$2:R1021,A36)=0,$B$10,"")) | C36: =IF(ISERROR(B36-2),"",1*(B36/$B$14-1)*$B$5) | E36: =IF(COUNTIF(L:L,A36)=1,VLOOKUP(A36,N:O,2), IF(COUNTIF(L:L,A36)=0,$C$9,"")) | F36: =IF(ISERROR(B36-2),"",(E36-$E$14)*$C$5*$F$4) | G36: =IF(ISERROR(B36-2),"",-$C$7*$C$5*(A36-$A$14)/360) | I36: =IF(ISERROR(B36-2),"",-1*(C36+D36-F36)) | L36: 46153 | M36: 96.719 | N36: 45967 | O36: 230.7 | P36: =IF(COUNTIF(N:N,L36),L36,"") -> 46153 | Q36: =IF(P36>$A$14,P36,"") | AB36: =IF(COUNTIF(Z:Z,X36),X36,"")
A37: =IF(AND(ISBLANK(R26), A36 = $R$1),NOW(),IF(ISBLANK(R26),IF(ISBLANK(C36),NOW(),""),R26)) | B37: =IF(COUNTIF($R$2:R1022,A37)=1,VLOOKUP(A37,X:Y,2), IF(COUNTIF($R$2:R1022,A37)=0,$B$10,"")) | C37: =IF(ISERROR(B37-2),"",1*(B37/$B$14-1)*$B$5) | E37: =IF(COUNTIF(L:L,A37)=1,VLOOKUP(A37,N:O,2), IF(COUNTIF(L:L,A37)=0,$C$9,"")) | F37: =IF(ISERROR(B37-2),"",(E37-$E$14)*$C$5*$F$4) | G37: =IF(ISERROR(B37-2),"",-$C$7*$C$5*(A37-$A$14)/360) | I37: =IF(ISERROR(B37-2),"",-1*(C37+D37-F37)) | L37: 46154 | M37: 100.017 | N37: 45968 | O37: 228.8 | P37: =IF(COUNTIF(N:N,L37),L37,"") -> 46154 | Q37: =IF(P37>$A$14,P37,"") | AB37: =IF(COUNTIF(Z:Z,X37),X37,"")
A38: =IF(AND(ISBLANK(R27), A37 = $R$1),NOW(),IF(ISBLANK(R27),IF(ISBLANK(C37),NOW(),""),R27)) | B38: =IF(COUNTIF($R$2:R1023,A38)=1,VLOOKUP(A38,X:Y,2), IF(COUNTIF($R$2:R1023,A38)=0,$B$10,"")) | C38: =IF(ISERROR(B38-2),"",1*(B38/$B$14-1)*$B$5) | E38: =IF(COUNTIF(L:L,A38)=1,VLOOKUP(A38,N:O,2), IF(COUNTIF(L:L,A38)=0,$C$9,"")) | F38: =IF(ISERROR(B38-2),"",(E38-$E$14)*$C$5*$F$4) | G38: =IF(ISERROR(B38-2),"",-$C$7*$C$5*(A38-$A$14)/360) | I38: =IF(ISERROR(B38-2),"",-1*(C38+D38-F38)) | L38: 46155 | M38: 97.277 | N38: 45971 | O38: 236.7 | P38: =IF(COUNTIF(N:N,L38),L38,"") -> 46155 | Q38: =IF(P38>$A$14,P38,"") | AB38: =IF(COUNTIF(Z:Z,X38),X38,"")
A39: =IF(AND(ISBLANK(R28), A38 = $R$1),NOW(),IF(ISBLANK(R28),IF(ISBLANK(C38),NOW(),""),R28)) | B39: =IF(COUNTIF($R$2:R1024,A39)=1,VLOOKUP(A39,X:Y,2), IF(COUNTIF($R$2:R1024,A39)=0,$B$10,"")) | C39: =IF(ISERROR(B39-2),"",1*(B39/$B$14-1)*$B$5) | E39: =IF(COUNTIF(L:L,A39)=1,VLOOKUP(A39,N:O,2), IF(COUNTIF(L:L,A39)=0,$C$9,"")) | F39: =IF(ISERROR(B39-2),"",(E39-$E$14)*$C$5*$F$4) | G39: =IF(ISERROR(B39-2),"",-$C$7*$C$5*(A39-$A$14)/360) | I39: =IF(ISERROR(B39-2),"",-1*(C39+D39-F39)) | L39: 46156 | M39: 95.843 | N39: 45972 | O39: 239.45 | P39: =IF(COUNTIF(N:N,L39),L39,"") -> 46156 | Q39: =IF(P39>$A$14,P39,"") | AB39: =IF(COUNTIF(Z:Z,X39),X39,"")
A40: =IF(AND(ISBLANK(R29), A39 = $R$1),NOW(),IF(ISBLANK(R29),IF(ISBLANK(C39),NOW(),""),R29)) | B40: =IF(COUNTIF($R$2:R1025,A40)=1,VLOOKUP(A40,X:Y,2), IF(COUNTIF($R$2:R1025,A40)=0,$B$10,"")) | C40: =IF(ISERROR(B40-2),"",1*(B40/$B$14-1)*$B$5) | E40: =IF(COUNTIF(L:L,A40)=1,VLOOKUP(A40,N:O,2), IF(COUNTIF(L:L,A40)=0,$C$9,"")) | F40: =IF(ISERROR(B40-2),"",(E40-$E$14)*$C$5*$F$4) | G40: =IF(ISERROR(B40-2),"",-$C$7*$C$5*(A40-$A$14)/360) | I40: =IF(ISERROR(B40-2),"",-1*(C40+D40-F40)) | L40: 46157 | M40: 100.188 | N40: 45973 | O40: 244.1 | P40: =IF(COUNTIF(N:N,L40),L40,"") -> 46157 | Q40: =IF(P40>$A$14,P40,"") | AB40: =IF(COUNTIF(Z:Z,X40),X40,"")
A41: =IF(AND(ISBLANK(R30), A40 = $R$1),NOW(),IF(ISBLANK(R30),IF(ISBLANK(C40),NOW(),""),R30)) | B41: =IF(COUNTIF($R$2:R1026,A41)=1,VLOOKUP(A41,X:Y,2), IF(COUNTIF($R$2:R1026,A41)=0,$B$10,"")) | C41: =IF(ISERROR(B41-2),"",1*(B41/$B$14-1)*$B$5) | E41: =IF(COUNTIF(L:L,A41)=1,VLOOKUP(A41,N:O,2), IF(COUNTIF(L:L,A41)=0,$C$9,"")) | F41: =IF(ISERROR(B41-2),"",(E41-$E$14)*$C$5*$F$4) | G41: =IF(ISERROR(B41-2),"",-$C$7*$C$5*(A41-$A$14)/360) | I41: =IF(ISERROR(B41-2),"",-1*(C41+D41-F41)) | L41: 46160 | M41: 98.826 | N41: 45974 | O41: 244.15 | P41: =IF(COUNTIF(N:N,L41),L41,"") -> 46160 | Q41: =IF(P41>$A$14,P41,"") | AB41: =IF(COUNTIF(Z:Z,X41),X41,"")
...

Sheet 41c
B1: ERIXITSE Index | L1: =TODAY()-150 -> 46041 | R1: {=LOOKUP(2,1/(R:R<>""),R:R)} -> 46190 | AC1: Last ER Date = | AD1: {=LOOKUP(2,1/(AB:AB<>""),AB:AB)} -> 46190
B2: Short Risk | C2: Long Risk | L2: Short Risk | N2: Long Risk | R2: {=_xlfn.UNIQUE(Q:Q)} -> 0 | AC2: Last CDX = | AD2: =VLOOKUP(AD1,Z:AA,2) -> 54.383
A3: Name= | B3: SNRFIN S45 | C3: SX7E | L3: {=_xll.BDH($B$4, "PX_LAST, ", TODAY()-300, TODAY()-1)} -> 46101 | M3: 77.71 | N3: {=_xll.BDH($C$4, "PX_LAST, ", TODAY()-300, TODAY()-1)} -> 45922 | O3: 225.7 | P3: =IF(COUNTIF(N:N,L3),L3,"") -> 46101 | Q3: =IF(P3>$A$14,P3,"") | X3: {=_xll.BDH(B1, "LAST_PRICE", "05/01/2026","")} -> 46143 | Y3: 126.6553 | Z3: {=_xll.BDH(B4, "LAST_PRICE", "05/01/2026", "")} -> 46143 | AA3: 60.498 | AB3: =IF(COUNTIF(Z:Z,X3),X3,"") -> 46143 | AC3: Last ER = | AD3: =VLOOKUP(AD1,X:Y,2) -> 127.1312
A4: BBG Ticker= | B4: SNRFIN CDSI S45 5Y CORP | C4: CAM6 INDEX | E4: Contract Size = | F4: 50 | L4: 46104 | M4: 75.63 | N4: 45923 | O4: 226.65 | P4: =IF(COUNTIF(N:N,L4),L4,"") -> 46104 | Q4: =IF(P4>$A$14,P4,"") | R4: 46182 | X4: 46147 | Y4: 126.6293 | Z4: 46147 | AA4: 61.04 | AB4: =IF(COUNTIF(Z:Z,X4),X4,"") -> 46147 | AC4: Carry Days = | AD4: =INT(NOW())-INT(AD1) -> 1
A5: Not'l= | B5: =125*10^6 -> 125000000 | C5: 475 | L5: 46105 | M5: 76.055 | N5: 45924 | O5: 227.4 | P5: =IF(COUNTIF(N:N,L5),L5,"") -> 46105 | Q5: =IF(P5>$A$14,P5,"") | R5: 46183 | X5: 46148 | Y5: 126.7805 | Z5: 46148 | AA5: 58.662 | AB5: =IF(COUNTIF(Z:Z,X5),X5,"") -> 46148
A6: Carry= | B6: 0.01 | C6: 0 | L6: 46106 | M6: 73.439 | N6: 45925 | O6: 225.8 | P6: =IF(COUNTIF(N:N,L6),L6,"") -> 46106 | Q6: =IF(P6>$A$14,P6,"") | R6: 46184 | X6: 46149 | Y6: 126.7497 | Z6: 46149 | AA6: 59.383 | AB6: =IF(COUNTIF(Z:Z,X6),X6,"") -> 46149
A7: Financing Rate= | B7: 0 | C7: 0 | E7: Markit ER at Entry = | F7: 126.9854 | L7: 46107 | M7: 77.638 | N7: 45926 | O7: 230.25 | P7: =IF(COUNTIF(N:N,L7),L7,"") -> 46107 | Q7: =IF(P7>$A$14,P7,"") | R7: 46185 | X7: 46150 | Y7: 126.746 | Z7: 46150 | AA7: 59.294 | AB7: =IF(COUNTIF(Z:Z,X7),X7,"") -> 46150
A8: Initial Duration= | B8: 4.736 | L8: 46108 | M8: 80.096 | N8: 45929 | O8: 228.4 | P8: =IF(COUNTIF(N:N,L8),L8,"") -> 46108 | Q8: =IF(P8>$A$14,P8,"") | R8: 46188 | X8: 46153 | Y8: 126.7757 | Z8: 46153 | AA8: 58.977 | AB8: =IF(COUNTIF(Z:Z,X8),X8,"") -> 46153
A9: Live BBG PX= | B9: {=_xll.BDP(B4,"PX_LAST")} -> 54.28358 | C9: {=_xll.BDP(C4,"PX_LAST")} -> 295.2 | L9: 46111 | M9: 79.806 | N9: 45930 | O9: 228.85 | P9: =IF(COUNTIF(N:N,L9),L9,"") -> 46111 | Q9: =IF(P9>$A$14,P9,"") | R9: 46189 | X9: 46154 | Y9: 126.6486 | Z9: 46154 | AA9: 61.081 | AB9: =IF(COUNTIF(Z:Z,X9),X9,"") -> 46154
A10: Live ER = | B10: =AD3*(1-(B9-AD2)*B8*10^-4+B6*AD4/360) -> 127.14072 | L10: 46112 | M10: 77.741 | N10: 45931 | O10: 230.4 | P10: =IF(COUNTIF(N:N,L10),L10,"") -> 46112 | Q10: =IF(P10>$A$14,P10,"") | R10: 46190 | X10: 46155 | Y10: 126.7083 | Z10: 46155 | AA10: 59.909 | AB10: =IF(COUNTIF(Z:Z,X10),X10,"") -> 46155
L11: 46113 | M11: 71.61 | N11: 45932 | O11: 228.5 | P11: =IF(COUNTIF(N:N,L11),L11,"") -> 46113 | Q11: =IF(P11>$A$14,P11,"") | X11: 46156 | Y11: 126.7735 | Z11: 46156 | AA11: 58.857 | AB11: =IF(COUNTIF(Z:Z,X11),X11,"") -> 46156
A12: Date | B12: Short Risk | E12: Long Risk | H12: Div | I12: Net P/L | L12: 46114 | M12: 70.682 | N12: 45933 | O12: 229.3 | P12: =IF(COUNTIF(N:N,L12),L12,"") -> 46114 | Q12: =IF(P12>$A$14,P12,"") | X12: 46157 | Y12: 126.6627 | Z12: 46157 | AA12: 61.091 | AB12: =IF(COUNTIF(Z:Z,X12),X12,"") -> 46157
B13: Sprd | C13: Price P/L | D13: Carry P/L | E13: Price | F13: Price P/L | G13: Carry P/L | L13: 46119 | M13: 72.153 | N13: 45936 | O13: 226.55 | P13: =IF(COUNTIF(N:N,L13),L13,"") -> 46119 | Q13: =IF(P13>$A$14,P13,"") | X13: 46160 | Y13: 126.6943 | Z13: 46160 | AA13: 60.332 | AB13: =IF(COUNTIF(Z:Z,X13),X13,"") -> 46160
A14: 46181 | B14: =F7/(1-(D14-C14)*B8*10^-4) -> 127.00338 | C14: 56.4 | D14: 56.699 | E14: 268.05 | I14: 0 | L14: 46120 | M14: 64.495 | N14: 45937 | O14: 226 | P14: =IF(COUNTIF(N:N,L14),L14,"") -> 46120 | Q14: =IF(P14>$A$14,P14,"") | X14: 46161 | Y14: 126.6609 | Z14: 46161 | AA14: 61.037 | AB14: =IF(COUNTIF(Z:Z,X14),X14,"") -> 46161
A15: =IF(AND(ISBLANK(R4), A14 = $R$1),NOW(),IF(ISBLANK(R4),IF(ISBLANK(#REF!),NOW(),""),R4)) -> 46182 | B15: =IF(COUNTIF($R$2:R1000,A15)=1,VLOOKUP(A15,X:Y,2), IF(COUNTIF($R$2:R1000,A15)=0,$B$10,"")) -> 126.9854 | C15: =IF(ISERROR(B15-2),"",1*(B15/$B$14-1)*$B$5) -> -17700.8 | E15: =IF(COUNTIF(L:L,A15)=1,VLOOKUP(A15,N:O,2), IF(COUNTIF(L:L,A15)=0,$C$9,"")) -> 268.2 | F15: =IF(ISERROR(B15-2),"",(E15-$E$14)*$C$5*$F$4) -> 3562.5 | G15: =IF(ISERROR(B15-2),"",-$C$7*$C$5*(A15-$A$14)/360) -> 0 | I15: =IF(ISERROR(B15-2),"",F15-C15) -> 21263.3 | L15: 46121 | M15: 63.02 | N15: 45938 | O15: 226.95 | P15: =IF(COUNTIF(N:N,L15),L15,"") -> 46121 | Q15: =IF(P15>$A$14,P15,"") | X15: 46162 | Y15: 126.7999 | Z15: 46162 | AA15: 58.652 | AB15: =IF(COUNTIF(Z:Z,X15),X15,"") -> 46162
A16: =IF(AND(ISBLANK(R5), A15 = $R$1),NOW(),IF(ISBLANK(R5),IF(ISBLANK(C15),NOW(),""),R5)) -> 46183 | B16: =IF(COUNTIF($R$2:R1001,A16)=1,VLOOKUP(A16,X:Y,2), IF(COUNTIF($R$2:R1001,A16)=0,$B$10,"")) -> 126.9585 | C16: =IF(ISERROR(B16-2),"",1*(B16/$B$14-1)*$B$5) -> -44176.472 | E16: =IF(COUNTIF(L:L,A16)=1,VLOOKUP(A16,N:O,2), IF(COUNTIF(L:L,A16)=0,$C$9,"")) -> 266.35 | F16: =IF(ISERROR(B16-2),"",(E16-$E$14)*$C$5*$F$4) -> -40375 | G16: =IF(ISERROR(B16-2),"",-$C$7*$C$5*(A16-$A$14)/360) -> 0 | I16: =IF(ISERROR(B16-2),"",F16-C16) -> 3801.4724 | L16: 46122 | M16: 63.872 | N16: 45939 | O16: 225.35 | P16: =IF(COUNTIF(N:N,L16),L16,"") -> 46122 | Q16: =IF(P16>$A$14,P16,"") | X16: 46163 | Y16: 126.7782 | Z16: 46163 | AA16: 59.023 | AB16: =IF(COUNTIF(Z:Z,X16),X16,"") -> 46163
A17: =IF(AND(ISBLANK(R6), A16 = $R$1),NOW(),IF(ISBLANK(R6),IF(ISBLANK(C16),NOW(),""),R6)) -> 46184 | B17: =IF(COUNTIF($R$2:R1002,A17)=1,VLOOKUP(A17,X:Y,2), IF(COUNTIF($R$2:R1002,A17)=0,$B$10,"")) -> 126.9697 | C17: =IF(ISERROR(B17-2),"",1*(B17/$B$14-1)*$B$5) -> -33153.144 | E17: =IF(COUNTIF(L:L,A17)=1,VLOOKUP(A17,N:O,2), IF(COUNTIF(L:L,A17)=0,$C$9,"")) -> 267.05 | F17: =IF(ISERROR(B17-2),"",(E17-$E$14)*$C$5*$F$4) -> -23750 | G17: =IF(ISERROR(B17-2),"",-$C$7*$C$5*(A17-$A$14)/360) -> 0 | I17: =IF(ISERROR(B17-2),"",F17-C17) -> 9403.1441 | L17: 46125 | M17: 63.852 | N17: 45940 | O17: 222.5 | P17: =IF(COUNTIF(N:N,L17),L17,"") -> 46125 | Q17: =IF(P17>$A$14,P17,"") | X17: 46164 | Y17: 126.8774 | Z17: 46164 | AA17: 57.529 | AB17: =IF(COUNTIF(Z:Z,X17),X17,"") -> 46164
A18: =IF(AND(ISBLANK(R7), A17 = $R$1),NOW(),IF(ISBLANK(R7),IF(ISBLANK(C17),NOW(),""),R7)) -> 46185 | B18: =IF(COUNTIF($R$2:R1003,A18)=1,VLOOKUP(A18,X:Y,2), IF(COUNTIF($R$2:R1003,A18)=0,$B$10,"")) -> 127.0964 | C18: =IF(ISERROR(B18-2),"",1*(B18/$B$14-1)*$B$5) -> 91548.257 | E18: =IF(COUNTIF(L:L,A18)=1,VLOOKUP(A18,N:O,2), IF(COUNTIF(L:L,A18)=0,$C$9,"")) -> 277.55 | F18: =IF(ISERROR(B18-2),"",(E18-$E$14)*$C$5*$F$4) -> 225625 | G18: =IF(ISERROR(B18-2),"",-$C$7*$C$5*(A18-$A$14)/360) -> 0 | I18: =IF(ISERROR(B18-2),"",F18-C18) -> 134076.74 | L18: 46126 | M18: 61.024 | N18: 45943 | O18: 223.45 | P18: =IF(COUNTIF(N:N,L18),L18,"") -> 46126 | Q18: =IF(P18>$A$14,P18,"") | X18: 46168 | Y18: 126.945 | Z18: 46168 | AA18: 56.646 | AB18: =IF(COUNTIF(Z:Z,X18),X18,"") -> 46168
A19: =IF(AND(ISBLANK(R8), A18 = $R$1),NOW(),IF(ISBLANK(R8),IF(ISBLANK(C18),NOW(),""),R8)) -> 46188 | B19: =IF(COUNTIF($R$2:R1004,A19)=1,VLOOKUP(A19,X:Y,2), IF(COUNTIF($R$2:R1004,A19)=0,$B$10,"")) -> 127.1601 | C19: =IF(ISERROR(B19-2),"",1*(B19/$B$14-1)*$B$5) -> 154243.44 | E19: =IF(COUNTIF(L:L,A19)=1,VLOOKUP(A19,N:O,2), IF(COUNTIF(L:L,A19)=0,$C$9,"")) -> 284.15 | F19: =IF(ISERROR(B19-2),"",(E19-$E$14)*$C$5*$F$4) -> 382375 | G19: =IF(ISERROR(B19-2),"",-$C$7*$C$5*(A19-$A$14)/360) -> 0 | I19: =IF(ISERROR(B19-2),"",F19-C19) -> 228131.56 | L19: 46127 | M19: 61.375 | N19: 45944 | O19: 224 | P19: =IF(COUNTIF(N:N,L19),L19,"") -> 46127 | Q19: =IF(P19>$A$14,P19,"") | X19: 46169 | Y19: 126.9612 | Z19: 46169 | AA19: 56.587 | AB19: =IF(COUNTIF(Z:Z,X19),X19,"") -> 46169
A20: =IF(AND(ISBLANK(R9), A19 = $R$1),NOW(),IF(ISBLANK(R9),IF(ISBLANK(C19),NOW(),""),R9)) -> 46189 | B20: =IF(COUNTIF($R$2:R1005,A20)=1,VLOOKUP(A20,X:Y,2), IF(COUNTIF($R$2:R1005,A20)=0,$B$10,"")) -> 127.1471 | C20: =IF(ISERROR(B20-2),"",1*(B20/$B$14-1)*$B$5) -> 141448.5 | E20: =IF(COUNTIF(L:L,A20)=1,VLOOKUP(A20,N:O,2), IF(COUNTIF(L:L,A20)=0,$C$9,"")) -> 289.15 | F20: =IF(ISERROR(B20-2),"",(E20-$E$14)*$C$5*$F$4) -> 501125 | G20: =IF(ISERROR(B20-2),"",-$C$7*$C$5*(A20-$A$14)/360) -> 0 | I20: =IF(ISERROR(B20-2),"",F20-C20) -> 359676.5 | L20: 46128 | M20: 62.141 | N20: 45945 | O20: 223.6 | P20: =IF(COUNTIF(N:N,L20),L20,"") -> 46128 | Q20: =IF(P20>$A$14,P20,"") | X20: 46170 | Y20: 127.0003 | Z20: 46170 | AA20: 55.875 | AB20: =IF(COUNTIF(Z:Z,X20),X20,"") -> 46170
A21: =IF(AND(ISBLANK(R10), A20 = $R$1),NOW(),IF(ISBLANK(R10),IF(ISBLANK(C20),NOW(),""),R10)) -> 46190 | B21: =IF(COUNTIF($R$2:R1006,A21)=1,VLOOKUP(A21,X:Y,2), IF(COUNTIF($R$2:R1006,A21)=0,$B$10,"")) -> 127.1312 | C21: =IF(ISERROR(B21-2),"",1*(B21/$B$14-1)*$B$5) -> 125799.31 | E21: =IF(COUNTIF(L:L,A21)=1,VLOOKUP(A21,N:O,2), IF(COUNTIF(L:L,A21)=0,$C$9,"")) -> 294.4 | F21: =IF(ISERROR(B21-2),"",(E21-$E$14)*$C$5*$F$4) -> 625812.5 | G21: =IF(ISERROR(B21-2),"",-$C$7*$C$5*(A21-$A$14)/360) -> 0 | I21: =IF(ISERROR(B21-2),"",F21-C21) -> 500013.19 | L21: 46129 | M21: 59.907 | N21: 45946 | O21: 224.8 | P21: =IF(COUNTIF(N:N,L21),L21,"") -> 46129 | Q21: =IF(P21>$A$14,P21,"") | X21: 46171 | Y21: 127.0389 | Z21: 46171 | AA21: 55.31 | AB21: =IF(COUNTIF(Z:Z,X21),X21,"") -> 46171
A22: =IF(AND(ISBLANK(R11), A21 = $R$1),NOW(),IF(ISBLANK(R11),IF(ISBLANK(C21),NOW(),""),R11)) -> 46191.471 | B22: =IF(COUNTIF($R$2:R1007,A22)=1,VLOOKUP(A22,X:Y,2), IF(COUNTIF($R$2:R1007,A22)=0,$B$10,"")) -> 127.14072 | C22: =IF(ISERROR(B22-2),"",1*(B22/$B$14-1)*$B$5) -> 135166.62 | E22: =IF(COUNTIF(L:L,A22)=1,VLOOKUP(A22,N:O,2), IF(COUNTIF(L:L,A22)=0,$C$9,"")) -> 295.2 | F22: =IF(ISERROR(B22-2),"",(E22-$E$14)*$C$5*$F$4) -> 644812.5 | G22: =IF(ISERROR(B22-2),"",-$C$7*$C$5*(A22-$A$14)/360) -> 0 | I22: =IF(ISERROR(B22-2),"",F22-C22) -> 509645.88 | L22: 46132 | M22: 60.746 | N22: 45947 | O22: 219.65 | P22: =IF(COUNTIF(N:N,L22),L22,"") -> 46132 | Q22: =IF(P22>$A$14,P22,"") | X22: 46174 | Y22: 126.9841 | Z22: 46174 | AA22: 56.264 | AB22: =IF(COUNTIF(Z:Z,X22),X22,"") -> 46174
A23: =IF(AND(ISBLANK(R12), A22 = $R$1),NOW(),IF(ISBLANK(R12),IF(ISBLANK(C22),NOW(),""),R12)) | B23: =IF(COUNTIF($R$2:R1008,A23)=1,VLOOKUP(A23,X:Y,2), IF(COUNTIF($R$2:R1008,A23)=0,$B$10,"")) | C23: =IF(ISERROR(B23-2),"",1*(B23/$B$14-1)*$B$5) | E23: =IF(COUNTIF(L:L,A23)=1,VLOOKUP(A23,N:O,2), IF(COUNTIF(L:L,A23)=0,$C$9,"")) | F23: =IF(ISERROR(B23-2),"",(E23-$E$14)*$C$5*$F$4) | G23: =IF(ISERROR(B23-2),"",-$C$7*$C$5*(A23-$A$14)/360) | I23: =IF(ISERROR(B23-2),"",F23-C23) | L23: 46133 | M23: 62.038 | N23: 45950 | O23: 222.05 | P23: =IF(COUNTIF(N:N,L23),L23,"") -> 46133 | Q23: =IF(P23>$A$14,P23,"") | X23: 46175 | Y23: 127.0347 | Z23: 46175 | AA23: 55.412 | AB23: =IF(COUNTIF(Z:Z,X23),X23,"") -> 46175
A24: =IF(AND(ISBLANK(R13), A23 = $R$1),NOW(),IF(ISBLANK(R13),IF(ISBLANK(C23),NOW(),""),R13)) | B24: =IF(COUNTIF($R$2:R1009,A24)=1,VLOOKUP(A24,X:Y,2), IF(COUNTIF($R$2:R1009,A24)=0,$B$10,"")) | C24: =IF(ISERROR(B24-2),"",1*(B24/$B$14-1)*$B$5) | E24: =IF(COUNTIF(L:L,A24)=1,VLOOKUP(A24,N:O,2), IF(COUNTIF(L:L,A24)=0,$C$9,"")) | F24: =IF(ISERROR(B24-2),"",(E24-$E$14)*$C$5*$F$4) | G24: =IF(ISERROR(B24-2),"",-$C$7*$C$5*(A24-$A$14)/360) | I24: =IF(ISERROR(B24-2),"",F24-C24) | L24: 46134 | M24: 62.338 | N24: 45951 | O24: 220.85 | P24: =IF(COUNTIF(N:N,L24),L24,"") -> 46134 | Q24: =IF(P24>$A$14,P24,"") | X24: 46176 | Y24: 126.981 | Z24: 46176 | AA24: 56.543 | AB24: =IF(COUNTIF(Z:Z,X24),X24,"") -> 46176
A25: =IF(AND(ISBLANK(R14), A24 = $R$1),NOW(),IF(ISBLANK(R14),IF(ISBLANK(C24),NOW(),""),R14)) | B25: =IF(COUNTIF($R$2:R1010,A25)=1,VLOOKUP(A25,X:Y,2), IF(COUNTIF($R$2:R1010,A25)=0,$B$10,"")) | C25: =IF(ISERROR(B25-2),"",1*(B25/$B$14-1)*$B$5) | E25: =IF(COUNTIF(L:L,A25)=1,VLOOKUP(A25,N:O,2), IF(COUNTIF(L:L,A25)=0,$C$9,"")) | F25: =IF(ISERROR(B25-2),"",(E25-$E$14)*$C$5*$F$4) | G25: =IF(ISERROR(B25-2),"",-$C$7*$C$5*(A25-$A$14)/360) | I25: =IF(ISERROR(B25-2),"",F25-C25) | L25: 46135 | M25: 62.619 | N25: 45952 | O25: 220.15 | P25: =IF(COUNTIF(N:N,L25),L25,"") -> 46135 | Q25: =IF(P25>$A$14,P25,"") | X25: 46177 | Y25: 127.027 | Z25: 46177 | AA25: 55.634 | AB25: =IF(COUNTIF(Z:Z,X25),X25,"") -> 46177
A26: =IF(AND(ISBLANK(R15), A25 = $R$1),NOW(),IF(ISBLANK(R15),IF(ISBLANK(C25),NOW(),""),R15)) | B26: =IF(COUNTIF($R$2:R1011,A26)=1,VLOOKUP(A26,X:Y,2), IF(COUNTIF($R$2:R1011,A26)=0,$B$10,"")) | C26: =IF(ISERROR(B26-2),"",1*(B26/$B$14-1)*$B$5) | E26: =IF(COUNTIF(L:L,A26)=1,VLOOKUP(A26,N:O,2), IF(COUNTIF(L:L,A26)=0,$C$9,"")) | F26: =IF(ISERROR(B26-2),"",(E26-$E$14)*$C$5*$F$4) | G26: =IF(ISERROR(B26-2),"",-$C$7*$C$5*(A26-$A$14)/360) | I26: =IF(ISERROR(B26-2),"",F26-C26) | L26: 46136 | M26: 62.325 | N26: 45953 | O26: 220.45 | P26: =IF(COUNTIF(N:N,L26),L26,"") -> 46136 | Q26: =IF(P26>$A$14,P26,"") | X26: 46178 | Y26: 126.9882 | Z26: 46178 | AA26: 56.305 | AB26: =IF(COUNTIF(Z:Z,X26),X26,"") -> 46178
A27: =IF(AND(ISBLANK(R16), A26 = $R$1),NOW(),IF(ISBLANK(R16),IF(ISBLANK(C26),NOW(),""),R16)) | B27: =IF(COUNTIF($R$2:R1012,A27)=1,VLOOKUP(A27,X:Y,2), IF(COUNTIF($R$2:R1012,A27)=0,$B$10,"")) | C27: =IF(ISERROR(B27-2),"",1*(B27/$B$14-1)*$B$5) | E27: =IF(COUNTIF(L:L,A27)=1,VLOOKUP(A27,N:O,2), IF(COUNTIF(L:L,A27)=0,$C$9,"")) | F27: =IF(ISERROR(B27-2),"",(E27-$E$14)*$C$5*$F$4) | G27: =IF(ISERROR(B27-2),"",-$C$7*$C$5*(A27-$A$14)/360) | I27: =IF(ISERROR(B27-2),"",F27-C27) | L27: 46139 | M27: 62.608 | N27: 45954 | O27: 220 | P27: =IF(COUNTIF(N:N,L27),L27,"") -> 46139 | Q27: =IF(P27>$A$14,P27,"") | X27: 46181 | Y27: 126.9862 | Z27: 46181 | AA27: 56.44 | AB27: =IF(COUNTIF(Z:Z,X27),X27,"") -> 46181
... A29: =IF(AND(ISBLANK(R18), A28 = $R$1),NOW(),IF(ISBLANK(R18),IF(ISBLANK(C28),NOW(),""),R18)) | B29: =IF(COUNTIF($R$2:R1014,A29)=1,VLOOKUP(A29,X:Y,2), IF(COUNTIF($R$2:R1014,A29)=0,$B$10,"")) | C29: =IF(ISERROR(B29-2),"",1*(B29/$B$14-1)*$B$5) | E29: =IF(COUNTIF(L:L,A29)=1,VLOOKUP(A29,N:O,2), IF(COUNTIF(L:L,A29)=0,$C$9,"")) | F29: =IF(ISERROR(B29-2),"",(E29-$E$14)*$C$5*$F$4) | G29: =IF(ISERROR(B29-2),"",-$C$7*$C$5*(A29-$A$14)/360) | I29: =IF(ISERROR(B29-2),"",F29-C29) | L29: 46141 | M29: 63.991 | N29: 45958 | O29: 223.5 | P29: =IF(COUNTIF(N:N,L29),L29,"") -> 46141 | Q29: =IF(P29>$A$14,P29,"") | X29: 46183 | Y29: 126.9585 | Z29: 46183 | AA29: 57.075 | AB29: =IF(COUNTIF(Z:Z,X29),X29,"") -> 46183
A30: =IF(AND(ISBLANK(R19), A29 = $R$1),NOW(),IF(ISBLANK(R19),IF(ISBLANK(C29),NOW(),""),R19)) | B30: =IF(COUNTIF($R$2:R1015,A30)=1,VLOOKUP(A30,X:Y,2), IF(COUNTIF($R$2:R1015,A30)=0,$B$10,"")) | C30: =IF(ISERROR(B30-2),"",1*(B30/$B$14-1)*$B$5) | E30: =IF(COUNTIF(L:L,A30)=1,VLOOKUP(A30,N:O,2), IF(COUNTIF(L:L,A30)=0,$C$9,"")) | F30: =IF(ISERROR(B30-2),"",(E30-$E$14)*$C$5*$F$4) | G30: =IF(ISERROR(B30-2),"",-$C$7*$C$5*(A30-$A$14)/360) | H30: =$F$7*$F$4 -> 6349.27 | I30: =IF(ISERROR(B30-2),"",F30-C30) | L30: 46142 | M30: 62.525 | N30: 45959 | O30: 228.1 | P30: =IF(COUNTIF(N:N,L30),L30,"") -> 46142 | Q30: =IF(P30>$A$14,P30,"") | X30: 46184 | Y30: 126.9697 | Z30: 46184 | AA30: 56.803 | AB30: =IF(COUNTIF(Z:Z,X30),X30,"") -> 46184
A31: =IF(AND(ISBLANK(R20), A30 = $R$1),NOW(),IF(ISBLANK(R20),IF(ISBLANK(C30),NOW(),""),R20)) | B31: =IF(COUNTIF($R$2:R1016,A31)=1,VLOOKUP(A31,X:Y,2), IF(COUNTIF($R$2:R1016,A31)=0,$B$10,"")) | C31: =IF(ISERROR(B31-2),"",1*(B31/$B$14-1)*$B$5) | E31: =IF(COUNTIF(L:L,A31)=1,VLOOKUP(A31,N:O,2), IF(COUNTIF(L:L,A31)=0,$C$9,"")) | F31: =IF(ISERROR(B31-2),"",(E31-$E$14)*$C$5*$F$4) | G31: =IF(ISERROR(B31-2),"",-$C$7*$C$5*(A31-$A$14)/360) | I31: =IF(ISERROR(B31-2),"",F31-C31) | L31: 46143 | M31: 60.498 | N31: 45960 | O31: 227.3 | P31: =IF(COUNTIF(N:N,L31),L31,"") | Q31: =IF(P31>$A$14,P31,"") | X31: 46185 | Y31: 127.0964 | Z31: 46185 | AA31: 54.791 | AB31: =IF(COUNTIF(Z:Z,X31),X31,"") -> 46185
A32: =IF(AND(ISBLANK(R21), A31 = $R$1),NOW(),IF(ISBLANK(R21),IF(ISBLANK(C31),NOW(),""),R21)) | B32: =IF(COUNTIF($R$2:R1017,A32)=1,VLOOKUP(A32,X:Y,2), IF(COUNTIF($R$2:R1017,A32)=0,$B$10,"")) | C32: =IF(ISERROR(B32-2),"",1*(B32/$B$14-1)*$B$5) | E32: =IF(COUNTIF(L:L,A32)=1,VLOOKUP(A32,N:O,2), IF(COUNTIF(L:L,A32)=0,$C$9,"")) | F32: =IF(ISERROR(B32-2),"",(E32-$E$14)*$C$5*$F$4) | G32: =IF(ISERROR(B32-2),"",-$C$7*$C$5*(A32-$A$14)/360) | I32: =IF(ISERROR(B32-2),"",F32-C32) | L32: 46147 | M32: 61.04 | N32: 45961 | O32: 228.35 | P32: =IF(COUNTIF(N:N,L32),L32,"") -> 46147 | Q32: =IF(P32>$A$14,P32,"") | X32: 46188 | Y32: 127.1601 | Z32: 46188 | AA32: 53.712 | AB32: =IF(COUNTIF(Z:Z,X32),X32,"") -> 46188
A33: =IF(AND(ISBLANK(R22), A32 = $R$1),NOW(),IF(ISBLANK(R22),IF(ISBLANK(C32),NOW(),""),R22)) | B33: =IF(COUNTIF($R$2:R1018,A33)=1,VLOOKUP(A33,X:Y,2), IF(COUNTIF($R$2:R1018,A33)=0,$B$10,"")) | C33: =IF(ISERROR(B33-2),"",1*(B33/$B$14-1)*$B$5) | E33: =IF(COUNTIF(L:L,A33)=1,VLOOKUP(A33,N:O,2), IF(COUNTIF(L:L,A33)=0,$C$9,"")) | F33: =IF(ISERROR(B33-2),"",(E33-$E$14)*$C$5*$F$4) | G33: =IF(ISERROR(B33-2),"",-$C$7*$C$5*(A33-$A$14)/360) | I33: =IF(ISERROR(B33-2),"",F33-C33) | L33: 46148 | M33: 58.662 | N33: 45964 | O33: 228.9 | P33: =IF(COUNTIF(N:N,L33),L33,"") -> 46148 | Q33: =IF(P33>$A$14,P33,"") | X33: 46189 | Y33: 127.1471 | Z33: 46189 | AA33: 54.116 | AB33: =IF(COUNTIF(Z:Z,X33),X33,"") -> 46189
A34: =IF(AND(ISBLANK(R23), A33 = $R$1),NOW(),IF(ISBLANK(R23),IF(ISBLANK(C33),NOW(),""),R23)) | B34: =IF(COUNTIF($R$2:R1019,A34)=1,VLOOKUP(A34,X:Y,2), IF(COUNTIF($R$2:R1019,A34)=0,$B$10,"")) | C34: =IF(ISERROR(B34-2),"",1*(B34/$B$14-1)*$B$5) | E34: =IF(COUNTIF(L:L,A34)=1,VLOOKUP(A34,N:O,2), IF(COUNTIF(L:L,A34)=0,$C$9,"")) | F34: =IF(ISERROR(B34-2),"",(E34-$E$14)*$C$5*$F$4) | G34: =IF(ISERROR(B34-2),"",-$C$7*$C$5*(A34-$A$14)/360) | I34: =IF(ISERROR(B34-2),"",F34-C34) | L34: 46149 | M34: 59.383 | N34: 45965 | O34: 229.25 | P34: =IF(COUNTIF(N:N,L34),L34,"") -> 46149 | Q34: =IF(P34>$A$14,P34,"") | X34: 46190 | Y34: 127.1312 | Z34: 46190 | AA34: 54.383 | AB34: =IF(COUNTIF(Z:Z,X34),X34,"") -> 46190
A35: =IF(AND(ISBLANK(R24), A34 = $R$1),NOW(),IF(ISBLANK(R24),IF(ISBLANK(C34),NOW(),""),R24)) | B35: =IF(COUNTIF($R$2:R1020,A35)=1,VLOOKUP(A35,X:Y,2), IF(COUNTIF($R$2:R1020,A35)=0,$B$10,"")) | C35: =IF(ISERROR(B35-2),"",1*(B35/$B$14-1)*$B$5) | E35: =IF(COUNTIF(L:L,A35)=1,VLOOKUP(A35,N:O,2), IF(COUNTIF(L:L,A35)=0,$C$9,"")) | F35: =IF(ISERROR(B35-2),"",(E35-$E$14)*$C$5*$F$4) | G35: =IF(ISERROR(B35-2),"",-$C$7*$C$5*(A35-$A$14)/360) | I35: =IF(ISERROR(B35-2),"",F35-C35) | L35: 46150 | M35: 59.294 | N35: 45966 | O35: 230.35 | P35: =IF(COUNTIF(N:N,L35),L35,"") -> 46150 | Q35: =IF(P35>$A$14,P35,"") | Z35: 46191 | AA35: 54.266 | AB35: =IF(COUNTIF(Z:Z,X35),X35,"")
A36: =IF(AND(ISBLANK(R25), A35 = $R$1),NOW(),IF(ISBLANK(R25),IF(ISBLANK(C35),NOW(),""),R25)) | B36: =IF(COUNTIF($R$2:R1021,A36)=1,VLOOKUP(A36,X:Y,2), IF(COUNTIF($R$2:R1021,A36)=0,$B$10,"")) | C36: =IF(ISERROR(B36-2),"",1*(B36/$B$14-1)*$B$5) | E36: =IF(COUNTIF(L:L,A36)=1,VLOOKUP(A36,N:O,2), IF(COUNTIF(L:L,A36)=0,$C$9,"")) | F36: =IF(ISERROR(B36-2),"",(E36-$E$14)*$C$5*$F$4) | G36: =IF(ISERROR(B36-2),"",-$C$7*$C$5*(A36-$A$14)/360) | I36: =IF(ISERROR(B36-2),"",F36-C36) | L36: 46153 | M36: 58.977 | N36: 45967 | O36: 230.7 | P36: =IF(COUNTIF(N:N,L36),L36,"") -> 46153 | Q36: =IF(P36>$A$14,P36,"") | AB36: =IF(COUNTIF(Z:Z,X36),X36,"")
A37: =IF(AND(ISBLANK(R26), A36 = $R$1),NOW(),IF(ISBLANK(R26),IF(ISBLANK(C36),NOW(),""),R26)) | B37: =IF(COUNTIF($R$2:R1022,A37)=1,VLOOKUP(A37,X:Y,2), IF(COUNTIF($R$2:R1022,A37)=0,$B$10,"")) | C37: =IF(ISERROR(B37-2),"",1*(B37/$B$14-1)*$B$5) | E37: =IF(COUNTIF(L:L,A37)=1,VLOOKUP(A37,N:O,2), IF(COUNTIF(L:L,A37)=0,$C$9,"")) | F37: =IF(ISERROR(B37-2),"",(E37-$E$14)*$C$5*$F$4) | G37: =IF(ISERROR(B37-2),"",-$C$7*$C$5*(A37-$A$14)/360) | I37: =IF(ISERROR(B37-2),"",F37-C37) | L37: 46154 | M37: 61.081 | N37: 45968 | O37: 228.8 | P37: =IF(COUNTIF(N:N,L37),L37,"") -> 46154 | Q37: =IF(P37>$A$14,P37,"") | AB37: =IF(COUNTIF(Z:Z,X37),X37,"")
A38: =IF(AND(ISBLANK(R27), A37 = $R$1),NOW(),IF(ISBLANK(R27),IF(ISBLANK(C37),NOW(),""),R27)) | B38: =IF(COUNTIF($R$2:R1023,A38)=1,VLOOKUP(A38,X:Y,2), IF(COUNTIF($R$2:R1023,A38)=0,$B$10,"")) | C38: =IF(ISERROR(B38-2),"",1*(B38/$B$14-1)*$B$5) | E38: =IF(COUNTIF(L:L,A38)=1,VLOOKUP(A38,N:O,2), IF(COUNTIF(L:L,A38)=0,$C$9,"")) | F38: =IF(ISERROR(B38-2),"",(E38-$E$14)*$C$5*$F$4) | G38: =IF(ISERROR(B38-2),"",-$C$7*$C$5*(A38-$A$14)/360) | I38: =IF(ISERROR(B38-2),"",F38-C38) | L38: 46155 | M38: 59.909 | N38: 45971 | O38: 236.7 | P38: =IF(COUNTIF(N:N,L38),L38,"") -> 46155 | Q38: =IF(P38>$A$14,P38,"") | AB38: =IF(COUNTIF(Z:Z,X38),X38,"")
A39: =IF(AND(ISBLANK(R28), A38 = $R$1),NOW(),IF(ISBLANK(R28),IF(ISBLANK(C38),NOW(),""),R28)) | B39: =IF(COUNTIF($R$2:R1024,A39)=1,VLOOKUP(A39,X:Y,2), IF(COUNTIF($R$2:R1024,A39)=0,$B$10,"")) | C39: =IF(ISERROR(B39-2),"",1*(B39/$B$14-1)*$B$5) | E39: =IF(COUNTIF(L:L,A39)=1,VLOOKUP(A39,N:O,2), IF(COUNTIF(L:L,A39)=0,$C$9,"")) | F39: =IF(ISERROR(B39-2),"",(E39-$E$14)*$C$5*$F$4) | G39: =IF(ISERROR(B39-2),"",-$C$7*$C$5*(A39-$A$14)/360) | I39: =IF(ISERROR(B39-2),"",F39-C39) | L39: 46156 | M39: 58.857 | N39: 45972 | O39: 239.45 | P39: =IF(COUNTIF(N:N,L39),L39,"") -> 46156 | Q39: =IF(P39>$A$14,P39,"") | AB39: =IF(COUNTIF(Z:Z,X39),X39,"")
A40: =IF(AND(ISBLANK(R29), A39 = $R$1),NOW(),IF(ISBLANK(R29),IF(ISBLANK(C39),NOW(),""),R29)) | B40: =IF(COUNTIF($R$2:R1025,A40)=1,VLOOKUP(A40,X:Y,2), IF(COUNTIF($R$2:R1025,A40)=0,$B$10,"")) | C40: =IF(ISERROR(B40-2),"",1*(B40/$B$14-1)*$B$5) | E40: =IF(COUNTIF(L:L,A40)=1,VLOOKUP(A40,N:O,2), IF(COUNTIF(L:L,A40)=0,$C$9,"")) | F40: =IF(ISERROR(B40-2),"",(E40-$E$14)*$C$5*$F$4) | G40: =IF(ISERROR(B40-2),"",-$C$7*$C$5*(A40-$A$14)/360) | I40: =IF(ISERROR(B40-2),"",F40-C40) | L40: 46157 | M40: 61.091 | N40: 45973 | O40: 244.1 | P40: =IF(COUNTIF(N:N,L40),L40,"") -> 46157 | Q40: =IF(P40>$A$14,P40,"") | AB40: =IF(COUNTIF(Z:Z,X40),X40,"")
A41: =IF(AND(ISBLANK(R30), A40 = $R$1),NOW(),IF(ISBLANK(R30),IF(ISBLANK(C40),NOW(),""),R30)) | B41: =IF(COUNTIF($R$2:R1026,A41)=1,VLOOKUP(A41,X:Y,2), IF(COUNTIF($R$2:R1026,A41)=0,$B$10,"")) | C41: =IF(ISERROR(B41-2),"",1*(B41/$B$14-1)*$B$5) | E41: =IF(COUNTIF(L:L,A41)=1,VLOOKUP(A41,N:O,2), IF(COUNTIF(L:L,A41)=0,$C$9,"")) | F41: =IF(ISERROR(B41-2),"",(E41-$E$14)*$C$5*$F$4) | G41: =IF(ISERROR(B41-2),"",-$C$7*$C$5*(A41-$A$14)/360) | I41: =IF(ISERROR(B41-2),"",F41-C41) | L41: 46160 | M41: 60.332 | N41: 45974 | O41: 244.15 | P41: =IF(COUNTIF(N:N,L41),L41,"") -> 46160 | Q41: =IF(P41>$A$14,P41,"") | AB41: =IF(COUNTIF(Z:Z,X41),X41,"")
...

Sheet 44a
C1: ERIXITEU Index | O1: {=LOOKUP(2,1/(O:O<>""),O:O)} -> 46191.625 | P1: Expiry | Q1: 48001 | X1: Last ER Date = | Y1: {=LOOKUP(2,1/(W:W<>""),W:W)} -> 46190
B2: Short Risk | C2: Long Risk | J2: Short Risk | K2: Long Risk | O2: {=_xlfn._xlws.SORT(_xlfn.UNIQUE(_xlfn._xlws.FILTER(N:N, ISNUMBER(N:N))))} -> 46177.625 | P2: Start Date | Q2: =K3 -> 46143.625 | X2: Last CDX = | Y2: =VLOOKUP(Y1,U:V,2) -> 51.82
A3: Name= | B3: HSBC Sen 5Y CDS | C3: Main | J3: {=_xll.avmDates(Q2,Q3,"EUR")} -> 46191.625 | K3: {=_xll.BDH(C4, "LAST_PRICE", "05/01/2026 15:00:00", "01/01/2035 17:00:00", "BarSize=120", "BarType=T", "RecurDaily=True", "TZ=London")} -> 46143.625 | L3: 57.603 | M3: =IF(COUNTIF(K:K,J3),J3,"") -> 46191.625 | N3: =IF(M3>$A$14,M3,"") -> 46191.625 | O3: 46178.625 | P3: End Date | Q3: =INT(TODAY()) + TIME(15,0,0) -> 46191.625 | S3: {=_xll.BDH(C1, "LAST_PRICE", "05/01/2026","")} -> 46143 | T3: 121.8568 | U3: {=_xll.BDH(C4, "LAST_PRICE", "05/01/2026", "")} -> 46143 | V3: 57.603 | W3: =IF(COUNTIF(U:U,S3),S3,"") -> 46143 | X3: Last ER = | Y3: =VLOOKUP(Y1,S:T,2) -> 122.2856
A4: BBG Ticker= | B4: HSBCHLDCO CDS EUR SR 5Y D14 Corp | C4: ITRX EUR CDSI GEN 5Y CORP | J4: 46190.625 | K4: 46147.625 | L4: 58.123 | M4: =IF(COUNTIF(K:K,J4),J4,"") -> 46190.625 | N4: =IF(M4>$A$14,M4,"") -> 46190.625 | O4: 46181.625 | P4: Ticker | Q4: HSBC | S4: 46147 | T4: 121.8245 | U4: 46147 | V4: 58.123 | W4: =IF(COUNTIF(U:U,S4),S4,"") -> 46147 | X4: Carry Days = | Y4: =INT(NOW())-INT(Y1) -> 1
A5: Not'l= | B5: =50*10^6 -> 50000000 | C5: =38*10^6 -> 38000000 | J5: 46189.625 | K5: 46148.625 | L5: 55.771 | M5: =IF(COUNTIF(K:K,J5),J5,"") -> 46189.625 | N5: =IF(M5>$A$14,M5,"") -> 46189.625 | O5: 46182.625 | P5: Ccy | Q5: EUR | S5: 46148 | T5: 121.9664 | U5: 46148 | V5: 55.771 | W5: =IF(COUNTIF(U:U,S5),S5,"") -> 46148
A6: Carry= | B6: 0.01 | C6: 0.01 | J6: 46188.625 | K6: 46149.625 | L6: 56.514 | M6: =IF(COUNTIF(K:K,J6),J6,"") -> 46188.625 | N6: =IF(M6>$A$14,M6,"") -> 46188.625 | O6: 46183.625 | P6: Tier | Q6: SNRFOR | S6: 46149 | T6: 121.9353 | U6: 46149 | V6: 56.514 | W6: =IF(COUNTIF(U:U,S6),S6,"") -> 46149
A7: Financing Rate= | B7: 0 | C7: 0 | J7: 46185.625 | K7: 46150.625 | L7: 56.433 | M7: =IF(COUNTIF(K:K,J7),J7,"") -> 46185.625 | N7: =IF(M7>$A$14,M7,"") -> 46185.625 | O7: 46184.625 | P7: Doc | Q7: MM14 | S7: 46150 | T7: 121.9332 | U7: 46150 | V7: 56.433 | W7: =IF(COUNTIF(U:U,S7),S7,"") -> 46150
A8: Initial Duration= | B8: 4.89 | C8: 4.769 | J8: 46184.625 | K8: 46153.625 | L8: 56.263 | M8: =IF(COUNTIF(K:K,J8),J8,"") -> 46184.625 | N8: =IF(M8>$A$14,M8,"") -> 46184.625 | O8: 46185.625 | S8: 46153 | T8: 121.9509 | U8: 46153 | V8: 56.263 | W8: =IF(COUNTIF(U:U,S8),S8,"") -> 46153
A9: Live BBG PX= | B9: {=_xll.BDP(B4,"PX_LAST")} -> 37.99845 | C9: {=_xll.BDP(C4,"PX_LAST")} -> 51.59373 | J9: 46183.625 | K9: 46154.625 | L9: 58.118 | M9: =IF(COUNTIF(K:K,J9),J9,"") -> 46183.625 | N9: =IF(M9>$A$14,M9,"") -> 46183.625 | O9: 46188.625 | S9: 46154 | T9: 121.8444 | U9: 46154 | V9: 58.118 | W9: =IF(COUNTIF(U:U,S9),S9,"") -> 46154
A10: Live ER= | C10: =Y3*(1-(C9-Y2)*C8*10^-4+C6/360*Y4) -> 122.30219 | J10: 46182.625 | K10: 46155.625 | L10: 57.145 | M10: =IF(COUNTIF(K:K,J10),J10,"") -> 46182.625 | N10: =IF(M10>$A$14,M10,"") -> 46182.625 | O10: 46189.625 | S10: 46155 | T10: 121.8929 | U10: 46155 | V10: 57.145 | W10: =IF(COUNTIF(U:U,S10),S10,"") -> 46155
J11: 46181.625 | K11: 46156.625 | L11: 56.268 | M11: =IF(COUNTIF(K:K,J11),J11,"") -> 46181.625 | N11: =IF(M11>$A$14,M11,"") -> 46181.625 | O11: 46190.625 | S11: 46156 | T11: 121.9464 | U11: 46156 | V11: 56.268 | W11: =IF(COUNTIF(U:U,S11),S11,"") -> 46156
A12: Date | B12: Short Risk | E12: Long Risk | H12: Net P/L | J12: 46178.625 | K12: 46157.625 | L12: 58.142 | M12: =IF(COUNTIF(K:K,J12),J12,"") -> 46178.625 | N12: =IF(M12>$A$14,M12,"") -> 46178.625 | O12: 46191.625 | S12: 46157 | T12: 121.8493 | U12: 46157 | V12: 58.142 | W12: =IF(COUNTIF(U:U,S12),S12,"") -> 46157
B13: Sprd | C13: Sprd P/L | D13: Carry P/L | E13: Price | F13: Price P/L | G13: Carry P/L | J13: 46177.625 | K13: 46160.625 | L13: 57.507 | M13: =IF(COUNTIF(K:K,J13),J13,"") -> 46177.625 | N13: =IF(M13>$A$14,M13,"") -> 46177.625 | S13: 46160 | T13: 121.8806 | U13: 46160 | V13: 57.507 | W13: =IF(COUNTIF(U:U,S13),S13,"") -> 46160
A14: 46176.625 | B14: 41 | E14: =VLOOKUP(A14-TIME(15,0,0),S:T,2)/(1-(G14-F14)*10^-4*C8) -> 122.16246 | F14: 53.5 | G14: 53.81 | H14: 0 | J14: 46176.625 | K14: 46161.625 | L14: 58.331 | M14: =IF(COUNTIF(K:K,J14),J14,"") -> 46176.625 | N14: =IF(M14>$A$14,M14,"") | S14: 46161 | T14: 121.8409 | U14: 46161 | V14: 58.331 | W14: =IF(COUNTIF(U:U,S14),S14,"") -> 46161
A15: =IF(AND(ISBLANK(O2), A14 = $O$1),NOW(),IF(AND(ISBLANK(O2),O2<NOW()),"",O2)) -> 46177.625 | B15: {=IF(COUNTIF(J:J,A15)=1,_xll.avmCdsSpreadForDate($Q$4,$Q$5,$Q$7,$Q$6,A15,$Q$1), IF(COUNTIF(J:J,A15)=0,$B$9,""))} -> 40.710693 | C15: =IF(ISERROR(B15-2),"",-1*(B15-$B$14)*10^-4*$B$8*$B$5) -> 7073.5525 | D15: =IF(ISERROR(B15-2),"",(INT(A15)-INT($A$14))/360*$B$6*$B$5) -> 1388.8889 | E15: =IF(COUNTIF(O:O,A15)=1,VLOOKUP(A15-TIME(15,0,0),S:T,2), IF(AND(COUNTIF(O:O,A15-TIME(15,0,0))=0,NOT(ISERROR(B15-2))),$C$10,"")) -> 122.181 | F15: =IF(ISERROR(B15-2),"", (E15/$E$14-1)*$C$5) -> 5766.9575 | H15: =IF(ISERROR(B15-2),"",(-1*(C15+D15))+F15+G15) -> -2695.4839 | J15: 46175.625 | K15: 46162.625 | L15: 56.151 | M15: =IF(COUNTIF(K:K,J15),J15,"") -> 46175.625 | N15: =IF(M15>$A$14,M15,"") | S15: 46162 | T15: 121.9667 | U15: 46162 | V15: 56.151 | W15: =IF(COUNTIF(U:U,S15),S15,"") -> 46162
A16: =IF(AND(ISBLANK(O3), A15 = $O$1),NOW(),IF(AND(ISBLANK(O3),O3<NOW()),"",O3)) -> 46178.625 | B16: {=IF(COUNTIF(J:J,A16)=1,_xll.avmCdsSpreadForDate($Q$4,$Q$5,$Q$7,$Q$6,A16,$Q$1), IF(COUNTIF(J:J,A16)=0,$B$9,""))} -> 40.725619 | C16: =IF(ISERROR(B16-2),"",-1*(B16-$B$14)*10^-4*$B$8*$B$5) -> 6708.6111 | D16: =IF(ISERROR(B16-2),"",(INT(A16)-INT($A$14))/360*$B$6*$B$5) -> 2777.7778 | E16: =IF(COUNTIF(O:O,A16)=1,VLOOKUP(A16-TIME(15,0,0),S:T,2), IF(AND(COUNTIF(O:O,A16-TIME(15,0,0))=0,NOT(ISERROR(B16-2))),$C$10,"")) -> 122.1475 | F16: =IF(ISERROR(B16-2),"", (E16/$E$14-1)*$C$5) -> -4653.5923 | H16: =IF(ISERROR(B16-2),"",(-1*(C16+D16))+F16+G16) -> -14139.981 | J16: 46174.625 | K16: 46163.625 | L16: 56.641 | M16: =IF(COUNTIF(K:K,J16),J16,"") -> 46174.625 | N16: =IF(M16>$A$14,M16,"") | S16: 46163 | T16: 121.9359 | U16: 46163 | V16: 56.641 | W16: =IF(COUNTIF(U:U,S16),S16,"") -> 46163
A17: =IF(AND(ISBLANK(O4), A16 = $O$1),NOW(),IF(AND(ISBLANK(O4),O4<NOW()),"",O4)) -> 46181.625 | B17: {=IF(COUNTIF(J:J,A17)=1,_xll.avmCdsSpreadForDate($Q$4,$Q$5,$Q$7,$Q$6,A17,$Q$1), IF(COUNTIF(J:J,A17)=0,$B$9,""))} -> 41.377222 | C17: =IF(ISERROR(B17-2),"",-1*(B17-$B$14)*10^-4*$B$8*$B$5) -> -9223.0759 | D17: =IF(ISERROR(B17-2),"",(INT(A17)-INT($A$14))/360*$B$6*$B$5) -> 6944.4444 | E17: =IF(COUNTIF(O:O,A17)=1,VLOOKUP(A17-TIME(15,0,0),S:T,2), IF(AND(COUNTIF(O:O,A17-TIME(15,0,0))=0,NOT(ISERROR(B17-2))),$C$10,"")) -> 122.1476 | F17: =IF(ISERROR(B17-2),"", (E17/$E$14-1)*$C$5) -> -4622.4862 | H17: =IF(ISERROR(B17-2),"",(-1*(C17+D17))+F17+G17) -> -2343.8548 | J17: 46171.625 | K17: 46164.625 | L17: 55.135 | M17: =IF(COUNTIF(K:K,J17),J17,"") -> 46171.625 | N17: =IF(M17>$A$14,M17,"") | S17: 46164 | T17: 122.0292 | U17: 46164 | V17: 55.135 | W17: =IF(COUNTIF(U:U,S17),S17,"") -> 46164
A18: =IF(AND(ISBLANK(O5), A17 = $O$1),NOW(),IF(AND(ISBLANK(O5),O5<NOW()),"",O5)) -> 46182.625 | B18: {=IF(COUNTIF(J:J,A18)=1,_xll.avmCdsSpreadForDate($Q$4,$Q$5,$Q$7,$Q$6,A18,$Q$1), IF(COUNTIF(J:J,A18)=0,$B$9,""))} -> 41.223247 | C18: =IF(ISERROR(B18-2),"",-1*(B18-$B$14)*10^-4*$B$8*$B$5) -> -5458.3788 | D18: =IF(ISERROR(B18-2),"",(INT(A18)-INT($A$14))/360*$B$6*$B$5) -> 8333.3333 | E18: =IF(COUNTIF(O:O,A18)=1,VLOOKUP(A18-TIME(15,0,0),S:T,2), IF(AND(COUNTIF(O:O,A18-TIME(15,0,0))=0,NOT(ISERROR(B18-2))),$C$10,"")) -> 122.1432 | F18: =IF(ISERROR(B18-2),"", (E18/$E$14-1)*$C$5) -> -5991.1554 | H18: =IF(ISERROR(B18-2),"",(-1*(C18+D18))+F18+G18) -> -8866.11 | J18: 46170.625 | K18: 46168.625 | L18: 54.31 | M18: =IF(COUNTIF(K:K,J18),J18,"") -> 46170.625 | N18: =IF(M18>$A$14,M18,"") | S18: 46168 | T18: 122.0951 | U18: 46168 | V18: 54.31 | W18: =IF(COUNTIF(U:U,S18),S18,"") -> 46168
