Workbook

Sheet IHYG vs AHW
A1: IHYG vs AHW — continuous trade P/L comparison (roll-adjusted M6 → U6)
A2: Long EUR HY (AHW future vs IHYG ETF) hedged short OBL 2.4% 10/28 + short Xover S44. P/L recomputes on open in Excel; post-roll & new dates auto-fill as Bloomberg extends the source columns.
A4: Assumptions (green = linked to source sheets, blue = input)
A5: Entry date | B5: ='13a (2)'!A14
A6: Roll date | B6: 46189.625
A7: Future entry px | B7: ='13a (2)'!B14
A8: Value of 1 pt | B8: ='13a (2)'!G3
A9: # contracts | B9: ='13a (2)'!I3
A10: M6 px @ roll | B10: =IFERROR(VLOOKUP($B$6,'13a (2)'!$O:$P,2,FALSE),"")
A11: U6 px @ roll | B11: =IFERROR(VLOOKUP($B$6,'13a (2)'!$AI:$AJ,2,FALSE),"")
A12: OBL entry px | B12: ='13a (2)'!E14
A13: OBL notional | B13: ='13a (2)'!C5
A14: OBL carry | B14: ='13a (2)'!C6
A15: OBL financing | B15: ='13a (2)'!C7
A16: Xover entry index | B16: ='13a (2)'!I14
A17: Xover notional | B17: ='13a (2)'!D5
A20: Date | B20: M6 Px | C20: U6 Px | D20: OBL Px | E20: Xover Adj.Index | F20: AHW Net P/L | G20: IHYG Net P/L
A21: 46113.625 | B21: =IFERROR(VLOOKUP($A21,'13a (2)'!$O:$P,2,FALSE),"") | C21: =IFERROR(VLOOKUP($A21,'13a (2)'!$AI:$AJ,2,FALSE),"") | D21: =IFERROR(VLOOKUP($A21,'13a (2)'!$Q:$R,2,FALSE),"") | E21: =IFERROR(VLOOKUP(INT($A21),'13a (2)'!$X:$Y,2,FALSE),"") | F21: 0 | G21: 0
A22: 46120.625 | B22: =IFERROR(VLOOKUP($A22,'13a (2)'!$O:$P,2,FALSE),"") | C22: =IFERROR(VLOOKUP($A22,'13a (2)'!$AI:$AJ,2,FALSE),"") | D22: =IFERROR(VLOOKUP($A22,'13a (2)'!$Q:$R,2,FALSE),"") | E22: =IFERROR(VLOOKUP(INT($A22),'13a (2)'!$X:$Y,2,FALSE),"") | F22: =IF($A22<=$B$6,IFERROR(VLOOKUP($A22,'13a (2)'!$A:$M,13,FALSE),""),IFERROR(($B$10-$B$7)*$B$8*$B$9+($C22-$B$11)*$B$8*$B$9-($D22-$B$12)/100*$B$13-((INT($A22)-INT($B$5))/360*$B$14*$B$13-(INT($A22)-INT($B$5))/360*$B$15*$B$13*$B$12/100)-($E22/$B$16-1)*$B$17,"")) | G22: =IFERROR(VLOOKUP($A22,'13 (2)'!$A:$M,13,FALSE),"")
A23: 46122.625 | B23: =IFERROR(VLOOKUP($A23,'13a (2)'!$O:$P,2,FALSE),"") | C23: =IFERROR(VLOOKUP($A23,'13a (2)'!$AI:$AJ,2,FALSE),"") | D23: =IFERROR(VLOOKUP($A23,'13a (2)'!$Q:$R,2,FALSE),"") | E23: =IFERROR(VLOOKUP(INT($A23),'13a (2)'!$X:$Y,2,FALSE),"") | F23: =IF($A23<=$B$6,IFERROR(VLOOKUP($A23,'13a (2)'!$A:$M,13,FALSE),""),IFERROR(($B$10-$B$7)*$B$8*$B$9+($C23-$B$11)*$B$8*$B$9-($D23-$B$12)/100*$B$13-((INT($A23)-INT($B$5))/360*$B$14*$B$13-(INT($A23)-INT($B$5))/360*$B$15*$B$13*$B$12/100)-($E23/$B$16-1)*$B$17,"")) | G23: =IFERROR(VLOOKUP($A23,'13 (2)'!$A:$M,13,FALSE),"")
A24: 46126.625 | B24: =IFERROR(VLOOKUP($A24,'13a (2)'!$O:$P,2,FALSE),"") | C24: =IFERROR(VLOOKUP($A24,'13a (2)'!$AI:$AJ,2,FALSE),"") | D24: =IFERROR(VLOOKUP($A24,'13a (2)'!$Q:$R,2,FALSE),"") | E24: =IFERROR(VLOOKUP(INT($A24),'13a (2)'!$X:$Y,2,FALSE),"") | F24: =IF($A24<=$B$6,IFERROR(VLOOKUP($A24,'13a (2)'!$A:$M,13,FALSE),""),IFERROR(($B$10-$B$7)*$B$8*$B$9+($C24-$B$11)*$B$8*$B$9-($D24-$B$12)/100*$B$13-((INT($A24)-INT($B$5))/360*$B$14*$B$13-(INT($A24)-INT($B$5))/360*$B$15*$B$13*$B$12/100)-($E24/$B$16-1)*$B$17,"")) | G24: =IFERROR(VLOOKUP($A24,'13 (2)'!$A:$M,13,FALSE),"")
A25: 46127.625 | B25: =IFERROR(VLOOKUP($A25,'13a (2)'!$O:$P,2,FALSE),"") | C25: =IFERROR(VLOOKUP($A25,'13a (2)'!$AI:$AJ,2,FALSE),"") | D25: =IFERROR(VLOOKUP($A25,'13a (2)'!$Q:$R,2,FALSE),"") | E25: =IFERROR(VLOOKUP(INT($A25),'13a (2)'!$X:$Y,2,FALSE),"") | F25: =IF($A25<=$B$6,IFERROR(VLOOKUP($A25,'13a (2)'!$A:$M,13,FALSE),""),IFERROR(($B$10-$B$7)*$B$8*$B$9+($C25-$B$11)*$B$8*$B$9-($D25-$B$12)/100*$B$13-((INT($A25)-INT($B$5))/360*$B$14*$B$13-(INT($A25)-INT($B$5))/360*$B$15*$B$13*$B$12/100)-($E25/$B$16-1)*$B$17,"")) | G25: =IFERROR(VLOOKUP($A25,'13 (2)'!$A:$M,13,FALSE),"")
A26: 46128.625 | B26: =IFERROR(VLOOKUP($A26,'13a (2)'!$O:$P,2,FALSE),"") | C26: =IFERROR(VLOOKUP($A26,'13a (2)'!$AI:$AJ,2,FALSE),"") | D26: =IFERROR(VLOOKUP($A26,'13a (2)'!$Q:$R,2,FALSE),"") | E26: =IFERROR(VLOOKUP(INT($A26),'13a (2)'!$X:$Y,2,FALSE),"") | F26: =IF($A26<=$B$6,IFERROR(VLOOKUP($A26,'13a (2)'!$A:$M,13,FALSE),""),IFERROR(($B$10-$B$7)*$B$8*$B$9+($C26-$B$11)*$B$8*$B$9-($D26-$B$12)/100*$B$13-((INT($A26)-INT($B$5))/360*$B$14*$B$13-(INT($A26)-INT($B$5))/360*$B$15*$B$13*$B$12/100)-($E26/$B$16-1)*$B$17,"")) | G26: =IFERROR(VLOOKUP($A26,'13 (2)'!$A:$M,13,FALSE),"")
A27: 46129.625 | B27: =IFERROR(VLOOKUP($A27,'13a (2)'!$O:$P,2,FALSE),"") | C27: =IFERROR(VLOOKUP($A27,'13a (2)'!$AI:$AJ,2,FALSE),"") | D27: =IFERROR(VLOOKUP($A27,'13a (2)'!$Q:$R,2,FALSE),"") | E27: =IFERROR(VLOOKUP(INT($A27),'13a (2)'!$X:$Y,2,FALSE),"") | F27: =IF($A27<=$B$6,IFERROR(VLOOKUP($A27,'13a (2)'!$A:$M,13,FALSE),""),IFERROR(($B$10-$B$7)*$B$8*$B$9+($C27-$B$11)*$B$8*$B$9-($D27-$B$12)/100*$B$13-((INT($A27)-INT($B$5))/360*$B$14*$B$13-(INT($A27)-INT($B$5))/360*$B$15*$B$13*$B$12/100)-($E27/$B$16-1)*$B$17,"")) | G27: =IFERROR(VLOOKUP($A27,'13 (2)'!$A:$M,13,FALSE),"")
A28: 46132.625 | B28: =IFERROR(VLOOKUP($A28,'13a (2)'!$O:$P,2,FALSE),"") | C28: =IFERROR(VLOOKUP($A28,'13a (2)'!$AI:$AJ,2,FALSE),"") | D28: =IFERROR(VLOOKUP($A28,'13a (2)'!$Q:$R,2,FALSE),"") | E28: =IFERROR(VLOOKUP(INT($A28),'13a (2)'!$X:$Y,2,FALSE),"") | F28: =IF($A28<=$B$6,IFERROR(VLOOKUP($A28,'13a (2)'!$A:$M,13,FALSE),""),IFERROR(($B$10-$B$7)*$B$8*$B$9+($C28-$B$11)*$B$8*$B$9-($D28-$B$12)/100*$B$13-((INT($A28)-INT($B$5))/360*$B$14*$B$13-(INT($A28)-INT($B$5))/360*$B$15*$B$13*$B$12/100)-($E28/$B$16-1)*$B$17,"")) | G28: =IFERROR(VLOOKUP($A28,'13 (2)'!$A:$M,13,FALSE),"")
A29: 46133.625 | B29: =IFERROR(VLOOKUP($A29,'13a (2)'!$O:$P,2,FALSE),"") | C29: =IFERROR(VLOOKUP($A29,'13a (2)'!$AI:$AJ,2,FALSE),"") | D29: =IFERROR(VLOOKUP($A29,'13a (2)'!$Q:$R,2,FALSE),"") | E29: =IFERROR(VLOOKUP(INT($A29),'13a (2)'!$X:$Y,2,FALSE),"") | F29: =IF($A29<=$B$6,IFERROR(VLOOKUP($A29,'13a (2)'!$A:$M,13,FALSE),""),IFERROR(($B$10-$B$7)*$B$8*$B$9+($C29-$B$11)*$B$8*$B$9-($D29-$B$12)/100*$B$13-((INT($A29)-INT($B$5))/360*$B$14*$B$13-(INT($A29)-INT($B$5))/360*$B$15*$B$13*$B$12/100)-($E29/$B$16-1)*$B$17,"")) | G29: =IFERROR(VLOOKUP($A29,'13 (2)'!$A:$M,13,FALSE),"")
A30: 46134.625 | B30: =IFERROR(VLOOKUP($A30,'13a (2)'!$O:$P,2,FALSE),"") | C30: =IFERROR(VLOOKUP($A30,'13a (2)'!$AI:$AJ,2,FALSE),"") | D30: =IFERROR(VLOOKUP($A30,'13a (2)'!$Q:$R,2,FALSE),"") | E30: =IFERROR(VLOOKUP(INT($A30),'13a (2)'!$X:$Y,2,FALSE),"") | F30: =IF($A30<=$B$6,IFERROR(VLOOKUP($A30,'13a (2)'!$A:$M,13,FALSE),""),IFERROR(($B$10-$B$7)*$B$8*$B$9+($C30-$B$11)*$B$8*$B$9-($D30-$B$12)/100*$B$13-((INT($A30)-INT($B$5))/360*$B$14*$B$13-(INT($A30)-INT($B$5))/360*$B$15*$B$13*$B$12/100)-($E30/$B$16-1)*$B$17,"")) | G30: =IFERROR(VLOOKUP($A30,'13 (2)'!$A:$M,13,FALSE),"")
A31: 46136.625 | B31: =IFERROR(VLOOKUP($A31,'13a (2)'!$O:$P,2,FALSE),"") | C31: =IFERROR(VLOOKUP($A31,'13a (2)'!$AI:$AJ,2,FALSE),"") | D31: =IFERROR(VLOOKUP($A31,'13a (2)'!$Q:$R,2,FALSE),"") | E31: =IFERROR(VLOOKUP(INT($A31),'13a (2)'!$X:$Y,2,FALSE),"") | F31: =IF($A31<=$B$6,IFERROR(VLOOKUP($A31,'13a (2)'!$A:$M,13,FALSE),""),IFERROR(($B$10-$B$7)*$B$8*$B$9+($C31-$B$11)*$B$8*$B$9-($D31-$B$12)/100*$B$13-((INT($A31)-INT($B$5))/360*$B$14*$B$13-(INT($A31)-INT($B$5))/360*$B$15*$B$13*$B$12/100)-($E31/$B$16-1)*$B$17,"")) | G31: =IFERROR(VLOOKUP($A31,'13 (2)'!$A:$M,13,FALSE),"")
A32: 46139.625 | B32: =IFERROR(VLOOKUP($A32,'13a (2)'!$O:$P,2,FALSE),"") | C32: =IFERROR(VLOOKUP($A32,'13a (2)'!$AI:$AJ,2,FALSE),"") | D32: =IFERROR(VLOOKUP($A32,'13a (2)'!$Q:$R,2,FALSE),"") | E32: =IFERROR(VLOOKUP(INT($A32),'13a (2)'!$X:$Y,2,FALSE),"") | F32: =IF($A32<=$B$6,IFERROR(VLOOKUP($A32,'13a (2)'!$A:$M,13,FALSE),""),IFERROR(($B$10-$B$7)*$B$8*$B$9+($C32-$B$11)*$B$8*$B$9-($D32-$B$12)/100*$B$13-((INT($A32)-INT($B$5))/360*$B$14*$B$13-(INT($A32)-INT($B$5))/360*$B$15*$B$13*$B$12/100)-($E32/$B$16-1)*$B$17,"")) | G32: =IFERROR(VLOOKUP($A32,'13 (2)'!$A:$M,13,FALSE),"")
A33: 46140.625 | B33: =IFERROR(VLOOKUP($A33,'13a (2)'!$O:$P,2,FALSE),"") | C33: =IFERROR(VLOOKUP($A33,'13a (2)'!$AI:$AJ,2,FALSE),"") | D33: =IFERROR(VLOOKUP($A33,'13a (2)'!$Q:$R,2,FALSE),"") | E33: =IFERROR(VLOOKUP(INT($A33),'13a (2)'!$X:$Y,2,FALSE),"") | F33: =IF($A33<=$B$6,IFERROR(VLOOKUP($A33,'13a (2)'!$A:$M,13,FALSE),""),IFERROR(($B$10-$B$7)*$B$8*$B$9+($C33-$B$11)*$B$8*$B$9-($D33-$B$12)/100*$B$13-((INT($A33)-INT($B$5))/360*$B$14*$B$13-(INT($A33)-INT($B$5))/360*$B$15*$B$13*$B$12/100)-($E33/$B$16-1)*$B$17,"")) | G33: =IFERROR(VLOOKUP($A33,'13 (2)'!$A:$M,13,FALSE),"")
... A122: 46283.625 | B122: =IFERROR(VLOOKUP($A122,'13a (2)'!$O:$P,2,FALSE),"") | C122: =IFERROR(VLOOKUP($A122,'13a (2)'!$AI:$AJ,2,FALSE),"") | D122: =IFERROR(VLOOKUP($A122,'13a (2)'!$Q:$R,2,FALSE),"") | E122: =IFERROR(VLOOKUP(INT($A122),'13a (2)'!$X:$Y,2,FALSE),"") | F122: =IF($A122<=$B$6,IFERROR(VLOOKUP($A122,'13a (2)'!$A:$M,13,FALSE),""),IFERROR(($B$10-$B$7)*$B$8*$B$9+($C122-$B$11)*$B$8*$B$9-($D122-$B$12)/100*$B$13-((INT($A122)-INT($B$5))/360*$B$14*$B$13-(INT($A122)-INT($B$5))/360*$B$15*$B$13*$B$12/100)-($E122/$B$16-1)*$B$17,"")) | G122: =IFERROR(VLOOKUP($A122,'13 (2)'!$A:$M,13,FALSE),"")

Sheet Dividends
A1: DIVIDEND HISTORY (live BDS — Bloomberg, Ex-Date + Amount)
A3: EMB | D3: VCIT | G3: IHYG
A4: EMB US EQUITY | D4: VCIT US EQUITY | G4: IHYG LN EQUITY
A5: Ex-Date | B5: Amount | D5: Ex-Date | E5: Amount | G5: Ex-Date | H5: Amount
A6: {=_xlfn.CHOOSECOLS(_xll.BDS($A$4,"DVD_HIST_ALL","DVD_START_DT=20240101","DVD_END_DT=20351231","HEADERS=N"),2,5)} -> 46174 | B6: 0.407041 | D6: {=_xlfn.CHOOSECOLS(_xll.BDS($D$4,"DVD_HIST_ALL","DVD_START_DT=20240101","DVD_END_DT=20351231","HEADERS=N"),2,5)} -> 46174 | E6: 0.3412 | G6: {=_xlfn.CHOOSECOLS(_xll.BDS($G$4,"DVD_HIST_ALL","DVD_START_DT=20240101","DVD_END_DT=20351231","HEADERS=N"),2,5)} -> 46191 | H6: 1.1646
A7: 46143 | B7: 0.410076 | D7: 46143 | E7: 0.3262 | G7: 46100 | H7: 2.3303
A8: 46113 | B8: 0.455397 | D8: 46113 | E8: 0.3438 | G8: 45911 | H8: 2.4173
A9: 46083 | B9: 0.402963 | D9: 46083 | E9: 0.3026 | G9: 45729 | H9: 2.6722
A10: 46055 | B10: 0.41458 | D10: 46055 | E10: 0.33 | G10: 45547 | H10: 2.8229
A11: 46010 | B11: 0.382893 | D11: 46009 | E11: 0.3358 | G11: 45365 | H11: 2.9
A12: 45992 | B12: 0.372202 | D12: 45992 | E12: 0.3223
A13: 45964 | B13: 0.417558 | D13: 45964 | E13: 0.334
A14: 45931 | B14: 0.392529 | D14: 45931 | E14: 0.326
A15: 45902 | B15: 0.401921 | D15: 45902 | E15: 0.3279
A16: 45870 | B16: 0.411035 | D16: 45870 | E16: 0.3408
A17: 45839 | B17: 0.379909 | D17: 45839 | E17: 0.3207
A18: 45810 | B18: 0.405383 | D18: 45810 | E18: 0.328
A19: 45778 | B19: 0.402288 | D19: 45778 | E19: 0.3151
A20: 45748 | B20: 0.399904 | D20: 45748 | E20: 0.3189
A21: 45719 | B21: 0.385564 | D21: 45719 | E21: 0.2865
A22: 45691 | B22: 0.440929 | D22: 45691 | E22: 0.3129
A23: 45656 | B23: 0.254515 | D23: 45650 | E23: 0.3119
... A34: 45352 | B34: 0.385713 | D34: 45323 | E34: 0.281
A35: 45323 | B35: 0.367262

Sheet 13a
D1: ERIXITXO INDEX | W1: {=LOOKUP(2,1/(W:W<>""),W:W)} -> 46190.625 | AE1: Last ER Date = | AF1: {=LOOKUP(2,1/(AD:AD<>""),AD:AD)} -> 46198
B2: Long Risk | C2: Short Risk | D2: Short Risk | G2: Value of 1pt | H2: Single Contract Notional at Start | I2: # of contracts | O2: Long Risk | Q2: Short Risk | S2: Short Risk | W2: {=_xlfn._xlws.SORT(_xlfn.UNIQUE(_xlfn._xlws.FILTER(V:V, ISNUMBER(V:V))))} -> 46094.625 | AE2: Last CDX = | AF2: =VLOOKUP(AF1,AB:AC,2) -> 247.307
A3: Name= | B3: EUR HY Fut | C3: OBL 2.4% 10/28 | D3: Xover S44 | F3: Eur HY Fut= | G3: 200 | H3: =200*B14 -> 62752 | I3: =INT(B5/H3) -> 478 | O3: {=_xll.BDH(B4, "LAST_PRICE", "01/26/2026 15:00:00", "01/26/2035 16:00:00", "BarSize=60", "BarType=T", "RecurDaily=True", "TZ=London")} -> 46094.625 | P3: 306.42 | Q3: {=_xll.BDH(C4, "LAST_PRICE", "01/26/2026 15:00:00", "01/01/2035 16:00:00", "BarSize=60", "BarType=T", "RecurDaily=True", "TZ=London")} -> 46048.625 | R3: 100.566 | S3: {=_xll.BDH(D4, "LAST_PRICE", "01/26/2026 15:00:00", "01/01/2035 16:00:00", "BarSize=60", "BarType=T", "RecurDaily=True", "TZ=London")} -> 46048.625 | T3: 242.329 | U3: =IF(COUNTIF(Q:Q,O3)*COUNTIF(S:S,O3),O3,"") -> 46094.625 | V3: =IF(U3>$A$14,U3,"") -> 46094.625 | W3: 46097.625 | Z3: {=_xll.BDH(D1, "LAST_PRICE", "05/01/2025","")} -> 45778 | AA3: 231.3922 | AB3: {=_xll.BDH(D4, "LAST_PRICE", "05/01/2025", "")} -> 45778 | AC3: 343.699 | AD3: =IF(COUNTIF(AB:AB,Z3),Z3,"") -> 45778 | AE3: Last ER = | AF3: =VLOOKUP(AF1,Z:AA,2) -> 255.5413
A4: BBG Ticker= | B4: AHWM6 Index | C4: ZK885444@BGN Corp | D4: ITRX XOVER CDSI GEN 5Y CORP | O4: 46097.625 | P4: 306.38 | Q4: 46049.625 | R4: 100.59 | S4: 46049.625 | T4: 241.372 | U4: =IF(COUNTIF(Q:Q,O4)*COUNTIF(S:S,O4),O4,"") -> 46097.625 | V4: =IF(U4>$A$14,U4,"") -> 46097.625 | W4: 46098.625 | X4: {=_xll.BDH("ERIXILXO Index", "PX_LAST", "01/22/2026", "")} -> 46044 | Y4: 264.1611 | Z4: 45779 | AA4: 232.4699 | AB4: 45779 | AC4: 333.964 | AD4: =IF(COUNTIF(AB:AB,Z4),Z4,"") -> 45779 | AE4: Carry Days = | AF4: =INT(NOW())-INT(AF1) -> 0
A5: Not'l= | B5: =30*10^6 -> 30000000 | C5: =26*10^6 -> 26000000 | D5: =18.7*10^6 -> 18700000 | O5: 46098.625 | P5: 307.76 | Q5: 46050.625 | R5: 100.65 | S5: 46050.625 | T5: 244.391 | U5: =IF(COUNTIF(Q:Q,O5)*COUNTIF(S:S,O5),O5,"") -> 46098.625 | V5: =IF(U5>$A$14,U5,"") -> 46098.625 | W5: 46099.625 | X5: 46045 | Y5: 263.9462 | Z5: 45783 | AA5: 232.7954 | AB5: 45783 | AC5: 331.257 | AD5: =IF(COUNTIF(AB:AB,Z5),Z5,"") -> 45783
A6: Carry= | B6: 0 | C6: 0.024 | D6: 0.05 | O6: 46099.625 | P6: 307.34 | Q6: 46051.625 | R6: 100.706 | S6: 46051.625 | T6: 249.25 | U6: =IF(COUNTIF(Q:Q,O6)*COUNTIF(S:S,O6),O6,"") -> 46099.625 | V6: =IF(U6>$A$14,U6,"") -> 46099.625 | W6: 46100.625 | X6: 46048 | Y6: 264.0295 | Z6: 45784 | AA6: 232.8287 | AB6: 45784 | AC6: 330.319 | AD6: =IF(COUNTIF(AB:AB,Z6),Z6,"") -> 45784
A7: Financing Rate= | B7: 0 | C7: {=_xll.BDP("EURR002W INDEX","PX_LAST")/100} -> 0.024 | D7: 0 | O7: 46100.625 | P7: 306.06 | Q7: 46052.625 | R7: 100.675 | S7: 46052.625 | T7: 246.12 | U7: =IF(COUNTIF(Q:Q,O7)*COUNTIF(S:S,O7),O7,"") -> 46100.625 | V7: =IF(U7>$A$14,U7,"") -> 46100.625 | W7: 46101.625 | X7: 46049 | Y7: 264.1769 | Z7: 45785 | AA7: 233.9237 | AB7: 45785 | AC7: 319.942 | AD7: =IF(COUNTIF(AB:AB,Z7),Z7,"") -> 45785
A8: Initial Duration= | B8: - | C8: - | D8: 4.859 | O8: 46101.625 | P8: 304.02 | Q8: 46055.625 | R8: 100.607 | S8: 46055.625 | T8: 243.642 | U8: =IF(COUNTIF(Q:Q,O8)*COUNTIF(S:S,O8),O8,"") -> 46101.625 | V8: =IF(U8>$A$14,U8,"") -> 46101.625 | W8: 46104.625 | X8: 46050 | Y8: 263.7748 | Z8: 45786 | AA8: 233.9268 | AB8: 45786 | AC8: 320.065 | AD8: =IF(COUNTIF(AB:AB,Z8),Z8,"") -> 45786
A9: Live PX= | B9: {=_xll.BDP(B4,"PX_LAST")} -> 313.66 | C9: {=_xll.BDP(C4,"PX_LAST")} -> 99.747 | D9: {=_xll.BDP(D4,"PX_LAST")} -> 247.3067 | O9: 46104.625 | P9: 305 | Q9: 46056.625 | R9: 100.576 | S9: 46056.625 | T9: 243.64 | U9: =IF(COUNTIF(Q:Q,O9)*COUNTIF(S:S,O9),O9,"") -> 46104.625 | V9: =IF(U9>$A$14,U9,"") -> 46104.625 | W9: 46105.625 | X9: 46051 | Y9: 263.4651 | Z9: 45789 | AA9: 235.5827 | AB9: 45789 | AC9: 306.82 | AD9: =IF(COUNTIF(AB:AB,Z9),Z9,"") -> 45789
A10: Live ER = | O10: 46105.625 | P10: 304.52 | Q10: 46057.625 | R10: 100.637 | S10: 46057.625 | T10: 244.557 | U10: =IF(COUNTIF(Q:Q,O10)*COUNTIF(S:S,O10),O10,"") -> 46105.625 | V10: =IF(U10>$A$14,U10,"") -> 46105.625 | W10: 46106.625 | X10: 46052 | Y10: 263.6153 | Z10: 45790 | AA10: 236.7813 | AB10: 45790 | AC10: 295.552 | AD10: =IF(COUNTIF(AB:AB,Z10),Z10,"") -> 45790
O11: 46106.625 | P11: 306.12 | Q11: 46058.625 | R11: 100.67 | S11: 46058.625 | T11: 249.851 | U11: =IF(COUNTIF(Q:Q,O11)*COUNTIF(S:S,O11),O11,"") -> 46106.625 | V11: =IF(U11>$A$14,U11,"") -> 46106.625 | W11: 46107.625 | X11: 46055 | Y11: 264.1297 | Z11: 45791 | AA11: 236.4158 | AB11: 45791 | AC11: 299.078 | AD11: =IF(COUNTIF(AB:AB,Z11),Z11,"") -> 45791
A12: Date | B12: Long Risk | E12: Short Risk | H12: Short Risk | L12: IHYG Dvd | M12: Net P/L | O12: 46107.625 | P12: 304.82 | Q12: 46059.625 | R12: 100.67 | S12: 46059.625 | T12: 244.11 | U12: =IF(COUNTIF(Q:Q,O12)*COUNTIF(S:S,O12),O12,"") -> 46107.625 | V12: =IF(U12>$A$14,U12,"") -> 46107.625 | W12: 46108.625 | X12: 46056 | Y12: 264 | Z12: 45792 | AA12: 236.2761 | AB12: 45792 | AC12: 300.107 | AD12: =IF(COUNTIF(AB:AB,Z12),Z12,"") -> 45792
B13: Price | C13: Price P/L | D13: Carry P/L | E13: Price | F13: Price P/L | G13: Carry P/L | H13: Sprd | I13: Index | J13: Adj. Index | K13: P/L | O13: 46108.625 | P13: 303.5 | Q13: 46062.625 | R13: 100.702 | S13: 46062.625 | T13: 241.44 | U13: =IF(COUNTIF(Q:Q,O13)*COUNTIF(S:S,O13),O13,"") -> 46108.625 | V13: =IF(U13>$A$14,U13,"") -> 46108.625 | W13: 46111.625 | X13: 46057 | Y13: 263.8195 | Z13: 45793 | AA13: 236.2916 | AB13: 45793 | AC13: 301.295 | AD13: =IF(COUNTIF(AB:AB,Z13),Z13,"") -> 45793
A14: 46049.625 | B14: 313.76 | E14: =IF(COUNTIF($W$2:W999,A14)=1,VLOOKUP(A14,Q:R,2), IF(COUNTIF($W$2:W999,A14)=0,$C$9,"")) -> 99.747 | H14: 241.372 | I14: 264.18 | J14: =IF(ISERROR(H14-2),"",I14) -> 264.18 | M14: 0 | O14: 46111.625 | P14: 302.92 | Q14: 46063.625 | R14: 100.736 | S14: 46063.625 | T14: 241.986 | U14: =IF(COUNTIF(Q:Q,O14)*COUNTIF(S:S,O14),O14,"") -> 46111.625 | V14: =IF(U14>$A$14,U14,"") -> 46111.625 | W14: 46112.625 | X14: 46058 | Y14: 263.5473 | Z14: 45796 | AA14: 236.3481 | AB14: 45796 | AC14: 299.938 | AD14: =IF(COUNTIF(AB:AB,Z14),Z14,"") -> 45796
A15: =IF(AND(ISBLANK(W4), A14 = $W$1),NOW(),IF(ISBLANK(W4),"",W4)) -> 46098.625 | B15: =IF(COUNTIF($W$2:W1000,A15)=1,VLOOKUP(A15,O:P,2), IF(COUNTIF($W$2:W1000,A15)=0,$B$9,"")) -> 307.76 | C15: =IF(ISERROR(B15-2),"",(B15-$B$14)*$G$3*$I$3) -> -573600 | E15: =IF(COUNTIF($W$2:W1000,A15)=1,VLOOKUP(A15,Q:R,2), IF(COUNTIF($W$2:W1000,A15)=0,$C$9,"")) -> 99.993 | F15: =IF(ISERROR(B15-2),"",(E15-$E$14)/100*$C$5) -> 63960 | G15: =IF(ISERROR(B15-2),"",(INT(A15)-INT($A$14))/360*$C$6*$C$5-(INT(A15)-INT($A$14))/360*$C$7*$C$5*$E$14/100) -> 214.88133 | H15: =IF(COUNTIF($W$2:W1000,A15)=1,VLOOKUP(A15,S:T,2), IF(COUNTIF($W$2:W1000,A15)=0,$D$9,"")) -> 294.984 | I15: =IF(COUNTIF($X$2:X1000,INT(A15))=1,VLOOKUP(INT(A15),X:Y,2), IF(ISERROR(H15-2),"",I14*(1-$D$8*(H15-H14)*0.0001))) -> 258.8311 | J15: =IF(ISERROR(H15-2),"",I15) -> 258.8311 | K15: =IF(ISERROR(H15-2),"",(J15/$J$14-1)*$D$5) -> -378622.27 | M15: =IF(ISERROR(B15-2),"",C15+D15-F15-G15-K15+SUM($L$14:L15)) -> -259152.62 | O15: 46112.625 | P15: 304.16 | Q15: 46064.625 | R15: 100.73 | S15: 46064.625 | T15: 242.796 | U15: =IF(COUNTIF(Q:Q,O15)*COUNTIF(S:S,O15),O15,"") -> 46112.625 | V15: =IF(U15>$A$14,U15,"") -> 46112.625 | W15: 46113.625 | X15: 46059 | Y15: 264.1749 | Z15: 45797 | AA15: 236.8784 | AB15: 45797 | AC15: 295.737 | AD15: =IF(COUNTIF(AB:AB,Z15),Z15,"") -> 45797
A16: =IF(AND(ISBLANK(W5), A15 = $W$1),NOW(),IF(ISBLANK(W5),"",W5)) -> 46099.625 | B16: =IF(COUNTIF($W$2:W1001,A16)=1,VLOOKUP(A16,O:P,2), IF(COUNTIF($W$2:W1001,A16)=0,$B$9,"")) -> 307.34 | C16: =IF(ISERROR(B16-2),"",(B16-$B$14)*$G$3*$I$3) -> -613752 | E16: =IF(COUNTIF($W$2:W1001,A16)=1,VLOOKUP(A16,Q:R,2), IF(COUNTIF($W$2:W1001,A16)=0,$C$9,"")) -> 99.842 | F16: =IF(ISERROR(B16-2),"",(E16-$E$14)/100*$C$5) -> 24700 | G16: =IF(ISERROR(B16-2),"",(INT(A16)-INT($A$14))/360*$C$6*$C$5-(INT(A16)-INT($A$14))/360*$C$7*$C$5*$E$14/100) -> 219.26667 | H16: =IF(COUNTIF($W$2:W1001,A16)=1,VLOOKUP(A16,S:T,2), IF(COUNTIF($W$2:W1001,A16)=0,$D$9,"")) -> 298.827 | I16: =IF(COUNTIF($X$2:X1001,INT(A16))=1,VLOOKUP(INT(A16),X:Y,2), IF(ISERROR(H16-2),"",I15*(1-$D$8*(H16-H15)*0.0001))) -> 258.3931 | J16: =IF(ISERROR(H16-2),"",I16) -> 258.3931 | K16: =IF(ISERROR(H16-2),"",(J16/$J$14-1)*$D$5) -> -409626.13 | M16: =IF(ISERROR(B16-2),"",C16+D16-F16-G16-K16+SUM($L$14:L16)) -> -229045.14 | O16: 46113.625 | P16: 306.24 | Q16: 46065.625 | R16: 100.751 | S16: 46065.625 | T16: 244.618 | U16: =IF(COUNTIF(Q:Q,O16)*COUNTIF(S:S,O16),O16,"") -> 46113.625 | V16: =IF(U16>$A$14,U16,"") -> 46113.625 | W16: 46114.625 | X16: 46062 | Y16: 264.5603 | Z16: 45798 | AA16: 236.6263 | AB16: 45798 | AC16: 298.613 | AD16: =IF(COUNTIF(AB:AB,Z16),Z16,"") -> 45798
A17: =IF(AND(ISBLANK(W6), A16 = $W$1),NOW(),IF(ISBLANK(W6),"",W6)) -> 46100.625 | B17: =IF(COUNTIF($W$2:W1002,A17)=1,VLOOKUP(A17,O:P,2), IF(COUNTIF($W$2:W1002,A17)=0,$B$9,"")) -> 306.06 | C17: =IF(ISERROR(B17-2),"",(B17-$B$14)*$G$3*$I$3) -> -736120 | E17: =IF(COUNTIF($W$2:W1002,A17)=1,VLOOKUP(A17,Q:R,2), IF(COUNTIF($W$2:W1002,A17)=0,$C$9,"")) -> 99.639 | F17: =IF(ISERROR(B17-2),"",(E17-$E$14)/100*$C$5) -> -28080 | G17: =IF(ISERROR(B17-2),"",(INT(A17)-INT($A$14))/360*$C$6*$C$5-(INT(A17)-INT($A$14))/360*$C$7*$C$5*$E$14/100) -> 223.652 | H17: =IF(COUNTIF($W$2:W1002,A17)=1,VLOOKUP(A17,S:T,2), IF(COUNTIF($W$2:W1002,A17)=0,$D$9,"")) -> 309.039 | I17: =IF(COUNTIF($X$2:X1002,INT(A17))=1,VLOOKUP(INT(A17),X:Y,2), IF(ISERROR(H17-2),"",I16*(1-$D$8*(H17-H16)*0.0001))) -> 257.0634 | J17: =IF(ISERROR(H17-2),"",I17) -> 257.0634 | K17: =IF(ISERROR(H17-2),"",(J17/$J$14-1)*$D$5) -> -503749.03 | M17: =IF(ISERROR(B17-2),"",C17+D17-F17-G17-K17+SUM($L$14:L17)) -> -204514.62 | O17: 46114.625 | P17: 306.5 | Q17: 46066.625 | R17: 100.819 | S17: 46066.625 | T17: 247.573 | U17: =IF(COUNTIF(Q:Q,O17)*COUNTIF(S:S,O17),O17,"") -> 46114.625 | V17: =IF(U17>$A$14,U17,"") -> 46114.625 | W17: 46119.625 | X17: 46063 | Y17: 264.468 | Z17: 45799 | AA17: 236.1527 | AB17: 45799 | AC17: 302.621 | AD17: =IF(COUNTIF(AB:AB,Z17),Z17,"") -> 45799
A18: =IF(AND(ISBLANK(W7), A17 = $W$1),NOW(),IF(ISBLANK(W7),"",W7)) -> 46101.625 | B18: =IF(COUNTIF($W$2:W1003,A18)=1,VLOOKUP(A18,O:P,2), IF(COUNTIF($W$2:W1003,A18)=0,$B$9,"")) -> 304.02 | C18: =IF(ISERROR(B18-2),"",(B18-$B$14)*$G$3*$I$3) -> -931144 | E18: =IF(COUNTIF($W$2:W1003,A18)=1,VLOOKUP(A18,Q:R,2), IF(COUNTIF($W$2:W1003,A18)=0,$C$9,"")) -> 99.41 | F18: =IF(ISERROR(B18-2),"",(E18-$E$14)/100*$C$5) -> -87620 | G18: =IF(ISERROR(B18-2),"",(INT(A18)-INT($A$14))/360*$C$6*$C$5-(INT(A18)-INT($A$14))/360*$C$7*$C$5*$E$14/100) -> 228.03733 | H18: =IF(COUNTIF($W$2:W1003,A18)=1,VLOOKUP(A18,S:T,2), IF(COUNTIF($W$2:W1003,A18)=0,$D$9,"")) -> 350.866 | I18: =IF(COUNTIF($X$2:X1003,INT(A18))=1,VLOOKUP(INT(A18),X:Y,2), IF(ISERROR(H18-2),"",I17*(1-$D$8*(H18-H17)*0.0001))) -> 255.8712 | J18: =IF(ISERROR(H18-2),"",I18) -> 255.8712 | K18: =IF(ISERROR(H18-2),"",(J18/$J$14-1)*$D$5) -> -588139 | M18: =IF(ISERROR(B18-2),"",C18+D18-F18-G18-K18+SUM($L$14:L18)) -> -255613.04 | O18: 46119.625 | P18: 305.86 | Q18: 46069.625 | R18: 100.827 | S18: 46069.625 | T18: 248.949 | U18: =IF(COUNTIF(Q:Q,O18)*COUNTIF(S:S,O18),O18,"") -> 46119.625 | V18: =IF(U18>$A$14,U18,"") -> 46119.625 | W18: 46120.625 | X18: 46064 | Y18: 264.3549 | Z18: 45800 | AA18: 234.8886 | AB18: 45800 | AC18: 315.955 | AD18: =IF(COUNTIF(AB:AB,Z18),Z18,"") -> 45800
A19: =IF(AND(ISBLANK(W8), A18 = $W$1),NOW(),IF(ISBLANK(W8),"",W8)) -> 46104.625 | B19: =IF(COUNTIF($W$2:W1004,A19)=1,VLOOKUP(A19,O:P,2), IF(COUNTIF($W$2:W1004,A19)=0,$B$9,"")) -> 305 | C19: =IF(ISERROR(B19-2),"",(B19-$B$14)*$G$3*$I$3) -> -837456 | E19: =IF(COUNTIF($W$2:W1004,A19)=1,VLOOKUP(A19,Q:R,2), IF(COUNTIF($W$2:W1004,A19)=0,$C$9,"")) -> 99.53 | F19: =IF(ISERROR(B19-2),"",(E19-$E$14)/100*$C$5) -> -56420 | G19: =IF(ISERROR(B19-2),"",(INT(A19)-INT($A$14))/360*$C$6*$C$5-(INT(A19)-INT($A$14))/360*$C$7*$C$5*$E$14/100) -> 241.19333 | H19: =IF(COUNTIF($W$2:W1004,A19)=1,VLOOKUP(A19,S:T,2), IF(COUNTIF($W$2:W1004,A19)=0,$D$9,"")) -> 341.823 | I19: =IF(COUNTIF($X$2:X1004,INT(A19))=1,VLOOKUP(INT(A19),X:Y,2), IF(ISERROR(H19-2),"",I18*(1-$D$8*(H19-H18)*0.0001))) -> 256.7421 | J19: =IF(ISERROR(H19-2),"",I19) -> 256.7421 | K19: =IF(ISERROR(H19-2),"",(J19/$J$14-1)*$D$5) -> -526492.28 | M19: =IF(ISERROR(B19-2),"",C19+D19-F19-G19-K19+SUM($L$14:L19)) -> -254784.92 | O19: 46120.625 | P19: 309.58 | Q19: 46070.625 | R19: 100.844 | S19: 46070.625 | T19: 252.082 | U19: =IF(COUNTIF(Q:Q,O19)*COUNTIF(S:S,O19),O19,"") -> 46120.625 | V19: =IF(U19>$A$14,U19,"") -> 46120.625 | W19: 46122.625 | X19: 46065 | Y19: 264.0449 | Z19: 45804 | AA19: 236.6034 | AB19: 45804 | AC19: 300.109 | AD19: =IF(COUNTIF(AB:AB,Z19),Z19,"") -> 45804
A20: =IF(AND(ISBLANK(W9), A19 = $W$1),NOW(),IF(ISBLANK(W9),"",W9)) -> 46105.625 | B20: =IF(COUNTIF($W$2:W1005,A20)=1,VLOOKUP(A20,O:P,2), IF(COUNTIF($W$2:W1005,A20)=0,$B$9,"")) -> 304.52 | C20: =IF(ISERROR(B20-2),"",(B20-$B$14)*$G$3*$I$3) -> -883344 | E20: =IF(COUNTIF($W$2:W1005,A20)=1,VLOOKUP(A20,Q:R,2), IF(COUNTIF($W$2:W1005,A20)=0,$C$9,"")) -> 99.401 | F20: =IF(ISERROR(B20-2),"",(E20-$E$14)/100*$C$5) -> -89960 | G20: =IF(ISERROR(B20-2),"",(INT(A20)-INT($A$14))/360*$C$6*$C$5-(INT(A20)-INT($A$14))/360*$C$7*$C$5*$E$14/100) -> 245.57867 | H20: =IF(COUNTIF($W$2:W1005,A20)=1,VLOOKUP(A20,S:T,2), IF(COUNTIF($W$2:W1005,A20)=0,$D$9,"")) -> 342.434 | I20: =IF(COUNTIF($X$2:X1005,INT(A20))=1,VLOOKUP(INT(A20),X:Y,2), IF(ISERROR(H20-2),"",I19*(1-$D$8*(H20-H19)*0.0001))) -> 256.9957 | J20: =IF(ISERROR(H20-2),"",I20) -> 256.9957 | K20: =IF(ISERROR(H20-2),"",(J20/$J$14-1)*$D$5) -> -508541.18 | M20: =IF(ISERROR(B20-2),"",C20+D20-F20-G20-K20+SUM($L$14:L20)) -> -285088.39 | O20: 46122.625 | P20: 309.46 | Q20: 46071.625 | R20: 100.795 | S20: 46071.625 | T20: 245.436 | U20: =IF(COUNTIF(Q:Q,O20)*COUNTIF(S:S,O20),O20,"") -> 46122.625 | V20: =IF(U20>$A$14,U20,"") -> 46122.625 | W20: 46126.625 | X20: 46066 | Y20: 263.8886 | Z20: 45805 | AA20: 236.6898 | AB20: 45805 | AC20: 300.604 | AD20: =IF(COUNTIF(AB:AB,Z20),Z20,"") -> 45805
A21: =IF(AND(ISBLANK(W10), A20 = $W$1),NOW(),IF(ISBLANK(W10),"",W10)) -> 46106.625 | B21: =IF(COUNTIF($W$2:W1006,A21)=1,VLOOKUP(A21,O:P,2), IF(COUNTIF($W$2:W1006,A21)=0,$B$9,"")) -> 306.12 | C21: =IF(ISERROR(B21-2),"",(B21-$B$14)*$G$3*$I$3) -> -730384 | E21: =IF(COUNTIF($W$2:W1006,A21)=1,VLOOKUP(A21,Q:R,2), IF(COUNTIF($W$2:W1006,A21)=0,$C$9,"")) -> 99.501 | F21: =IF(ISERROR(B21-2),"",(E21-$E$14)/100*$C$5) -> -63960 | G21: =IF(ISERROR(B21-2),"",(INT(A21)-INT($A$14))/360*$C$6*$C$5-(INT(A21)-INT($A$14))/360*$C$7*$C$5*$E$14/100) -> 249.964 | H21: =IF(COUNTIF($W$2:W1006,A21)=1,VLOOKUP(A21,S:T,2), IF(COUNTIF($W$2:W1006,A21)=0,$D$9,"")) -> 334.504 | I21: =IF(COUNTIF($X$2:X1006,INT(A21))=1,VLOOKUP(INT(A21),X:Y,2), IF(ISERROR(H21-2),"",I20*(1-$D$8*(H21-H20)*0.0001))) -> 258.2086 | J21: =IF(ISERROR(H21-2),"",I21) -> 258.2086 | K21: =IF(ISERROR(H21-2),"",(J21/$J$14-1)*$D$5) -> -422685.97 | M21: =IF(ISERROR(B21-2),"",C21+D21-F21-G21-K21+SUM($L$14:L21)) -> -243987.99 | O21: 46126.625 | P21: 309.9 | Q21: 46072.625 | R21: 100.789 | S21: 46072.625 | T21: 249.529 | U21: =IF(COUNTIF(Q:Q,O21)*COUNTIF(S:S,O21),O21,"") -> 46126.625 | V21: =IF(U21>$A$14,U21,"") -> 46126.625 | W21: 46127.625 | X21: 46069 | Y21: 263.7609 | Z21: 45806 | AA21: 236.8452 | AB21: 45806 | AC21: 300.02 | AD21: =IF(COUNTIF(AB:AB,Z21),Z21,"") -> 45806
A22: =IF(AND(ISBLANK(W11), A21 = $W$1),NOW(),IF(ISBLANK(W11),"",W11)) -> 46107.625 | B22: =IF(COUNTIF($W$2:W1007,A22)=1,VLOOKUP(A22,O:P,2), IF(COUNTIF($W$2:W1007,A22)=0,$B$9,"")) -> 304.82 | C22: =IF(ISERROR(B22-2),"",(B22-$B$14)*$G$3*$I$3) -> -854664 | E22: =IF(COUNTIF($W$2:W1007,A22)=1,VLOOKUP(A22,Q:R,2), IF(COUNTIF($W$2:W1007,A22)=0,$C$9,"")) -> 99.313 | F22: =IF(ISERROR(B22-2),"",(E22-$E$14)/100*$C$5) -> -112840 | G22: =IF(ISERROR(B22-2),"",(INT(A22)-INT($A$14))/360*$C$6*$C$5-(INT(A22)-INT($A$14))/360*$C$7*$C$5*$E$14/100) -> 254.34933 | H22: =IF(COUNTIF($W$2:W1007,A22)=1,VLOOKUP(A22,S:T,2), IF(COUNTIF($W$2:W1007,A22)=0,$D$9,"")) -> 344.472 | I22: =IF(COUNTIF($X$2:X1007,INT(A22))=1,VLOOKUP(INT(A22),X:Y,2), IF(ISERROR(H22-2),"",I21*(1-$D$8*(H22-H21)*0.0001))) -> 255.9935 | J22: =IF(ISERROR(H22-2),"",I22) -> 255.9935 | K22: =IF(ISERROR(H22-2),"",(J22/$J$14-1)*$D$5) -> -579481.98 | M22: =IF(ISERROR(B22-2),"",C22+D22-F22-G22-K22+SUM($L$14:L22)) -> -162596.37 | O22: 46127.625 | P22: 310.42 | Q22: 46073.625 | R22: 100.775 | S22: 46073.625 | T22: 246.545 | U22: =IF(COUNTIF(Q:Q,O22)*COUNTIF(S:S,O22),O22,"") -> 46127.625 | V22: =IF(U22>$A$14,U22,"") -> 46127.625 | W22: 46128.625 | X22: 46070 | Y22: 263.6029 | Z22: 45807 | AA22: 236.7066 | AB22: 45807 | AC22: 300.049 | AD22: =IF(COUNTIF(AB:AB,Z22),Z22,"") -> 45807
A23: =IF(AND(ISBLANK(W12), A22 = $W$1),NOW(),IF(ISBLANK(W12),"",W12)) -> 46108.625 | B23: =IF(COUNTIF($W$2:W1008,A23)=1,VLOOKUP(A23,O:P,2), IF(COUNTIF($W$2:W1008,A23)=0,$B$9,"")) -> 303.5 | C23: =IF(ISERROR(B23-2),"",(B23-$B$14)*$G$3*$I$3) -> -980856 | E23: =IF(COUNTIF($W$2:W1008,A23)=1,VLOOKUP(A23,Q:R,2), IF(COUNTIF($W$2:W1008,A23)=0,$C$9,"")) -> 99.304 | F23: =IF(ISERROR(B23-2),"",(E23-$E$14)/100*$C$5) -> -115180 | G23: =IF(ISERROR(B23-2),"",(INT(A23)-INT($A$14))/360*$C$6*$C$5-(INT(A23)-INT($A$14))/360*$C$7*$C$5*$E$14/100) -> 258.73467 | H23: =IF(COUNTIF($W$2:W1008,A23)=1,VLOOKUP(A23,S:T,2), IF(COUNTIF($W$2:W1008,A23)=0,$D$9,"")) -> 361.33 | I23: =IF(COUNTIF($X$2:X1008,INT(A23))=1,VLOOKUP(INT(A23),X:Y,2), IF(ISERROR(H23-2),"",I22*(1-$D$8*(H23-H22)*0.0001))) -> 254.5716 | J23: =IF(ISERROR(H23-2),"",I23) -> 254.5716 | K23: =IF(ISERROR(H23-2),"",(J23/$J$14-1)*$D$5) -> -680131.27 | M23: =IF(ISERROR(B23-2),"",C23+D23-F23-G23-K23+SUM($L$14:L23)) -> -185803.46 | O23: 46128.625 | P23: 310.64 | Q23: 46076.625 | R23: 100.827 | S23: 46076.625 | T23: 249.638 | U23: =IF(COUNTIF(Q:Q,O23)*COUNTIF(S:S,O23),O23,"") -> 46128.625 | V23: =IF(U23>$A$14,U23,"") -> 46128.625 | W23: 46129.625 | X23: 46071 | Y23: 264.2651 | Z23: 45810 | AA23: 236.8003 | AB23: 45810 | AC23: 299.909 | AD23: =IF(COUNTIF(AB:AB,Z23),Z23,"") -> 45810
A24: =IF(AND(ISBLANK(W13), A23 = $W$1),NOW(),IF(ISBLANK(W13),"",W13)) -> 46111.625 | B24: =IF(COUNTIF($W$2:W1009,A24)=1,VLOOKUP(A24,O:P,2), IF(COUNTIF($W$2:W1009,A24)=0,$B$9,"")) -> 302.92 | C24: =IF(ISERROR(B24-2),"",(B24-$B$14)*$G$3*$I$3) -> -1036304 | E24: =IF(COUNTIF($W$2:W1009,A24)=1,VLOOKUP(A24,Q:R,2), IF(COUNTIF($W$2:W1009,A24)=0,$C$9,"")) -> 99.467 | F24: =IF(ISERROR(B24-2),"",(E24-$E$14)/100*$C$5) -> -72800 | G24: =IF(ISERROR(B24-2),"",(INT(A24)-INT($A$14))/360*$C$6*$C$5-(INT(A24)-INT($A$14))/360*$C$7*$C$5*$E$14/100) -> 271.89067 | H24: =IF(COUNTIF($W$2:W1009,A24)=1,VLOOKUP(A24,S:T,2), IF(COUNTIF($W$2:W1009,A24)=0,$D$9,"")) -> 364.034 | I24: =IF(COUNTIF($X$2:X1009,INT(A24))=1,VLOOKUP(INT(A24),X:Y,2), IF(ISERROR(H24-2),"",I23*(1-$D$8*(H24-H23)*0.0001))) -> 254.6893 | J24: =IF(ISERROR(H24-2),"",I24) -> 254.6893 | K24: =IF(ISERROR(H24-2),"",(J24/$J$14-1)*$D$5) -> -671799.87 | M24: =IF(ISERROR(B24-2),"",C24+D24-F24-G24-K24+SUM($L$14:L24)) -> -291976.02 | O24: 46129.625 | P24: 312.38 | Q24: 46077.625 | R24: 100.815 | S24: 46077.625 | T24: 252.336 | U24: =IF(COUNTIF(Q:Q,O24)*COUNTIF(S:S,O24),O24,"") -> 46129.625 | V24: =IF(U24>$A$14,U24,"") -> 46129.625 | W24: 46132.625 | X24: 46072 | Y24: 263.7488 | Z24: 45811 | AA24: 237.2446 | AB24: 45811 | AC24: 295.498 | AD24: =IF(COUNTIF(AB:AB,Z24),Z24,"") -> 45811
A25: =IF(AND(ISBLANK(W14), A24 = $W$1),NOW(),IF(ISBLANK(W14),"",W14)) -> 46112.625 | B25: =IF(COUNTIF($W$2:W1010,A25)=1,VLOOKUP(A25,O:P,2), IF(COUNTIF($W$2:W1010,A25)=0,$B$9,"")) -> 304.16 | C25: =IF(ISERROR(B25-2),"",(B25-$B$14)*$G$3*$I$3) -> -917760 | E25: =IF(COUNTIF($W$2:W1010,A25)=1,VLOOKUP(A25,Q:R,2), IF(COUNTIF($W$2:W1010,A25)=0,$C$9,"")) -> 99.444 | F25: =IF(ISERROR(B25-2),"",(E25-$E$14)/100*$C$5) -> -78780 | G25: =IF(ISERROR(B25-2),"",(INT(A25)-INT($A$14))/360*$C$6*$C$5-(INT(A25)-INT($A$14))/360*$C$7*$C$5*$E$14/100) -> 276.276 | H25: =IF(COUNTIF($W$2:W1010,A25)=1,VLOOKUP(A25,S:T,2), IF(COUNTIF($W$2:W1010,A25)=0,$D$9,"")) -> 355.63 | I25: =IF(COUNTIF($X$2:X1010,INT(A25))=1,VLOOKUP(INT(A25),X:Y,2), IF(ISERROR(H25-2),"",I24*(1-$D$8*(H25-H24)*0.0001))) -> 255.8124 | J25: =IF(ISERROR(H25-2),"",I25) -> 255.8124 | K25: =IF(ISERROR(H25-2),"",(J25/$J$14-1)*$D$5) -> -592301.16 | M25: =IF(ISERROR(B25-2),"",C25+D25-F25-G25-K25+SUM($L$14:L25)) -> -246955.12 | O25: 46132.625 | P25: 311.66 | Q25: 46078.625 | R25: 100.824 | S25: 46078.625 | T25: 251.272 | U25: =IF(COUNTIF(Q:Q,O25)*COUNTIF(S:S,O25),O25,"") -> 46132.625 | V25: =IF(U25>$A$14,U25,"") -> 46132.625 | W25: 46133.625 | X25: 46073 | Y25: 264.066 | Z25: 45812 | AA25: 237.5259 | AB25: 45812 | AC25: 294.682 | AD25: =IF(COUNTIF(AB:AB,Z25),Z25,"") -> 45812
A26: =IF(AND(ISBLANK(W15), A25 = $W$1),NOW(),IF(ISBLANK(W15),"",W15)) -> 46113.625 | B26: =IF(COUNTIF($W$2:W1011,A26)=1,VLOOKUP(A26,O:P,2), IF(COUNTIF($W$2:W1011,A26)=0,$B$9,"")) -> 306.24 | C26: =IF(ISERROR(B26-2),"",(B26-$B$14)*$G$3*$I$3) -> -718912 | E26: =IF(COUNTIF($W$2:W1011,A26)=1,VLOOKUP(A26,Q:R,2), IF(COUNTIF($W$2:W1011,A26)=0,$C$9,"")) -> 99.511 | F26: =IF(ISERROR(B26-2),"",(E26-$E$14)/100*$C$5) -> -61360 | G26: =IF(ISERROR(B26-2),"",(INT(A26)-INT($A$14))/360*$C$6*$C$5-(INT(A26)-INT($A$14))/360*$C$7*$C$5*$E$14/100) -> 280.66133 | H26: =IF(COUNTIF($W$2:W1011,A26)=1,VLOOKUP(A26,S:T,2), IF(COUNTIF($W$2:W1011,A26)=0,$D$9,"")) -> 329.106 | I26: =IF(COUNTIF($X$2:X1011,INT(A26))=1,VLOOKUP(INT(A26),X:Y,2), IF(ISERROR(H26-2),"",I25*(1-$D$8*(H26-H25)*0.0001))) -> 258.7911 | J26: =IF(ISERROR(H26-2),"",I26) -> 258.7911 | K26: =IF(ISERROR(H26-2),"",(J26/$J$14-1)*$D$5) -> -381453.67 | M26: =IF(ISERROR(B26-2),"",C26+D26-F26-G26-K26+SUM($L$14:L26)) -> -276378.99 | O26: 46133.625 | P26: 311.4 | Q26: 46079.625 | R26: 100.834 | S26: 46079.625 | T26: 252.992 | U26: =IF(COUNTIF(Q:Q,O26)*COUNTIF(S:S,O26),O26,"") -> 46133.625 | V26: =IF(U26>$A$14,U26,"") -> 46133.625 | W26: 46134.625 | X26: 46076 | Y26: 263.8705 | Z26: 45813 | AA26: 237.5851 | AB26: 45813 | AC26: 292.914 | AD26: =IF(COUNTIF(AB:AB,Z26),Z26,"") -> 45813
... A52: =IF(AND(ISBLANK(W41), A51 = $W$1),NOW(),IF(ISBLANK(W41),"",W41)) -> 46163.625 | B52: =IF(COUNTIF($W$2:W1037,A52)=1,VLOOKUP(A52,O:P,2), IF(COUNTIF($W$2:W1037,A52)=0,$B$9,"")) -> 311.18 | C52: =IF(ISERROR(B52-2),"",(B52-$B$14)*$G$3*$I$3) -> -246648 | E52: =IF(COUNTIF($W$2:W1037,A52)=1,VLOOKUP(A52,Q:R,2), IF(COUNTIF($W$2:W1037,A52)=0,$C$9,"")) -> 99.37 | F52: =IF(ISERROR(B52-2),"",(E52-$E$14)/100*$C$5) -> -98020 | G52: =IF(ISERROR(B52-2),"",(INT(A52)-INT($A$14))/360*$C$6*$C$5-(INT(A52)-INT($A$14))/360*$C$7*$C$5*$E$14/100) -> 499.928 | H52: =IF(COUNTIF($W$2:W1037,A52)=1,VLOOKUP(A52,S:T,2), IF(COUNTIF($W$2:W1037,A52)=0,$D$9,"")) -> 279.541 | I52: =IF(COUNTIF($X$2:X1037,INT(A52))=1,VLOOKUP(INT(A52),X:Y,2), IF(ISERROR(H52-2),"",I51*(1-$D$8*(H52-H51)*0.0001))) -> 265.8161 | J52: =IF(ISERROR(H52-2),"",I52) -> 265.8161 | K52: =IF(ISERROR(H52-2),"",(J52/$J$14-1)*$D$5) -> 115811.45 | M52: =IF(ISERROR(B52-2),"",C52+D52-F52-G52-K52+SUM($L$14:L52)) -> -264939.38 | O52: 46182.625 | P52: 313.3 | Q52: 46119.625 | R52: 99.213 | S52: 46119.625 | T52: 333.967 | U52: =IF(COUNTIF(Q:Q,O52)*COUNTIF(S:S,O52),O52,"") -> 46182.625 | V52: =IF(U52>$A$14,U52,"") -> 46182.625 | W52: 46190.625 | X52: 46112 | Y52: 255.8124 | Z52: 45849 | AA52: 239.6415 | AB52: 45849 | AC52: 281.735 | AD52: =IF(COUNTIF(AB:AB,Z52),Z52,"") -> 45849
A53: =IF(AND(ISBLANK(W42), A52 = $W$1),NOW(),IF(ISBLANK(W42),"",W42)) -> 46168.625 | B53: =IF(COUNTIF($W$2:W1038,A53)=1,VLOOKUP(A53,O:P,2), IF(COUNTIF($W$2:W1038,A53)=0,$B$9,"")) -> 312.5 | C53: =IF(ISERROR(B53-2),"",(B53-$B$14)*$G$3*$I$3) -> -120456 | E53: =IF(COUNTIF($W$2:W1038,A53)=1,VLOOKUP(A53,Q:R,2), IF(COUNTIF($W$2:W1038,A53)=0,$C$9,"")) -> 99.56 | F53: =IF(ISERROR(B53-2),"",(E53-$E$14)/100*$C$5) -> -48620 | G53: =IF(ISERROR(B53-2),"",(INT(A53)-INT($A$14))/360*$C$6*$C$5-(INT(A53)-INT($A$14))/360*$C$7*$C$5*$E$14/100) -> 521.85467 | H53: =IF(COUNTIF($W$2:W1038,A53)=1,VLOOKUP(A53,S:T,2), IF(COUNTIF($W$2:W1038,A53)=0,$D$9,"")) -> 268.835 | I53: =IF(COUNTIF($X$2:X1038,INT(A53))=1,VLOOKUP(INT(A53),X:Y,2), IF(ISERROR(H53-2),"",I52*(1-$D$8*(H53-H52)*0.0001))) -> 267.4075 | J53: =IF(ISERROR(H53-2),"",I53) -> 267.4075 | K53: =IF(ISERROR(H53-2),"",(J53/$J$14-1)*$D$5) -> 228458.82 | M53: =IF(ISERROR(B53-2),"",C53+D53-F53-G53-K53+SUM($L$14:L53)) -> -300816.67 | O53: 46188.625 | P53: 314.28 | Q53: 46120.625 | R53: 99.777 | S53: 46120.625 | T53: 301.619 | U53: =IF(COUNTIF(Q:Q,O53)*COUNTIF(S:S,O53),O53,"") -> 46188.625 | V53: =IF(U53>$A$14,U53,"") -> 46188.625 | X53: 46113 | Y53: 258.7911 | Z53: 45852 | AA53: 239.5692 | AB53: 45852 | AC53: 282.806 | AD53: =IF(COUNTIF(AB:AB,Z53),Z53,"") -> 45852
A54: =IF(AND(ISBLANK(W43), A53 = $W$1),NOW(),IF(ISBLANK(W43),"",W43)) -> 46169.625 | B54: =IF(COUNTIF($W$2:W1039,A54)=1,VLOOKUP(A54,O:P,2), IF(COUNTIF($W$2:W1039,A54)=0,$B$9,"")) -> 312.84 | C54: =IF(ISERROR(B54-2),"",(B54-$B$14)*$G$3*$I$3) -> -87952 | E54: =IF(COUNTIF($W$2:W1039,A54)=1,VLOOKUP(A54,Q:R,2), IF(COUNTIF($W$2:W1039,A54)=0,$C$9,"")) -> 99.589 | F54: =IF(ISERROR(B54-2),"",(E54-$E$14)/100*$C$5) -> -41080 | G54: =IF(ISERROR(B54-2),"",(INT(A54)-INT($A$14))/360*$C$6*$C$5-(INT(A54)-INT($A$14))/360*$C$7*$C$5*$E$14/100) -> 526.24 | H54: =IF(COUNTIF($W$2:W1039,A54)=1,VLOOKUP(A54,S:T,2), IF(COUNTIF($W$2:W1039,A54)=0,$D$9,"")) -> 266.559 | I54: =IF(COUNTIF($X$2:X1039,INT(A54))=1,VLOOKUP(INT(A54),X:Y,2), IF(ISERROR(H54-2),"",I53*(1-$D$8*(H54-H53)*0.0001))) -> 267.6639 | J54: =IF(ISERROR(H54-2),"",I54) -> 267.6639 | K54: =IF(ISERROR(H54-2),"",(J54/$J$14-1)*$D$5) -> 246608.11 | M54: =IF(ISERROR(B54-2),"",C54+D54-F54-G54-K54+SUM($L$14:L54)) -> -294006.35 | O54: 46189.625 | P54: 314.16 | Q54: 46121.625 | R54: 99.577 | S54: 46121.625 | T54: 299.792 | U54: =IF(COUNTIF(Q:Q,O54)*COUNTIF(S:S,O54),O54,"") -> 46189.625 | V54: =IF(U54>$A$14,U54,"") -> 46189.625 | X54: 46114 | Y54: 259.0143 | Z54: 45853 | AA54: 239.5731 | AB54: 45853 | AC54: 282.986 | AD54: =IF(COUNTIF(AB:AB,Z54),Z54,"") -> 45853
A55: =IF(AND(ISBLANK(W44), A54 = $W$1),NOW(),IF(ISBLANK(W44),"",W44)) -> 46170.625 | B55: =IF(COUNTIF($W$2:W1040,A55)=1,VLOOKUP(A55,O:P,2), IF(COUNTIF($W$2:W1040,A55)=0,$B$9,"")) -> 312.7 | C55: =IF(ISERROR(B55-2),"",(B55-$B$14)*$G$3*$I$3) -> -101336 | E55: =IF(COUNTIF($W$2:W1040,A55)=1,VLOOKUP(A55,Q:R,2), IF(COUNTIF($W$2:W1040,A55)=0,$C$9,"")) -> 99.654 | F55: =IF(ISERROR(B55-2),"",(E55-$E$14)/100*$C$5) -> -24180 | G55: =IF(ISERROR(B55-2),"",(INT(A55)-INT($A$14))/360*$C$6*$C$5-(INT(A55)-INT($A$14))/360*$C$7*$C$5*$E$14/100) -> 530.62533 | H55: =IF(COUNTIF($W$2:W1040,A55)=1,VLOOKUP(A55,S:T,2), IF(COUNTIF($W$2:W1040,A55)=0,$D$9,"")) -> 264.232 | I55: =IF(COUNTIF($X$2:X1040,INT(A55))=1,VLOOKUP(INT(A55),X:Y,2), IF(ISERROR(H55-2),"",I54*(1-$D$8*(H55-H54)*0.0001))) -> 268.2162 | J55: =IF(ISERROR(H55-2),"",I55) -> 268.2162 | K55: =IF(ISERROR(H55-2),"",(J55/$J$14-1)*$D$5) -> 285702.7 | M55: =IF(ISERROR(B55-2),"",C55+D55-F55-G55-K55+SUM($L$14:L55)) -> -363389.33 | O55: 46190.625 | P55: 313.66 | Q55: 46122.625 | R55: 99.55 | S55: 46122.625 | T55: 291.343 | U55: =IF(COUNTIF(Q:Q,O55)*COUNTIF(S:S,O55),O55,"") -> 46190.625 | V55: =IF(U55>$A$14,U55,"") -> 46190.625 | X55: 46119 | Y55: 258.062 | Z55: 45854 | AA55: 239.2413 | AB55: 45854 | AC55: 285.261 | AD55: =IF(COUNTIF(AB:AB,Z55),Z55,"") -> 45854
A56: =IF(AND(ISBLANK(W45), A55 = $W$1),NOW(),IF(ISBLANK(W45),"",W45)) -> 46171.625 | B56: =IF(COUNTIF($W$2:W1041,A56)=1,VLOOKUP(A56,O:P,2), IF(COUNTIF($W$2:W1041,A56)=0,$B$9,"")) -> 313.78 | C56: =IF(ISERROR(B56-2),"",(B56-$B$14)*$G$3*$I$3) -> 1912 | E56: =IF(COUNTIF($W$2:W1041,A56)=1,VLOOKUP(A56,Q:R,2), IF(COUNTIF($W$2:W1041,A56)=0,$C$9,"")) -> 99.679 | F56: =IF(ISERROR(B56-2),"",(E56-$E$14)/100*$C$5) -> -17680 | G56: =IF(ISERROR(B56-2),"",(INT(A56)-INT($A$14))/360*$C$6*$C$5-(INT(A56)-INT($A$14))/360*$C$7*$C$5*$E$14/100) -> 535.01067 | H56: =IF(COUNTIF($W$2:W1041,A56)=1,VLOOKUP(A56,S:T,2), IF(COUNTIF($W$2:W1041,A56)=0,$D$9,"")) -> 258.706 | I56: =IF(COUNTIF($X$2:X1041,INT(A56))=1,VLOOKUP(INT(A56),X:Y,2), IF(ISERROR(H56-2),"",I55*(1-$D$8*(H56-H55)*0.0001))) -> 268.7623 | J56: =IF(ISERROR(H56-2),"",I56) -> 268.7623 | K56: =IF(ISERROR(H56-2),"",(J56/$J$14-1)*$D$5) -> 324358.43 | M56: =IF(ISERROR(B56-2),"",C56+D56-F56-G56-K56+SUM($L$14:L56)) -> -305301.44 | Q56: 46125.625 | R56: 99.418 | S56: 46125.625 | T56: 294.253 | U56: =IF(COUNTIF(Q:Q,O56)*COUNTIF(S:S,O56),O56,"") | V56: =IF(U56>$A$14,U56,"") | X56: 46120 | Y56: 262.3835 | Z56: 45855 | AA56: 240.1303 | AB56: 45855 | AC56: 278.768 | AD56: =IF(COUNTIF(AB:AB,Z56),Z56,"") -> 45855
A57: =IF(AND(ISBLANK(W46), A56 = $W$1),NOW(),IF(ISBLANK(W46),"",W46)) -> 46174.625 | B57: =IF(COUNTIF($W$2:W1042,A57)=1,VLOOKUP(A57,O:P,2), IF(COUNTIF($W$2:W1042,A57)=0,$B$9,"")) -> 312.84 | C57: =IF(ISERROR(B57-2),"",(B57-$B$14)*$G$3*$I$3) -> -87952 | E57: =IF(COUNTIF($W$2:W1042,A57)=1,VLOOKUP(A57,Q:R,2), IF(COUNTIF($W$2:W1042,A57)=0,$C$9,"")) -> 99.451 | F57: =IF(ISERROR(B57-2),"",(E57-$E$14)/100*$C$5) -> -76960 | G57: =IF(ISERROR(B57-2),"",(INT(A57)-INT($A$14))/360*$C$6*$C$5-(INT(A57)-INT($A$14))/360*$C$7*$C$5*$E$14/100) -> 548.16667 | H57: =IF(COUNTIF($W$2:W1042,A57)=1,VLOOKUP(A57,S:T,2), IF(COUNTIF($W$2:W1042,A57)=0,$D$9,"")) -> 265.436 | I57: =IF(COUNTIF($X$2:X1042,INT(A57))=1,VLOOKUP(INT(A57),X:Y,2), IF(ISERROR(H57-2),"",I56*(1-$D$8*(H57-H56)*0.0001))) -> 268.3984 | J57: =IF(ISERROR(H57-2),"",I57) -> 268.3984 | K57: =IF(ISERROR(H57-2),"",(J57/$J$14-1)*$D$5) -> 298599.74 | M57: =IF(ISERROR(B57-2),"",C57+D57-F57-G57-K57+SUM($L$14:L57)) -> -310139.91 | Q57: 46126.625 | R57: 99.619 | S57: 46126.625 | T57: 282.697 | U57: =IF(COUNTIF(Q:Q,O57)*COUNTIF(S:S,O57),O57,"") | V57: =IF(U57>$A$14,U57,"") | X57: 46121 | Y57: 263.2626 | Z57: 45856 | AA57: 240.3284 | AB57: 45856 | AC57: 277.186 | AD57: =IF(COUNTIF(AB:AB,Z57),Z57,"") -> 45856
A58: =IF(AND(ISBLANK(W47), A57 = $W$1),NOW(),IF(ISBLANK(W47),"",W47)) -> 46176.625 | B58: =IF(COUNTIF($W$2:W1043,A58)=1,VLOOKUP(A58,O:P,2), IF(COUNTIF($W$2:W1043,A58)=0,$B$9,"")) -> 313.08 | C58: =IF(ISERROR(B58-2),"",(B58-$B$14)*$G$3*$I$3) -> -65008 | E58: =IF(COUNTIF($W$2:W1043,A58)=1,VLOOKUP(A58,Q:R,2), IF(COUNTIF($W$2:W1043,A58)=0,$C$9,"")) -> 99.422 | F58: =IF(ISERROR(B58-2),"",(E58-$E$14)/100*$C$5) -> -84500 | G58: =IF(ISERROR(B58-2),"",(INT(A58)-INT($A$14))/360*$C$6*$C$5-(INT(A58)-INT($A$14))/360*$C$7*$C$5*$E$14/100) -> 556.93733 | H58: =IF(COUNTIF($W$2:W1043,A58)=1,VLOOKUP(A58,S:T,2), IF(COUNTIF($W$2:W1043,A58)=0,$D$9,"")) -> 261.796 | I58: =IF(COUNTIF($X$2:X1043,INT(A58))=1,VLOOKUP(INT(A58),X:Y,2), IF(ISERROR(H58-2),"",I57*(1-$D$8*(H58-H57)*0.0001))) -> 268.4079 | J58: =IF(ISERROR(H58-2),"",I58) -> 268.4079 | K58: =IF(ISERROR(H58-2),"",(J58/$J$14-1)*$D$5) -> 299272.2 | M58: =IF(ISERROR(B58-2),"",C58+D58-F58-G58-K58+SUM($L$14:L58)) -> -280337.14 | Q58: 46127.625 | R58: 99.654 | S58: 46127.625 | T58: 282.519 | U58: =IF(COUNTIF(Q:Q,O58)*COUNTIF(S:S,O58),O58,"") | V58: =IF(U58>$A$14,U58,"") | X58: 46122 | Y58: 263.2931 | Z58: 45859 | AA58: 240.3394 | AB58: 45859 | AC58: 277.458 | AD58: =IF(COUNTIF(AB:AB,Z58),Z58,"") -> 45859
A59: =IF(AND(ISBLANK(W48), A58 = $W$1),NOW(),IF(ISBLANK(W48),"",W48)) -> 46177.625 | B59: =IF(COUNTIF($W$2:W1044,A59)=1,VLOOKUP(A59,O:P,2), IF(COUNTIF($W$2:W1044,A59)=0,$B$9,"")) -> 313.04 | C59: =IF(ISERROR(B59-2),"",(B59-$B$14)*$G$3*$I$3) -> -68832 | E59: =IF(COUNTIF($W$2:W1044,A59)=1,VLOOKUP(A59,Q:R,2), IF(COUNTIF($W$2:W1044,A59)=0,$C$9,"")) -> 99.431 | F59: =IF(ISERROR(B59-2),"",(E59-$E$14)/100*$C$5) -> -82160 | G59: =IF(ISERROR(B59-2),"",(INT(A59)-INT($A$14))/360*$C$6*$C$5-(INT(A59)-INT($A$14))/360*$C$7*$C$5*$E$14/100) -> 561.32267 | H59: =IF(COUNTIF($W$2:W1044,A59)=1,VLOOKUP(A59,S:T,2), IF(COUNTIF($W$2:W1044,A59)=0,$D$9,"")) -> 261.392 | I59: =IF(COUNTIF($X$2:X1044,INT(A59))=1,VLOOKUP(INT(A59),X:Y,2), IF(ISERROR(H59-2),"",I58*(1-$D$8*(H59-H58)*0.0001))) -> 268.6451 | J59: =IF(ISERROR(H59-2),"",I59) -> 268.6451 | K59: =IF(ISERROR(H59-2),"",(J59/$J$14-1)*$D$5) -> 316062.42 | M59: =IF(ISERROR(B59-2),"",C59+D59-F59-G59-K59+SUM($L$14:L59)) -> -303295.74 | Q59: 46128.625 | R59: 99.677 | S59: 46128.625 | T59: 286.733 | U59: =IF(COUNTIF(Q:Q,O59)*COUNTIF(S:S,O59),O59,"") | V59: =IF(U59>$A$14,U59,"") | X59: 46125 | Y59: 263.0391 | Z59: 45860 | AA59: 240.1245 | AB59: 45860 | AC59: 279.557 | AD59: =IF(COUNTIF(AB:AB,Z59),Z59,"") -> 45860
A60: =IF(AND(ISBLANK(W49), A59 = $W$1),NOW(),IF(ISBLANK(W49),"",W49)) -> 46182.625 | B60: =IF(COUNTIF($W$2:W1045,A60)=1,VLOOKUP(A60,O:P,2), IF(COUNTIF($W$2:W1045,A60)=0,$B$9,"")) -> 313.3 | C60: =IF(ISERROR(B60-2),"",(B60-$B$14)*$G$3*$I$3) -> -43976 | E60: =IF(COUNTIF($W$2:W1045,A60)=1,VLOOKUP(A60,Q:R,2), IF(COUNTIF($W$2:W1045,A60)=0,$C$9,"")) -> 99.396 | F60: =IF(ISERROR(B60-2),"",(E60-$E$14)/100*$C$5) -> -91260 | G60: =IF(ISERROR(B60-2),"",(INT(A60)-INT($A$14))/360*$C$6*$C$5-(INT(A60)-INT($A$14))/360*$C$7*$C$5*$E$14/100) -> 583.24933 | H60: =IF(COUNTIF($W$2:W1045,A60)=1,VLOOKUP(A60,S:T,2), IF(COUNTIF($W$2:W1045,A60)=0,$D$9,"")) -> 261.05 | I60: =IF(COUNTIF($X$2:X1045,INT(A60))=1,VLOOKUP(INT(A60),X:Y,2), IF(ISERROR(H60-2),"",I59*(1-$D$8*(H60-H59)*0.0001))) -> 268.3329 | J60: =IF(ISERROR(H60-2),"",I60) -> 268.3329 | K60: =IF(ISERROR(H60-2),"",(J60/$J$14-1)*$D$5) -> 293963.32 | M60: =IF(ISERROR(B60-2),"",C60+D60-F60-G60-K60+SUM($L$14:L60)) -> -247262.57 | Q60: 46129.625 | R60: 99.954 | S60: 46129.625 | T60: 275.168 | U60: =IF(COUNTIF(Q:Q,O60)*COUNTIF(S:S,O60),O60,"") | V60: =IF(U60>$A$14,U60,"") | X60: 46126 | Y60: 264.6927 | Z60: 45861 | AA60: 240.6497 | AB60: 45861 | AC60: 273.141 | AD60: =IF(COUNTIF(AB:AB,Z60),Z60,"") -> 45861
A61: =IF(AND(ISBLANK(W50), A60 = $W$1),NOW(),IF(ISBLANK(W50),"",W50)) -> 46188.625 | B61: =IF(COUNTIF($W$2:W1046,A61)=1,VLOOKUP(A61,O:P,2), IF(COUNTIF($W$2:W1046,A61)=0,$B$9,"")) -> 314.28 | C61: =IF(ISERROR(B61-2),"",(B61-$B$14)*$G$3*$I$3) -> 49712 | E61: =IF(COUNTIF($W$2:W1046,A61)=1,VLOOKUP(A61,Q:R,2), IF(COUNTIF($W$2:W1046,A61)=0,$C$9,"")) -> 99.631 | F61: =IF(ISERROR(B61-2),"",(E61-$E$14)/100*$C$5) -> -30160 | G61: =IF(ISERROR(B61-2),"",(INT(A61)-INT($A$14))/360*$C$6*$C$5-(INT(A61)-INT($A$14))/360*$C$7*$C$5*$E$14/100) -> 609.56133 | H61: =IF(COUNTIF($W$2:W1046,A61)=1,VLOOKUP(A61,S:T,2), IF(COUNTIF($W$2:W1046,A61)=0,$D$9,"")) -> 248.518 | I61: =IF(COUNTIF($X$2:X1046,INT(A61))=1,VLOOKUP(INT(A61),X:Y,2), IF(ISERROR(H61-2),"",I60*(1-$D$8*(H61-H60)*0.0001))) -> 270.4706 | J61: =IF(ISERROR(H61-2),"",I61) -> 270.4706 | K61: =IF(ISERROR(H61-2),"",(J61/$J$14-1)*$D$5) -> 445280.57 | M61: =IF(ISERROR(B61-2),"",C61+D61-F61-G61-K61+SUM($L$14:L61)) -> -366018.13 | Q61: 46132.625 | R61: 99.831 | S61: 46132.625 | T61: 280.364 | U61: =IF(COUNTIF(Q:Q,O61)*COUNTIF(S:S,O61),O61,"") | V61: =IF(U61>$A$14,U61,"") | X61: 46127 | Y61: 264.629 | Z61: 45862 | AA61: 241.2562 | AB61: 45862 | AC61: 270.698 | AD61: =IF(COUNTIF(AB:AB,Z61),Z61,"") -> 45862
A62: =IF(AND(ISBLANK(W51), A61 = $W$1),NOW(),IF(ISBLANK(W51),"",W51)) -> 46189.625 | B62: =IF(COUNTIF($W$2:W1047,A62)=1,VLOOKUP(A62,O:P,2), IF(COUNTIF($W$2:W1047,A62)=0,$B$9,"")) -> 314.16 | C62: =IF(ISERROR(B62-2),"",(B62-$B$14)*$G$3*$I$3) -> 38240 | E62: =IF(COUNTIF($W$2:W1047,A62)=1,VLOOKUP(A62,Q:R,2), IF(COUNTIF($W$2:W1047,A62)=0,$C$9,"")) -> 99.625 | F62: =IF(ISERROR(B62-2),"",(E62-$E$14)/100*$C$5) -> -31720 | G62: =IF(ISERROR(B62-2),"",(INT(A62)-INT($A$14))/360*$C$6*$C$5-(INT(A62)-INT($A$14))/360*$C$7*$C$5*$E$14/100) -> 613.94667 | H62: =IF(COUNTIF($W$2:W1047,A62)=1,VLOOKUP(A62,S:T,2), IF(COUNTIF($W$2:W1047,A62)=0,$D$9,"")) -> 249.794 | I62: =IF(COUNTIF($X$2:X1047,INT(A62))=1,VLOOKUP(INT(A62),X:Y,2), IF(ISERROR(H62-2),"",I61*(1-$D$8*(H62-H61)*0.0001))) -> 270.3356 | J62: =IF(ISERROR(H62-2),"",I62) -> 270.3356 | K62: =IF(ISERROR(H62-2),"",(J62/$J$14-1)*$D$5) -> 435724.58 | M62: =IF(ISERROR(B62-2),"",C62+D62-F62-G62-K62+SUM($L$14:L62)) -> -366378.53 | Q62: 46133.625 | R62: 99.708 | S62: 46133.625 | T62: 285.448 | U62: =IF(COUNTIF(Q:Q,O62)*COUNTIF(S:S,O62),O62,"") | V62: =IF(U62>$A$14,U62,"") | X62: 46128 | Y62: 264.2442 | Z62: 45863 | AA62: 241.3281 | AB62: 45863 | AC62: 269.244 | AD62: =IF(COUNTIF(AB:AB,Z62),Z62,"") -> 45863
A63: =IF(AND(ISBLANK(W52), A62 = $W$1),NOW(),IF(ISBLANK(W52),"",W52)) -> 46190.625 | B63: =IF(COUNTIF($W$2:W1048,A63)=1,VLOOKUP(A63,O:P,2), IF(COUNTIF($W$2:W1048,A63)=0,$B$9,"")) -> 313.66 | C63: =IF(ISERROR(B63-2),"",(B63-$B$14)*$G$3*$I$3) -> -9560 | E63: =IF(COUNTIF($W$2:W1048,A63)=1,VLOOKUP(A63,Q:R,2), IF(COUNTIF($W$2:W1048,A63)=0,$C$9,"")) -> 99.601 | F63: =IF(ISERROR(B63-2),"",(E63-$E$14)/100*$C$5) -> -37960 | G63: =IF(ISERROR(B63-2),"",(INT(A63)-INT($A$14))/360*$C$6*$C$5-(INT(A63)-INT($A$14))/360*$C$7*$C$5*$E$14/100) -> 618.332 | H63: =IF(COUNTIF($W$2:W1048,A63)=1,VLOOKUP(A63,S:T,2), IF(COUNTIF($W$2:W1048,A63)=0,$D$9,"")) -> 252.459 | I63: =IF(COUNTIF($X$2:X1048,INT(A63))=1,VLOOKUP(INT(A63),X:Y,2), IF(ISERROR(H63-2),"",I62*(1-$D$8*(H63-H62)*0.0001))) -> 270.1644 | J63: =IF(ISERROR(H63-2),"",I63) -> 270.1644 | K63: =IF(ISERROR(H63-2),"",(J63/$J$14-1)*$D$5) -> 423606.18 | M63: =IF(ISERROR(B63-2),"",C63+D63-F63-G63-K63+SUM($L$14:L63)) -> -395824.51 | Q63: 46134.625 | R63: 99.655 | S63: 46134.625 | T63: 285.535 | U63: =IF(COUNTIF(Q:Q,O63)*COUNTIF(S:S,O63),O63,"") | V63: =IF(U63>$A$14,U63,"") | X63: 46129 | Y63: 265.6018 | Z63: 45866 | AA63: 241.5315 | AB63: 45866 | AC63: 267.811 | AD63: =IF(COUNTIF(AB:AB,Z63),Z63,"") -> 45866
A64: =IF(AND(ISBLANK(W53), A63 = $W$1),NOW(),IF(ISBLANK(W53),"",W53)) -> 46198.782 | B64: =IF(COUNTIF($W$2:W1049,A64)=1,VLOOKUP(A64,O:P,2), IF(COUNTIF($W$2:W1049,A64)=0,$B$9,"")) -> 313.66 | C64: =IF(ISERROR(B64-2),"",(B64-$B$14)*$G$3*$I$3) -> -9560 | E64: =IF(COUNTIF($W$2:W1049,A64)=1,VLOOKUP(A64,Q:R,2), IF(COUNTIF($W$2:W1049,A64)=0,$C$9,"")) -> 99.747 | F64: =IF(ISERROR(B64-2),"",(E64-$E$14)/100*$C$5) -> 0 | G64: =IF(ISERROR(B64-2),"",(INT(A64)-INT($A$14))/360*$C$6*$C$5-(INT(A64)-INT($A$14))/360*$C$7*$C$5*$E$14/100) -> 653.41467 | H64: =IF(COUNTIF($W$2:W1049,A64)=1,VLOOKUP(A64,S:T,2), IF(COUNTIF($W$2:W1049,A64)=0,$D$9,"")) -> 247.3067 | I64: =IF(COUNTIF($X$2:X1049,INT(A64))=1,VLOOKUP(INT(A64),X:Y,2), IF(ISERROR(H64-2),"",I63*(1-$D$8*(H64-H63)*0.0001))) -> 270.9793 | J64: =IF(ISERROR(H64-2),"",I64) -> 270.9793 | K64: =IF(ISERROR(H64-2),"",(J64/$J$14-1)*$D$5) -> 481288.93 | M64: =IF(ISERROR(B64-2),"",C64+D64-F64-G64-K64+SUM($L$14:L64)) -> -491502.35 | Q64: 46135.625 | R64: 99.627 | S64: 46135.625 | T64: 284.408 | U64: =IF(COUNTIF(Q:Q,O64)*COUNTIF(S:S,O64),O64,"") | V64: =IF(U64>$A$14,U64,"") | X64: 46132 | Y64: 265.2414 | Z64: 45867 | AA64: 241.9485 | AB64: 45867 | AC64: 264.292 | AD64: =IF(COUNTIF(AB:AB,Z64),Z64,"") -> 45867
A65: =IF(AND(ISBLANK(W54), A64 = $W$1),NOW(),IF(ISBLANK(W54),"",W54)) | B65: =IF(COUNTIF($W$2:W1050,A65)=1,VLOOKUP(A65,O:P,2), IF(COUNTIF($W$2:W1050,A65)=0,$B$9,"")) | C65: =IF(ISERROR(B65-2),"",(B65-$B$14)*$G$3*$I$3) | E65: =IF(COUNTIF($W$2:W1050,A65)=1,VLOOKUP(A65,Q:R,2), IF(COUNTIF($W$2:W1050,A65)=0,$C$9,"")) | F65: =IF(ISERROR(B65-2),"",(E65-$E$14)/100*$C$5) | G65: =IF(ISERROR(B65-2),"",(INT(A65)-INT($A$14))/360*$C$6*$C$5-(INT(A65)-INT($A$14))/360*$C$7*$C$5*$E$14/100) | H65: =IF(COUNTIF($W$2:W1050,A65)=1,VLOOKUP(A65,S:T,2), IF(COUNTIF($W$2:W1050,A65)=0,$D$9,"")) | I65: =IF(COUNTIF($X$2:X1050,INT(A65))=1,VLOOKUP(INT(A65),X:Y,2), IF(ISERROR(H65-2),"",I64*(1-$D$8*(H65-H64)*0.0001))) | J65: =IF(ISERROR(H65-2),"",I65) | K65: =IF(ISERROR(H65-2),"",(J65/$J$14-1)*$D$5) | M65: =IF(ISERROR(B65-2),"",C65+D65-F65-G65-K65+SUM($L$14:L65)) | Q65: 46136.625 | R65: 99.637 | S65: 46136.625 | T65: 288.863 | U65: =IF(COUNTIF(Q:Q,O65)*COUNTIF(S:S,O65),O65,"") | V65: =IF(U65>$A$14,U65,"") | X65: 46133 | Y65: 264.6036 | Z65: 45868 | AA65: 241.7086 | AB65: 45868 | AC65: 266.432 | AD65: =IF(COUNTIF(AB:AB,Z65),Z65,"") -> 45868
...

Sheet 13
D1: ERIXITXO INDEX | W1: {=LOOKUP(2,1/(W:W<>""),W:W)} -> 46198.625 | AE1: Last ER Date = | AF1: {=LOOKUP(2,1/(AD:AD<>""),AD:AD)} -> 46198
B2: Long Risk | C2: Short Risk | D2: Short Risk | G2: IHYG Units | H2: =B5/B14 -> 320034.14 | O2: Long Risk | Q2: Short Risk | S2: Short Risk | W2: {=_xlfn.UNIQUE(V:V)} -> 0 | AE2: Last CDX = | AF2: =VLOOKUP(AF1,AB:AC,2) -> 247.307
A3: Name= | B3: IHYG | C3: OBL 2.4% 10/28 | D3: Xover S44 | H3: Dvd | O3: {=_xll.BDH(B4, "LAST_PRICE", "01/26/2026 15:00:00", "01/26/2035 16:00:00", "BarSize=60", "BarType=T", "RecurDaily=True", "TZ=London")} -> 46048.625 | P3: 93.62 | Q3: {=_xll.BDH(C4, "LAST_PRICE", "01/26/2026 15:00:00", "01/01/2035 16:00:00", "BarSize=60", "BarType=T", "RecurDaily=True", "TZ=London")} -> 46048.625 | R3: 100.566 | S3: {=_xll.BDH(D4, "LAST_PRICE", "01/26/2026 15:00:00", "01/01/2035 16:00:00", "BarSize=60", "BarType=T", "RecurDaily=True", "TZ=London")} -> 46048.625 | T3: 242.329 | U3: =IF(COUNTIF(Q:Q,O3)*COUNTIF(S:S,O3),O3,"") -> 46048.625 | V3: =IF(U3>$A$14,U3,"") | Z3: {=_xll.BDH(D1, "LAST_PRICE", "05/01/2025","")} -> 45778 | AA3: 231.3922 | AB3: {=_xll.BDH(D4, "LAST_PRICE", "05/01/2025", "")} -> 45778 | AC3: 343.699 | AD3: =IF(COUNTIF(AB:AB,Z3),Z3,"") -> 45778 | AE3: Last ER = | AF3: =VLOOKUP(AF1,Z:AA,2) -> 255.5413
A4: BBG Ticker= | B4: IHYG LN EQUITY | C4: ZK885444@BGN Corp | D4: ITRX XOVER CDSI GEN 5Y CORP | H4: 46100 | I4: IHYG | J4: 2.3303 | O4: 46049.625 | P4: 93.74 | Q4: 46049.625 | R4: 100.59 | S4: 46049.625 | T4: 241.372 | U4: =IF(COUNTIF(Q:Q,O4)*COUNTIF(S:S,O4),O4,"") -> 46049.625 | V4: =IF(U4>$A$14,U4,"") | W4: 46050.625 | X4: {=_xll.BDH("ERIXILXO Index", "PX_LAST", "01/22/2026", "")} -> 46044 | Y4: 264.1611 | Z4: 45779 | AA4: 232.4699 | AB4: 45779 | AC4: 333.964 | AD4: =IF(COUNTIF(AB:AB,Z4),Z4,"") -> 45779 | AE4: Carry Days = | AF4: =INT(NOW())-INT(AF1) -> 0
A5: Not'l= | B5: =30*10^6 -> 30000000 | C5: =26*10^6 -> 26000000 | D5: =18.7*10^6 -> 18700000 | O5: 46050.625 | P5: 93.63 | Q5: 46050.625 | R5: 100.65 | S5: 46050.625 | T5: 244.391 | U5: =IF(COUNTIF(Q:Q,O5)*COUNTIF(S:S,O5),O5,"") -> 46050.625 | V5: =IF(U5>$A$14,U5,"") -> 46050.625 | W5: 46051.625 | X5: 46045 | Y5: 263.9462 | Z5: 45783 | AA5: 232.7954 | AB5: 45783 | AC5: 331.257 | AD5: =IF(COUNTIF(AB:AB,Z5),Z5,"") -> 45783
A6: Carry= | B6: 0 | C6: 0.024 | D6: 0.05 | O6: 46051.625 | P6: 93.53 | Q6: 46051.625 | R6: 100.706 | S6: 46051.625 | T6: 249.25 | U6: =IF(COUNTIF(Q:Q,O6)*COUNTIF(S:S,O6),O6,"") -> 46051.625 | V6: =IF(U6>$A$14,U6,"") -> 46051.625 | W6: 46052.625 | X6: 46048 | Y6: 264.0295 | Z6: 45784 | AA6: 232.8287 | AB6: 45784 | AC6: 330.319 | AD6: =IF(COUNTIF(AB:AB,Z6),Z6,"") -> 45784
A7: Financing Rate= | B7: {=_xll.BDP("EURR002W INDEX","PX_LAST")/100+0.25/100} -> 0.0265 | C7: {=_xll.BDP("EURR002W INDEX","PX_LAST")/100} -> 0.024 | D7: 0 | O7: 46052.625 | P7: 93.62 | Q7: 46052.625 | R7: 100.675 | S7: 46052.625 | T7: 246.12 | U7: =IF(COUNTIF(Q:Q,O7)*COUNTIF(S:S,O7),O7,"") -> 46052.625 | V7: =IF(U7>$A$14,U7,"") -> 46052.625 | W7: 46055.625 | X7: 46049 | Y7: 264.1769 | Z7: 45785 | AA7: 233.9237 | AB7: 45785 | AC7: 319.942 | AD7: =IF(COUNTIF(AB:AB,Z7),Z7,"") -> 45785
A8: Initial Duration= | B8: - | C8: - | D8: 4.859 | O8: 46055.625 | P8: 93.64 | Q8: 46055.625 | R8: 100.607 | S8: 46055.625 | T8: 243.642 | U8: =IF(COUNTIF(Q:Q,O8)*COUNTIF(S:S,O8),O8,"") -> 46055.625 | V8: =IF(U8>$A$14,U8,"") -> 46055.625 | W8: 46056.625 | X8: 46050 | Y8: 263.7748 | Z8: 45786 | AA8: 233.9268 | AB8: 45786 | AC8: 320.065 | AD8: =IF(COUNTIF(AB:AB,Z8),Z8,"") -> 45786
A9: Live PX= | B9: {=_xll.BDP(B4,"PX_LAST")} -> 91.16 | C9: {=_xll.BDP(C4,"PX_LAST")} -> 99.747 | D9: {=_xll.BDP(D4,"PX_LAST")} -> 247.3067 | O9: 46056.625 | P9: 93.64 | Q9: 46056.625 | R9: 100.576 | S9: 46056.625 | T9: 243.64 | U9: =IF(COUNTIF(Q:Q,O9)*COUNTIF(S:S,O9),O9,"") -> 46056.625 | V9: =IF(U9>$A$14,U9,"") -> 46056.625 | W9: 46057.625 | X9: 46051 | Y9: 263.4651 | Z9: 45789 | AA9: 235.5827 | AB9: 45789 | AC9: 306.82 | AD9: =IF(COUNTIF(AB:AB,Z9),Z9,"") -> 45789
A10: Live ER = | O10: 46057.625 | P10: 93.61 | Q10: 46057.625 | R10: 100.637 | S10: 46057.625 | T10: 244.557 | U10: =IF(COUNTIF(Q:Q,O10)*COUNTIF(S:S,O10),O10,"") -> 46057.625 | V10: =IF(U10>$A$14,U10,"") -> 46057.625 | W10: 46058.625 | X10: 46052 | Y10: 263.6153 | Z10: 45790 | AA10: 236.7813 | AB10: 45790 | AC10: 295.552 | AD10: =IF(COUNTIF(AB:AB,Z10),Z10,"") -> 45790
O11: 46058.625 | P11: 93.49 | Q11: 46058.625 | R11: 100.67 | S11: 46058.625 | T11: 249.851 | U11: =IF(COUNTIF(Q:Q,O11)*COUNTIF(S:S,O11),O11,"") -> 46058.625 | V11: =IF(U11>$A$14,U11,"") -> 46058.625 | W11: 46059.625 | X11: 46055 | Y11: 264.1297 | Z11: 45791 | AA11: 236.4158 | AB11: 45791 | AC11: 299.078 | AD11: =IF(COUNTIF(AB:AB,Z11),Z11,"") -> 45791
A12: Date | B12: Long Risk | E12: Short Risk | H12: Short Risk | L12: IHYG Dvd | M12: Net P/L | O12: 46059.625 | P12: 93.62 | Q12: 46059.625 | R12: 100.67 | S12: 46059.625 | T12: 244.11 | U12: =IF(COUNTIF(Q:Q,O12)*COUNTIF(S:S,O12),O12,"") -> 46059.625 | V12: =IF(U12>$A$14,U12,"") -> 46059.625 | W12: 46062.625 | X12: 46056 | Y12: 264 | Z12: 45792 | AA12: 236.2761 | AB12: 45792 | AC12: 300.107 | AD12: =IF(COUNTIF(AB:AB,Z12),Z12,"") -> 45792
B13: Price | C13: Price P/L | D13: Carry P/L | E13: Price | F13: Price P/L | G13: Carry P/L | H13: Sprd | I13: Index | J13: Adj. Index | K13: P/L | O13: 46062.625 | P13: 93.76 | Q13: 46062.625 | R13: 100.702 | S13: 46062.625 | T13: 241.44 | U13: =IF(COUNTIF(Q:Q,O13)*COUNTIF(S:S,O13),O13,"") -> 46062.625 | V13: =IF(U13>$A$14,U13,"") -> 46062.625 | W13: 46064.625 | X13: 46057 | Y13: 263.8195 | Z13: 45793 | AA13: 236.2916 | AB13: 45793 | AC13: 301.295 | AD13: =IF(COUNTIF(AB:AB,Z13),Z13,"") -> 45793
A14: 46049.625 | B14: 93.74 | E14: 100.59 | H14: 241.372 | I14: 264.18 | J14: =IF(ISERROR(H14-2),"",I14) -> 264.18 | M14: 0 | O14: 46064.625 | P14: 93.63 | Q14: 46063.625 | R14: 100.736 | S14: 46063.625 | T14: 241.986 | U14: =IF(COUNTIF(Q:Q,O14)*COUNTIF(S:S,O14),O14,"") -> 46064.625 | V14: =IF(U14>$A$14,U14,"") -> 46064.625 | W14: 46065.625 | X14: 46058 | Y14: 263.5473 | Z14: 45796 | AA14: 236.3481 | AB14: 45796 | AC14: 299.938 | AD14: =IF(COUNTIF(AB:AB,Z14),Z14,"") -> 45796
A15: =IF(AND(ISBLANK(W4), A14 = $W$1),NOW(),IF(ISBLANK(W4),"",W4)) -> 46050.625 | B15: =IF(COUNTIF($W$2:W1000,A15)=1,VLOOKUP(A15,O:P,2), IF(COUNTIF($W$2:W1000,A15)=0,$B$9,"")) -> 93.63 | C15: =IF(ISERROR(B15-2),"",(B15/$B$14-1)*$B$5) -> -35203.755 | D15: =IF(ISERROR(B15-2),"",-1*(INT(A15)-INT($A$14))/360*$B$7*$B$5) -> -2208.3333 | E15: =IF(COUNTIF($W$2:W1000,A15)=1,VLOOKUP(A15,Q:R,2), IF(COUNTIF($W$2:W1000,A15)=0,$C$9,"")) -> 100.65 | F15: =IF(ISERROR(B15-2),"",(E15-$E$14)/100*$C$5) -> 15600 | G15: =IF(ISERROR(B15-2),"",(INT(A15)-INT($A$14))/360*$C$6*$C$5-(INT(A15)-INT($A$14))/360*$C$7*$C$5*$E$14/100) -> -10.226667 | H15: =IF(COUNTIF($W$2:W1000,A15)=1,VLOOKUP(A15,S:T,2), IF(COUNTIF($W$2:W1000,A15)=0,$D$9,"")) -> 244.391 | I15: =IF(COUNTIF($X$2:X1000,INT(A15))=1,VLOOKUP(INT(A15),X:Y,2), IF(ISERROR(H15-2),"",I14*(1-$D$8*(H15-H14)*0.0001))) -> 263.7748 | J15: =IF(ISERROR(H15-2),"",I15) -> 263.7748 | K15: =IF(ISERROR(H15-2),"",(J15/$J$14-1)*$D$5) -> -28682.111 | L15: =IF($A15="","",IF(COUNTIFS(Dividends!$G:$G,">"&INT($A14),Dividends!$G:$G,"<="&INT($A15))=0,"",$H$2*SUMIFS(Dividends!$H:$H,Dividends!$G:$G,">"&INT($A14),Dividends!$G:$G,"<="&INT($A15)))) | M15: =IF(ISERROR(B15-2),"",C15+D15-F15-G15-K15+SUM($L$14:L15)) -> -24319.751 | O15: 46065.625 | P15: 93.65 | Q15: 46064.625 | R15: 100.73 | S15: 46064.625 | T15: 242.796 | U15: =IF(COUNTIF(Q:Q,O15)*COUNTIF(S:S,O15),O15,"") -> 46065.625 | V15: =IF(U15>$A$14,U15,"") -> 46065.625 | W15: 46066.625 | X15: 46059 | Y15: 264.1749 | Z15: 45797 | AA15: 236.8784 | AB15: 45797 | AC15: 295.737 | AD15: =IF(COUNTIF(AB:AB,Z15),Z15,"") -> 45797
A16: =IF(AND(ISBLANK(W5), A15 = $W$1),NOW(),IF(ISBLANK(W5),"",W5)) -> 46051.625 | B16: =IF(COUNTIF($W$2:W1001,A16)=1,VLOOKUP(A16,O:P,2), IF(COUNTIF($W$2:W1001,A16)=0,$B$9,"")) -> 93.53 | C16: =IF(ISERROR(B16-2),"",(B16/$B$14-1)*$B$5) -> -67207.169 | D16: =IF(ISERROR(B16-2),"",-1*(INT(A16)-INT($A$14))/360*$B$7*$B$5) -> -4416.6667 | E16: =IF(COUNTIF($W$2:W1001,A16)=1,VLOOKUP(A16,Q:R,2), IF(COUNTIF($W$2:W1001,A16)=0,$C$9,"")) -> 100.706 | F16: =IF(ISERROR(B16-2),"",(E16-$E$14)/100*$C$5) -> 30160 | G16: =IF(ISERROR(B16-2),"",(INT(A16)-INT($A$14))/360*$C$6*$C$5-(INT(A16)-INT($A$14))/360*$C$7*$C$5*$E$14/100) -> -20.453333 | H16: =IF(COUNTIF($W$2:W1001,A16)=1,VLOOKUP(A16,S:T,2), IF(COUNTIF($W$2:W1001,A16)=0,$D$9,"")) -> 249.25 | I16: =IF(COUNTIF($X$2:X1001,INT(A16))=1,VLOOKUP(INT(A16),X:Y,2), IF(ISERROR(H16-2),"",I15*(1-$D$8*(H16-H15)*0.0001))) -> 263.4651 | J16: =IF(ISERROR(H16-2),"",I16) -> 263.4651 | K16: =IF(ISERROR(H16-2),"",(J16/$J$14-1)*$D$5) -> -50604.247 | L16: =IF($A16="","",IF(COUNTIFS(Dividends!$G:$G,">"&INT($A15),Dividends!$G:$G,"<="&INT($A16))=0,"",$H$2*SUMIFS(Dividends!$H:$H,Dividends!$G:$G,">"&INT($A15),Dividends!$G:$G,"<="&INT($A16)))) | M16: =IF(ISERROR(B16-2),"",C16+D16-F16-G16-K16+SUM($L$14:L16)) -> -51159.135 | O16: 46066.625 | P16: 93.55 | Q16: 46065.625 | R16: 100.751 | S16: 46065.625 | T16: 244.618 | U16: =IF(COUNTIF(Q:Q,O16)*COUNTIF(S:S,O16),O16,"") -> 46066.625 | V16: =IF(U16>$A$14,U16,"") -> 46066.625 | W16: 46069.625 | X16: 46062 | Y16: 264.5603 | Z16: 45798 | AA16: 236.6263 | AB16: 45798 | AC16: 298.613 | AD16: =IF(COUNTIF(AB:AB,Z16),Z16,"") -> 45798
